Workbook
Name \a: #REF!
Name \a: #REF!
Name \a: #REF!
Name \a: #REF!
Name \a: #REF!
Name \a: #REF!
Name \a: #REF!
Name \a: #REF!
Name \a: #REF!
Name \a: #REF!
Name \a: #REF!
Name \a: #REF!
Name \a: #REF!
Name \a: #REF!
Name \a: #REF!
Name \a: #REF!
Name \a: #REF!
Name \a: #REF!
Name \a: #REF!
Name \a: #REF!
Name \a: #REF!
Name \a: #REF!
Name \a: #REF!
Name \a: #REF!
Name \a: #REF!
Name \a: #REF!
Name \s: #REF!
Name \s: #REF!
Name \s: #REF!
Name \s: #REF!
Name \s: #REF!
Name \s: #REF!
Name \s: #REF!
Name \s: #REF!
Name \s: #REF!
Name \s: #REF!
Name \s: #REF!
Name \s: #REF!
Name \s: #REF!
Name \s: #REF!
Name \s: #REF!
Name \s: #REF!
Name \s: #REF!
Name \s: #REF!
Name \s: #REF!
Name \s: #REF!
Name \s: #REF!
Name a: #REF!
Name a: #REF!
Name a: #REF!
Name a: #REF!
Name a: #REF!
Name a: #REF!
Name a: #REF!
Name a: #REF!
Name a: #REF!
Name a: #REF!
Name a: #REF!
Name a: #REF!
Name a: #REF!

Sheet Portada
C33: ='Pm2'!G6 -> 45870
C34: =PROPER(TEXT(C33,"Mmmm"))& " de " & PROPER(TEXT(C33,"aaa")) -> Agosto de 2025

Sheet Nota
B4: La presente información corresponde a la que, en cumplimiento a las Disposiciones aplicables a cada sector, entregan las entidades supervisadas a la CNBV a través de los reportes regulatorios debiéndose asegurar que la misma sea completa, correcta, precisa, integra, confiable y oportuna. Es importante mencionar, como lo indican las propias Disposiciones, que dicha información debe cumplir con las validaciones establecidas en el Sistema Interinstitucional de Transferencia de Información, así como los estándares de calidad que indique la Comisión a través de dicho sistema, además debe existir consistencia entre la información que las entidades incluyan en uno o más reportes regulatorios, aunque se encuentre con un nivel distinto de integración, por lo que puede ser modificada derivado de las revisiones internas que se hagan a la misma. Por lo anterior se informa que la presente publicación se genera con la información con la que se cuenta al momento de su elaboración, se recomienda su uso tomando en cuenta los aspectos anteriormente descritos.
B6: Consideraciones sobre los criterios para integrar los estados financieros del sector de Banca Múltiple a partir de enero de 2022. El 13 de marzo de 2020 se publicó en el Diario Oficial de la Federación la resolución que modificó las Disposiciones de carácter general aplicables a las instituciones de crédito (Disposiciones), la cual incorporó las nuevas normas de información emitidas por el Consejo Mexicano de Normas de Información Financiera A.C., mismas que serían exigibles a partir del 1 de enero de 2021; sin embargo, su entrada en vigor se aplazó hasta el 1 de enero de 2022, mediante la resolución modificatoria publicada en el Diario Oficial de la Federación el 4 de diciembre de 2020. En la resolución modificatoria del 4 de diciembre, se indica que los estados financieros básicos consolidados trimestrales y anuales requeridos a las instituciones de conformidad con las disposiciones señaladas correspondientes al periodo concluido el 31 de diciembre de 2022, no deberán presentarse comparativos con cada trimestre del ejercicio 2021 y por el periodo terminado el 31 de diciembre de 2021. La información del comunicado de prensa de Banca Múltiple se puede consultar en https://www.cnbv.gob.mx/PRENSA/Paginas/Boletines-de-Prensa.aspx Para la información financiera histórica se recomienda utilizar los reportes publicados en el Portafolio de Información. Para consultar las cifras bajo la norma internacional de información financiera 9 “Instrumentos Financieros” (IFRS 9), dirigirse a la sección de IFRS 9 del Portafolio Consultas.
B11: El presente Boletín Estadístico se elaboró por personal de la Comisión Nacional Bancaria y de Valores (CNBV) con la información correspondiente a agosto de 2025 contenida en los reportes regulatorios que las entidades supervisadas envían a esta Comisión, la cual estuvo disponible a partir del 23 de septiembre de 2025.
B13: Las cifras aquí contenidas no se actualizan en el tiempo, por lo que para consultar series históricas se recomienda utilizar los reportes publicados en el Portafolio de Información.
B15: Al cierre de agosto de 2025, el sector de Banca Múltiple estuvo integrado por 52 instituciones en operación, dos más que el año anterior, considerando el inicio de operaciones de; Openbank México, S.A., Institución de Banca Múltiple, Grupo Financiero Santander México el 19 de noviembre de 2024 y de Hey Banco, S.A. Institución de Banca Múltiple, Banregio Grupo Financiero el 12 de febrero de 2025.
B17: Mediante oficio con fecha del 24 de septiembre de 2024 se aprobó el cambio de denominación de CBM Banco, S.A., Institución de Banca Múltiple, Integrante del Grupo Financiero Citibanamex a Banco Citi México, S.A., Institución de Banca Múltiple, Grupo Financiero Citi México, en el presente Boletin estadístico (Citi México). Mediante oficio con fecha del 24 de septiembre de 2024 se aprobó el cambio de denominación de ABC Capital, S.A., Institución de Banca Múltiple (ABC Capital) a Ualá, S.A., Institución de Banca Múltiple, en el presente Boletín estadístico (Banco Ualá).
B19: El 1 de diciembre de 2024 Citigroup (Citigroup Inc.) concretó la separación del negocio de banca corporativa y privada de los negocios de consumo y banca empresarial. A partir de esa fecha, Citi opera en México a través de dos grupos financieros separados e independientes: Grupo Financiero Banamex y Grupo Financiero Citi México; por lo anterior, Citi gestionará el negocio de banca corporativa y privada (cartera comercial) y Banamex llevará el negocio de consumo y la banca empresarial (cartera comercial, de consumo y a la vivienda).
B21: El 18 de diciembre de 2024 se le notifica a Banco Sabadell, S.A., Institución de Banca Múltiple, que podrá llevar a cabo la fusión con Sabcapital, S.A. de C.V., Sociedad Financiera de Objeto Múltiple, Entidad Regulada, como sociedad fusionada, a partir de enero de 2025.

Sheet Índice
B4: Índice
B5: Presentación
B7: I. Índice de Capitalización y Evaluación de la Calidad de la Información
B8: Artículo 121 Ley de Instituciones de Crédito
B9: Metodología de Evaluación Sistema Financiero
B10: Metodología Evaluación Cartera Comercial
B11: Metodología Evaluación Cartera a la Vivienda
B12: Evaluación de Calidad a la Información
B14: II. Estadísticas de la Banca Múltiple
B15: Principales Rubros del Estado de Situación Financiera y Estado de Resultado Integral
B16: Indicadores Financieros
B17: Cartera de Crédito Total
... B36: III. Estados Financieros

Sheet Presentación
A2: Presentación
A3: La Comisión Nacional Bancaria y de Valores (CNBV) emite el presente documento para cumplir con lo dispuesto por la fracción XXIII del Artículo 4º de la Ley de la Comisión Nacional Bancaria y de Valores. Mediante la difusión de este boletín estadístico se persigue promover la transparencia y autorregulación del sector de Banca Múltiple, así como proveer a los mercados y al público en general información suficiente y confiable, que permita el análisis y seguimiento de estas instituciones.
A4: El boletín estadístico se encuentra dividido en 3 secciones: En primer lugar se informa sobre el nivel del Índice de Capitalización de las instituciones y su correspondiente categoría de Alertas Tempranas. Además, se presenta la tabla de Evaluación de la Calidad y Oportunidad de la Información con el que se califica el envío de los reportes regulatorios que las entidades supervisadas entregan a este organismo.
A5: En segundo lugar se muestra la información estadística relevante y principales indicadores de rentabilidad de cada institución de banca múltiple que proviene o se calcula con sus estados financieros consolidados.
A6: Enseguida se presenta la información reportada por las 52 instituciones de banca múltiple en operación correspondiente a agosto de 2025, consolidada con la de sus SOFOMER (Sociedades Financieras de Objeto Múltiple, Entidades Reguladas) en el caso de los siguientes bancos: Banamex con Tarjetas Banamex; Santander con Santander Inclusión Financiera; CI Banco con Finanmadrid México; Banco del Bajío con Financiera Bajío; Banregio con Start Banregio; Inbursa con STM Financial, SOFOM Inbursa y CETELEM Inbursa; Afirme con Arrendadora Afirme; Banco Base con Arrendadora Base, Invex con Invex Consumo; Bancrea con Arrendadora Bancrea, así como Ve por Más con Arrendadora Ve por Más.
A7: Se incluyen los indicadores financieros destacados, los saldos de cada tipo de crédito y de la captación de recursos.
A8: Por último, se hace un compendio de los estados financieros que las instituciones de banca múltiple reportaron a esta Comisión, al igual que en las secciones anteriores, se incluye información consolidada de las instituciones de banca múltiple con las SOFOMER de cada banco.

Sheet Portadilla I
A7: I. Índice de Capitalización y Evaluación de la Calidad de la Información.
A8: El objetivo de este apartado es proporcionar al público los indicadores de capitalización de los bancos, con las cifras disponibles en la fecha de elaboración del presente boletín, así como la clasificación de las instituciones de banca múltiple en distintas categorías, de acuerdo con las disposiciones de Alertas Tempranas.
A9: Por otra parte, se presenta la evaluación de la calidad y oportunidad de la información que entregan las instituciones a este Organismo, la cual considera la oportunidad con la que reportan y el número de reenvíos.

Sheet Art_121
B4: REGLAS DE CARÁCTER GENERAL A QUE SE REFIERE EL ARTÍCULO 121 DE LA LEY DE INSTITUCIONES DE CRÉDITO.
B5: Con el fin de mantener informado al público sobre el desempeño de las instituciones que conforman al sector de banca múltiple, la CNBV con fundamento en lo dispuesto en el artículo 121 de la Ley de Instituciones de Crédito, en relación con los artículos 220 y 221 de las Disposiciones de carácter general aplicables a las instituciones de crédito (las Disposiciones), da a conocer la clasificación de las instituciones de banca múltiple en categorías, con base en el índice de capitalización requerido conforme a las disposiciones aplicables a los requerimientos de capitalización, emitidas por esta Comisión en términos del artículo 50 de la Ley de Instituciones de Crédito
B6: CLASIFICACIÓN DE LAS INSTITUCIONES DE BANCA MÚLTIPLE DE ACUERDO CON EL ARTÍCULO 220 DE LAS DISPOSICIONES
B7: INDICADORES DE CAPITALIZACIÓN CIFRAS AL 31 DE JULIO DE 20251/
B8: Institución | C8: CCB 2/ % | D8: CCF 3/ % | E8: ICAP 4/ % | F8: Categoría 5/
B9: Actinver | C9: 18.196937 | D9: 18.196937 | E9: 18.196937 | F9: I
B10: Afirme | C10: 11.430329 | D10: 10.403862 | E10: 15.351335 | F10: I
B11: Autofin | C11: 13.20908 | D11: 13.20908 | E11: 13.20908 | F11: I
B12: Banamex | C12: 21.007107 | D12: 17.867328 | E12: 21.007107 | F12: I
B13: Banca Mifel | C13: 16.590164 | D13: 16.590164 | E13: 16.735582 | F13: I
B14: Banco Azteca | C14: 13.889673 | D14: 13.889673 | E14: 14.365216 | F14: I
B15: Banco Base | C15: 23.354958 | D15: 23.354958 | E15: 23.354958 | F15: I
B16: Banco Bineo | C16: 259.1889 | D16: 259.1889 | E16: 259.1889 | F16: I
B17: Banco Covalto | C17: 13.337459 | D17: 13.337459 | E17: 13.337459 | F17: I
B18: Banco del Bajío | C18: 14.466207 | D18: 14.466207 | E18: 14.709493 | F18: I
B19: Banco S3 | C19: 181.66557 | D19: 181.66557 | E19: 181.66557 | F19: I
B20: Banco Ualá | C20: 36.441537 | D20: 36.441537 | E20: 36.441537 | F20: I
... B60: Volkswagen Bank | C60: 27.505769 | D60: 27.505769 | E60: 27.505769 | F60: I
B61: Total Banca Múltiple | C61: 18.1448 | D61: 16.8123 | E61: 20.2415
B62: 1/ Dado a conocer a esta Comisión por el Banco de México el 12 de agosto de 2025, con base en la información entregada por las Instituciones, conforme a lo dispuesto por el artículo 2 Bis y 2 Bis 4 de las Disposiciones.
B63: 2/ CCB (Coeficiente de Capital Básico) = (Capital Fundamental + Capital no Fundamental) / Activos Ponderados Sujetos a Riesgo Total.
B64: 3/ CCF (Coeficiente de Capital Fundamental) = Capital Fundamental / Activos Ponderados Sujetos a Riesgo Total.
B65: 4/ ICAP (Índice de Capitalización) = Capital Neto / Activos Ponderados Sujetos a Riesgo Total.
B66: 5/ Categorías de Alertas Tempranas determinadas con base en el artículo 220 de las Disposiciones.

Sheet Ficha Técnica
B11: Evaluación de la Calidad de la Información
B12: Banca Múltiple
B14: Derivado de la mejora continua en los procesos de verificación de la calidad en la información, esta comisión ha modificado los criterios de evaluación de la calidad y los hábitos de envío de los reportes regulatorios que son transmitidos por las Instituciones de Banca Múltiple, por lo cual, se ha optado por generar un indicador único de calidad que refleje el estado actual obtenido para los reportes regulatorios, clasificados en 5 tipos de información distintos:
B20: Clave | C20: Clasificación | E20: Reportes | F20: Descripción
B21: 1 | C21: Situación financiera | E21: 22 | F21: Reportes de las series R01, R04 A, R06, R07, R08, R10, R12 , R13, R14, R32, R34 y R36.
B22: 2 | C22: Cartera Comercial | E22: 11 | F22: Reportes de la serie R04 C.
B23: 3 | C23: Cartera a la Vivienda | E23: 4 | F23: Reportes de la serie R04 H.
B24: 4 | C24: Captación | E24: 1 | F24: Reporte R24 B-2421.
B25: 5 | C25: Operativos | E25: 23 | F25: Reportes de las series R15, R24 B-2422, R24 B-2423, R24 C, R24 D, R24 E, R26, R27, R28, R29 y R35.
B27: Tomando en consideración la anterior clasificación, se generan 2 métricas para el cálculo del indicador único, como a continuación se muestra:
B30: 1. Calidad
B32: Para la medición del porcentaje de calidad obtenido, se identifican las incidencias presentadas en la ventana de evaluación del periodo, estas incidencias tienen ponderadores específicos para cada IBM, los cuáles se calculan a través de la distribución de sus errores presentados de manera histórica y se omiten aquellos reportes que por la naturaleza de su negocio no le son aplicables a cada IBM.
B37: 2. Oportunidad 1/
B39: Para la evaluación de hábitos de envío se consideran 3 conductas que no son adecuadas, siendo estas, los reenvíos, entregas extemporáneas y reportes omisos a la fecha de corte y que se encuentren en la ventana de evaluación. De igual forma se ponderan en la ventana de evaluación en función del comportamiento histórico y se ponderan de diferente forma en función del porcentaje de calidad obtenido.
B43: 2. Calificación final
B45: Tomando en consideración las 2 calificaciones previas, se determina una calificación final, la cual servirá como indicador general de evaluación para las IBM, el cual se calcula multiplicando el porcentaje de calidad obtenido por el porcentaje de oportunidad.
B50: Determinación de semáforos
B52: La determinación de semáforos se realiza con base en los siguientes criterios:
B54: Rojo | D54: Se asigna para instituciones que tienen una calificación final inferior a 90 puntos.
B56: Amarillo | D56: Se asigna para las instituciones que tienen una calificación de 90 o más y menor de 95 puntos.
B58: Verde | D58: Se asigna para las instituciones con 95 puntos o más.
B60: 1/ Debido a las intermitencias en el aplicativo SITI WEB, que han ocasionado retrasos involuntarios en la recepción de los Reportes Regulatorios transmitidos a la CNBV, la calificación no penaliza los hábitos de envío desde diciembre de 2023 hasta la fecha.

Sheet Evaluación Calidad
B7: Evaluación de la Calidad de la Información
B8: Banca Múltiple
B9: agosto 2025
J10: Fecha de corte: 23 de septiembre de 2025
B11: RANKING | C11: INSTITUCIÓN | G11: CALIFICACIÓN | J11: CALIDAD | K11: OPORTUNIDAD
B12: 1 | C12: 040126 | D12: Credit Suisse | G12: 100 | H12: 100 | J12: 100 | K12: 100
B13: 1 | C13: 040139 | D13: BIAfirme | G13: 100 | H13: 100 | J13: 100 | K13: 100
B14: 1 | C14: 040162 | D14: KEB Hana México | G14: 100 | H14: 100 | J14: 100 | K14: 100
B15: 1 | C15: 040165 | D15: Banco Bineo | G15: 100 | H15: 100 | J15: 100 | K15: 100
B16: 1 | C16: 040167 | D16: Hey Banco | G16: 100 | H16: 100 | J16: 100 | K16: 100
B17: 1 | C17: 040169 | D17: Openbank | G17: 100 | H17: 100 | J17: 100 | K17: 100
B18: 7 | C18: 040002 | D18: Banamex | G18: 99.93 | H18: 99.93 | J18: 99.93 | K18: 100
B19: 8 | C19: 040030 | D19: Banco del Bajío | G19: 99.86 | H19: 99.86 | J19: 99.86 | K19: 100
B20: 9 | C20: 040151 | D20: Dondé Banco | G20: 99.71 | H20: 99.71 | J20: 99.71 | K20: 100
B21: 10 | C21: 040108 | D21: MUFG Bank | G21: 99.61 | H21: 99.61 | J21: 99.61 | K21: 100
B22: 11 | C22: 040129 | D22: Barclays | G22: 99.56 | H22: 99.56 | J22: 99.56 | K22: 100
B23: 12 | C23: 040159 | D23: Bank of China | G23: 99.52 | H23: 99.52 | J23: 99.52 | K23: 100
... B63: 52 | C63: 040136 | D63: Intercam Banco | G63: 76.88 | H63: 76.88 | J63: 76.88 | K63: 100
B101: =_xlfn.XLOOKUP(C101,[1]Calificación!D:D,[1]Calificación!A:A,"",0,1) | C101: =IF([1]Calificación!D88=0,"",[1]Calificación!D88) | D101: =IFERROR(VLOOKUP(C101,[1]Calificación!$D$1:$X$53,2,0),"") | G101: =IFERROR(VLOOKUP(C101,[1]Calificación!$D$1:$X$53,5,0),"") | H101: =IFERROR(VLOOKUP(C101,[1]Calificación!$D$1:$X$53,6,0),"") | J101: =IFERROR(VLOOKUP(C101,[1]Calificación!$D$1:$X$53,3,0),"") | K101: =IFERROR(VLOOKUP(C101,[1]Calificación!$D$1:$X$53,4,0),"")
B102: =_xlfn.XLOOKUP(C102,[1]Calificación!D:D,[1]Calificación!A:A,"",0,1) | C102: =IF([1]Calificación!D89=0,"",[1]Calificación!D89) | D102: =IFERROR(VLOOKUP(C102,[1]Calificación!$D$1:$X$53,2,0),"") | G102: =IFERROR(VLOOKUP(C102,[1]Calificación!$D$1:$X$53,5,0),"") | H102: =IFERROR(VLOOKUP(C102,[1]Calificación!$D$1:$X$53,6,0),"") | J102: =IFERROR(VLOOKUP(C102,[1]Calificación!$D$1:$X$53,3,0),"") | K102: =IFERROR(VLOOKUP(C102,[1]Calificación!$D$1:$X$53,4,0),"")
B103: =_xlfn.XLOOKUP(C103,[1]Calificación!D:D,[1]Calificación!A:A,"",0,1) | C103: =IF([1]Calificación!D90=0,"",[1]Calificación!D90) | D103: =IFERROR(VLOOKUP(C103,[1]Calificación!$D$1:$X$53,2,0),"") | G103: =IFERROR(VLOOKUP(C103,[1]Calificación!$D$1:$X$53,5,0),"") | H103: =IFERROR(VLOOKUP(C103,[1]Calificación!$D$1:$X$53,6,0),"") | J103: =IFERROR(VLOOKUP(C103,[1]Calificación!$D$1:$X$53,3,0),"") | K103: =IFERROR(VLOOKUP(C103,[1]Calificación!$D$1:$X$53,4,0),"")
B104: =_xlfn.XLOOKUP(C104,[1]Calificación!D:D,[1]Calificación!A:A,"",0,1) | C104: =IF([1]Calificación!D91=0,"",[1]Calificación!D91) | D104: =IFERROR(VLOOKUP(C104,[1]Calificación!$D$1:$X$53,2,0),"") | G104: =IFERROR(VLOOKUP(C104,[1]Calificación!$D$1:$X$53,5,0),"") | H104: =IFERROR(VLOOKUP(C104,[1]Calificación!$D$1:$X$53,6,0),"") | J104: =IFERROR(VLOOKUP(C104,[1]Calificación!$D$1:$X$53,3,0),"") | K104: =IFERROR(VLOOKUP(C104,[1]Calificación!$D$1:$X$53,4,0),"")
B105: =_xlfn.XLOOKUP(C105,[1]Calificación!D:D,[1]Calificación!A:A,"",0,1) | C105: =IF([1]Calificación!D92=0,"",[1]Calificación!D92) | D105: =IFERROR(VLOOKUP(C105,[1]Calificación!$D$1:$X$53,2,0),"") | G105: =IFERROR(VLOOKUP(C105,[1]Calificación!$D$1:$X$53,5,0),"") | H105: =IFERROR(VLOOKUP(C105,[1]Calificación!$D$1:$X$53,6,0),"") | J105: =IFERROR(VLOOKUP(C105,[1]Calificación!$D$1:$X$53,3,0),"") | K105: =IFERROR(VLOOKUP(C105,[1]Calificación!$D$1:$X$53,4,0),"")
B106: =_xlfn.XLOOKUP(C106,[1]Calificación!D:D,[1]Calificación!A:A,"",0,1) | C106: =IF([1]Calificación!D93=0,"",[1]Calificación!D93) | D106: =IFERROR(VLOOKUP(C106,[1]Calificación!$D$1:$X$53,2,0),"") | G106: =IFERROR(VLOOKUP(C106,[1]Calificación!$D$1:$X$53,5,0),"") | H106: =IFERROR(VLOOKUP(C106,[1]Calificación!$D$1:$X$53,6,0),"") | J106: =IFERROR(VLOOKUP(C106,[1]Calificación!$D$1:$X$53,3,0),"") | K106: =IFERROR(VLOOKUP(C106,[1]Calificación!$D$1:$X$53,4,0),"")
B107: =_xlfn.XLOOKUP(C107,[1]Calificación!D:D,[1]Calificación!A:A,"",0,1) | C107: =IF([1]Calificación!D94=0,"",[1]Calificación!D94) | D107: =IFERROR(VLOOKUP(C107,[1]Calificación!$D$1:$X$53,2,0),"") | G107: =IFERROR(VLOOKUP(C107,[1]Calificación!$D$1:$X$53,5,0),"") | H107: =IFERROR(VLOOKUP(C107,[1]Calificación!$D$1:$X$53,6,0),"") | J107: =IFERROR(VLOOKUP(C107,[1]Calificación!$D$1:$X$53,3,0),"") | K107: =IFERROR(VLOOKUP(C107,[1]Calificación!$D$1:$X$53,4,0),"")
B108: =_xlfn.XLOOKUP(C108,[1]Calificación!D:D,[1]Calificación!A:A,"",0,1) | C108: =IF([1]Calificación!D95=0,"",[1]Calificación!D95) | D108: =IFERROR(VLOOKUP(C108,[1]Calificación!$D$1:$X$53,2,0),"") | G108: =IFERROR(VLOOKUP(C108,[1]Calificación!$D$1:$X$53,5,0),"") | H108: =IFERROR(VLOOKUP(C108,[1]Calificación!$D$1:$X$53,6,0),"") | J108: =IFERROR(VLOOKUP(C108,[1]Calificación!$D$1:$X$53,3,0),"") | K108: =IFERROR(VLOOKUP(C108,[1]Calificación!$D$1:$X$53,4,0),"")
B109: =_xlfn.XLOOKUP(C109,[1]Calificación!D:D,[1]Calificación!A:A,"",0,1) | C109: =IF([1]Calificación!D96=0,"",[1]Calificación!D96) | D109: =IFERROR(VLOOKUP(C109,[1]Calificación!$D$1:$X$53,2,0),"") | G109: =IFERROR(VLOOKUP(C109,[1]Calificación!$D$1:$X$53,5,0),"") | H109: =IFERROR(VLOOKUP(C109,[1]Calificación!$D$1:$X$53,6,0),"") | J109: =IFERROR(VLOOKUP(C109,[1]Calificación!$D$1:$X$53,3,0),"") | K109: =IFERROR(VLOOKUP(C109,[1]Calificación!$D$1:$X$53,4,0),"")
B110: =_xlfn.XLOOKUP(C110,[1]Calificación!D:D,[1]Calificación!A:A,"",0,1) | C110: =IF([1]Calificación!D97=0,"",[1]Calificación!D97) | D110: =IFERROR(VLOOKUP(C110,[1]Calificación!$D$1:$X$53,2,0),"") | G110: =IFERROR(VLOOKUP(C110,[1]Calificación!$D$1:$X$53,5,0),"") | H110: =IFERROR(VLOOKUP(C110,[1]Calificación!$D$1:$X$53,6,0),"") | J110: =IFERROR(VLOOKUP(C110,[1]Calificación!$D$1:$X$53,3,0),"") | K110: =IFERROR(VLOOKUP(C110,[1]Calificación!$D$1:$X$53,4,0),"")
B111: =_xlfn.XLOOKUP(C111,[1]Calificación!D:D,[1]Calificación!A:A,"",0,1) | C111: =IF([1]Calificación!D98=0,"",[1]Calificación!D98) | D111: =IFERROR(VLOOKUP(C111,[1]Calificación!$D$1:$X$53,2,0),"") | G111: =IFERROR(VLOOKUP(C111,[1]Calificación!$D$1:$X$53,5,0),"") | H111: =IFERROR(VLOOKUP(C111,[1]Calificación!$D$1:$X$53,6,0),"") | J111: =IFERROR(VLOOKUP(C111,[1]Calificación!$D$1:$X$53,3,0),"") | K111: =IFERROR(VLOOKUP(C111,[1]Calificación!$D$1:$X$53,4,0),"")
B112: =_xlfn.XLOOKUP(C112,[1]Calificación!D:D,[1]Calificación!A:A,"",0,1) | C112: =IF([1]Calificación!D99=0,"",[1]Calificación!D99) | D112: =IFERROR(VLOOKUP(C112,[1]Calificación!$D$1:$X$53,2,0),"") | G112: =IFERROR(VLOOKUP(C112,[1]Calificación!$D$1:$X$53,5,0),"") | H112: =IFERROR(VLOOKUP(C112,[1]Calificación!$D$1:$X$53,6,0),"") | J112: =IFERROR(VLOOKUP(C112,[1]Calificación!$D$1:$X$53,3,0),"") | K112: =IFERROR(VLOOKUP(C112,[1]Calificación!$D$1:$X$53,4,0),"")
... B133: =_xlfn.XLOOKUP(C133,[1]Calificación!D:D,[1]Calificación!A:A,"",0,1) | C133: =IF([1]Calificación!D120=0,"",[1]Calificación!D120) | D133: =IFERROR(VLOOKUP(C133,[1]Calificación!$D$1:$X$53,2,0),"") | G133: =IFERROR(VLOOKUP(C133,[1]Calificación!$D$1:$X$53,5,0),"") | H133: =IFERROR(VLOOKUP(C133,[1]Calificación!$D$1:$X$53,6,0),"") | J133: =IFERROR(VLOOKUP(C133,[1]Calificación!$D$1:$X$53,3,0),"") | K133: =IFERROR(VLOOKUP(C133,[1]Calificación!$D$1:$X$53,4,0),"")

Sheet Evaluación Calidad Grupos
B7: Evaluación de la Calidad de la Información
B8: Banca Múltiple
B9: agosto 2025
K10: Fecha de corte: 23 de septiembre de 2025
B11: RANKING | C11: INSTITUCIÓN | G11: CALIFICACIÓN | K11: CALIDAD | L11: OPORTUNIDAD
B12: G7
B13: 1 | C13: 040002 | D13: Banamex | G13: 99.93 | H13: 99.93 | K13: 99.93 | L13: 100 | O13: G-7
B14: 2 | C14: 040072 | D14: Banorte | G14: 97.83 | H14: 97.83 | K14: 97.83 | L14: 100 | O14: G-7
B15: 3 | C15: 040036 | D15: Inbursa | G15: 96.87 | H15: 96.87 | K15: 96.87 | L15: 100 | O15: G-7
B16: 4 | C16: 040044 | D16: Scotiabank | G16: 96.8 | H16: 96.8 | K16: 96.8 | L16: 100 | O16: G-7
B17: 5 | C17: 040021 | D17: HSBC | G17: 95.68 | H17: 95.68 | K17: 95.68 | L17: 100 | O17: G-7
B18: 6 | C18: 040012 | D18: BBVA México | G18: 95.15 | H18: 95.15 | K18: 95.15 | L18: 100 | O18: G-7
B19: 7 | C19: 040014 | D19: Santander | G19: 90.2 | H19: 90.2 | K19: 90.2 | L19: 100 | O19: G-7
B21: BANCOS CAMBIARIOS
B22: 1 | C22: 040112 | D22: Monex | G22: 96.67 | H22: 96.67 | K22: 96.67 | L22: 100 | O22: Bancos Cambiarios
B23: 2 | C23: 040143 | D23: CIBanco | G23: 92.76 | H23: 92.76 | K23: 92.76 | L23: 100 | O23: Bancos Cambiarios
B24: 3 | C24: 040145 | D24: Banco Base | G24: 90.46 | H24: 90.46 | K24: 90.46 | L24: 100 | O24: Bancos Cambiarios
B25: 4 | C25: 040136 | D25: Intercam Banco | G25: 76.88 | H25: 76.88 | K25: 76.88 | L25: 100 | O25: Bancos Cambiarios
B27: BANCA DE INVERSIÓN Y OTROS SERVICIOS
B28: 1 | C28: 040126 | D28: Credit Suisse | G28: 100 | H28: 100 | K28: 100 | L28: 100 | O28: Banca de Inversión y Otros Servicios
B29: 1 | C29: 040139 | D29: BIAfirme | G29: 100 | H29: 100 | K29: 100 | L29: 100 | O29: Banca de Inversión y Otros Servicios
B30: 3 | C30: 040108 | D30: MUFG Bank | G30: 99.61 | H30: 99.61 | K30: 99.61 | L30: 100 | O30: Banca de Inversión y Otros Servicios
B31: 4 | C31: 040129 | D31: Barclays | G31: 99.56 | H31: 99.56 | K31: 99.56 | L31: 100 | O31: Banca de Inversión y Otros Servicios
B32: 5 | C32: 040124 | D32: Citi México (Antes CBM Banco) | G32: 99.01 | H32: 99.01 | K32: 99.01 | L32: 100 | O32: Banca de Inversión y Otros Servicios
B33: 6 | C33: 040148 | D33: Pagatodo | G33: 98.19 | H33: 98.19 | K33: 98.19 | L33: 100 | O33: Banca de Inversión y Otros Servicios
B34: 7 | C34: 040164 | D34: BNP Paribas México | G34: 97.99 | H34: 97.99 | K34: 97.99 | L34: 100 | O34: Banca de Inversión y Otros Servicios
B35: 8 | C35: 040106 | D35: Bank of America | G35: 97.65 | H35: 97.65 | K35: 97.65 | L35: 100 | O35: Banca de Inversión y Otros Servicios
B36: 9 | C36: 040160 | D36: Banco S3 | G36: 96.77 | H36: 96.77 | K36: 96.77 | L36: 100 | O36: Banca de Inversión y Otros Servicios
B37: 10 | C37: 040110 | D37: J.P. Morgan | G37: 94.57 | H37: 94.57 | K37: 94.57 | L37: 100 | O37: Banca de Inversión y Otros Servicios
B38: 11 | C38: 040062 | D38: Afirme | G38: 93.49 | H38: 93.49 | K38: 93.49 | L38: 100 | O38: Banca de Inversión y Otros Servicios
B39: 12 | C39: 040059 | D39: Invex | G39: 87.81 | H39: 87.81 | K39: 87.81 | L39: 100 | O39: Banca de Inversión y Otros Servicios
B41: COMERCIAL MEDIANO
B42: 1 | C42: 040030 | D42: Banco del Bajío | G42: 99.86 | H42: 99.86 | K42: 99.86 | L42: 100 | O42: Comercial Mediano
B43: 2 | C43: 040113 | D43: Ve por Más | G43: 99.43 | H43: 99.43 | K43: 99.43 | L43: 100 | O43: Comercial Mediano
B44: 3 | C44: 040156 | D44: Sabadell | G44: 98.53 | H44: 98.53 | K44: 98.53 | L44: 100 | O44: Comercial Mediano
B45: 4 | C45: 040058 | D45: Banregio | G45: 96.93 | H45: 96.93 | K45: 96.93 | L45: 100 | O45: Comercial Mediano
B46: 5 | C46: 040132 | D46: Multiva | G46: 95.16 | H46: 95.16 | K46: 95.16 | L46: 100 | O46: Comercial Mediano
B47: 6 | C47: 040042 | D47: Banca Mifel | G47: 94.9 | H47: 94.9 | K47: 94.9 | L47: 100 | O47: Comercial Mediano
B49: COMERCIAL PEQUEÑO
B50: 1 | C50: 040162 | D50: KEB Hana México | G50: 100 | H50: 100 | K50: 100 | L50: 100 | O50: Comercial pequeño
...

Sheet Evaluación Calidad Detallada
B3: Evaluación de la Calidad de la Información
B4: Banca Múltiple
B5: agosto 2025
M6: Fecha de corte: 23 de septiembre de 2025
B8: RANKING | C8: INSTITUCIÓN | G8: SITUACIÓN FINANCIERA | J8: CARTERA COMERCIAL | M8: CARTERA A LA VIVIENDA | P8: PRODUCTOS DE CAPTACIÓN | S8: OPERATIVOS
G9: CALIDAD | H9: OPORTUNIDAD | J9: CALIDAD | K9: OPORTUNIDAD | M9: CALIDAD | N9: OPORTUNIDAD | P9: CALIDAD | Q9: OPORTUNIDAD | S9: CALIDAD | T9: OPORTUNIDAD
B10: 1 | C10: 040126 | D10: Credit Suisse | G10: 100 | H10: 100 | J10: n.a | K10: 100 | M10: n.a | N10: 100 | P10: 100 | Q10: 100 | S10: 100 | T10: 100
B11: 1 | C11: 040139 | D11: BIAfirme | G11: 100 | H11: 100 | J11: 100 | K11: 100 | M11: n.a | N11: 100 | P11: 100 | Q11: 100 | S11: 100 | T11: 100
B12: 1 | C12: 040162 | D12: KEB Hana México | G12: 100 | H12: 100 | J12: 100 | K12: 100 | M12: n.a | N12: 100 | P12: 100 | Q12: 100 | S12: 100 | T12: 100
B13: 1 | C13: 040165 | D13: Banco Bineo | G13: 100 | H13: 100 | J13: n.a | K13: 100 | M13: n.a | N13: 100 | P13: 100 | Q13: 100 | S13: 100 | T13: 100
B14: 1 | C14: 040167 | D14: Hey Banco | G14: 100 | H14: 100 | J14: n.a | K14: 100 | M14: n.a | N14: 100 | P14: 100 | Q14: 100 | S14: 100 | T14: 100
B15: 1 | C15: 040169 | D15: Openbank | G15: 100 | H15: 100 | J15: n.a | K15: 100 | M15: n.a | N15: 100 | P15: 100 | Q15: 100 | S15: 100 | T15: 100
B16: 7 | C16: 040002 | D16: Banamex | G16: 100 | H16: 100 | J16: 99.76 | K16: 100 | M16: 100 | N16: 100 | P16: 100 | Q16: 100 | S16: 100 | T16: 100
B17: 8 | C17: 040030 | D17: Banco del Bajío | G17: 100 | H17: 100 | J17: 99.52 | K17: 100 | M17: 100 | N17: 100 | P17: 100 | Q17: 100 | S17: 100 | T17: 100
B18: 9 | C18: 040151 | D18: Dondé Banco | G18: 100 | H18: 100 | J18: 99.54 | K18: 100 | M18: n.a | N18: 100 | P18: 97.44 | Q18: 100 | S18: 100 | T18: 100
B19: 10 | C19: 040108 | D19: MUFG Bank | G19: 99.73 | H19: 100 | J19: 99.31 | K19: 100 | M19: n.a | N19: 100 | P19: 100 | Q19: 100 | S19: 100 | T19: 100
B20: 11 | C20: 040129 | D20: Barclays | G20: 99.1 | H20: 100 | J20: n.a | K20: 100 | M20: n.a | N20: 100 | P20: 100 | Q20: 100 | S20: 100 | T20: 100
B21: 12 | C21: 040159 | D21: Bank of China | G21: 99.43 | H21: 100 | J21: 100 | K21: 100 | M21: n.a | N21: 100 | P21: 92.31 | Q21: 100 | S21: 100 | T21: 100
B22: 13 | C22: 040113 | D22: Ve por Más | G22: 100 | H22: 100 | J22: 98.29 | K22: 100 | M22: 100 | N22: 100 | P22: 100 | Q22: 100 | S22: 99.49 | T22: 100
B23: 14 | C23: 040147 | D23: Bankaool | G23: 99.47 | H23: 100 | J23: 99.31 | K23: 100 | M23: n.a | N23: 100 | P23: 100 | Q23: 100 | S23: 99.49 | T23: 100
B24: 15 | C24: 040149 | D24: Forjadores | G24: 100 | H24: 100 | J24: 98.38 | K24: 100 | M24: n.a | N24: 100 | P24: 100 | Q24: 100 | S24: 100 | T24: 100
B25: 16 | C25: 040124 | D25: Citi México (Antes CBM Banco) | G25: 100 | H25: 100 | J25: 98.33 | K25: 100 | M25: n.a | N25: 100 | P25: n.a | Q25: 100 | S25: 98.46 | T25: 100
B26: 17 | C26: 040130 | D26: Compartamos | G26: 99.01 | H26: 100 | J26: 99.76 | K26: 100 | M26: n.a | N26: 100 | P26: 84.62 | Q26: 100 | S26: 100 | T26: 100
B27: 18 | C27: 040155 | D27: ICBC | G27: 97.53 | H27: 100 | J27: 100 | K27: 100 | M27: n.a | N27: 100 | P27: 94.87 | Q27: 100 | S27: 100 | T27: 100
B28: 19 | C28: 040141 | D28: Volkswagen Bank | G28: 99.49 | H28: 100 | J28: n.a | K28: 100 | M28: n.a | N28: 100 | P28: 100 | Q28: 100 | S28: 100 | T28: 100
B29: 20 | C29: 040156 | D29: Sabadell | G29: 100 | H29: 100 | J29: 95.21 | K29: 100 | M29: 100 | N29: 100 | P29: 100 | Q29: 100 | S29: 100 | T29: 100
B30: 21 | C30: 040060 | D30: Bansí | G30: 100 | H30: 100 | J30: 96.38 | K30: 100 | M30: 100 | N30: 100 | P30: 100 | Q30: 100 | S30: 95.38 | T30: 100
B31: 22 | C31: 040148 | D31: Pagatodo | G31: 100 | H31: 100 | J31: n.a | K31: 100 | M31: n.a | N31: 100 | P31: 79.49 | Q31: 100 | S31: 100 | T31: 100
B32: 23 | C32: 040164 | D32: BNP Paribas México | G32: 96.1 | H32: 100 | J32: n.a | K32: 100 | M32: n.a | N32: 100 | P32: n.a | Q32: 100 | S32: 100 | T32: 100
B33: 24 | C33: 040072 | D33: Banorte | G33: 100 | H33: 100 | J33: 96.64 | K33: 100 | M33: 95.95 | N33: 100 | P33: 100 | Q33: 100 | S33: 100 | T33: 100
B34: 25 | C34: 040106 | D34: Bank of America | G34: 98.87 | H34: 100 | J34: 97.9 | K34: 100 | M34: n.a | N34: 100 | P34: 97.44 | Q34: 100 | S34: 94.87 | T34: 100
B35: 26 | C35: 040154 | D35: Covalto | G35: 98.63 | H35: 100 | J35: 95.2 | K35: 100 | M35: n.a | N35: 100 | P35: 100 | Q35: 100 | S35: 100 | T35: 100
B36: 27 | C36: 040157 | D36: Shinhan | G36: 100 | H36: 100 | J36: 93.74 | K36: 100 | M36: n.a | N36: 100 | P36: 100 | Q36: 100 | S36: 100 | T36: 100
B37: 28 | C37: 040137 | D37: Bancoppel | G37: 96.4 | H37: 100 | J37: 96.94 | K37: 100 | M37: 99.31 | N37: 100 | P37: 100 | Q37: 100 | S37: 94.87 | T37: 100
B38: 29 | C38: 040058 | D38: Banregio | G38: 100 | H38: 100 | J38: 98.04 | K38: 100 | M38: 91.28 | N38: 100 | P38: 100 | Q38: 100 | S38: 100 | T38: 100
B39: 30 | C39: 040036 | D39: Inbursa | G39: 99.47 | H39: 100 | J39: 95.99 | K39: 100 | M39: 98.68 | N39: 100 | P39: 66.67 | Q39: 100 | S39: 95.9 | T39: 100
B40: 31 | C40: 040044 | D40: Scotiabank | G40: 100 | H40: 100 | J40: 98.38 | K40: 100 | M40: 90.81 | N40: 100 | P40: 100 | Q40: 100 | S40: 100 | T40: 100
B41: 32 | C41: 040160 | D41: Banco S3 | G41: 97.55 | H41: 100 | J41: 96.71 | K41: 100 | M41: n.a | N41: 100 | P41: 100 | Q41: 100 | S41: 94.87 | T41: 100
B42: 33 | C42: 040112 | D42: Monex | G42: 100 | H42: 100 | J42: 91.79 | K42: 100 | M42: 100 | N42: 100 | P42: 100 | Q42: 100 | S42: 93.33 | T42: 100
B43: 34 | C43: 040158 | D43: Mizuho Bank | G43: 99.18 | H43: 100 | J43: 92.76 | K43: 100 | M43: n.a | N43: 100 | P43: 100 | Q43: 100 | S43: 100 | T43: 100
...

Sheet Portadilla II
B2: II. Estadísticas de la Banca Múltiple
B3: El objetivo de este apartado es proporcionar al público indicadores estadísticos que reflejen adecuadamente la evolución de la condición financiera de la Banca Múltiple, por lo que en esta sección, se presenta la información reportada por las 52 instituciones de banca múltiple en operación correspondiente a agosto de 2025, consolidada con la de sus SOFOMER en el caso de las siguientes instituciones: Banamex con Tarjetas Banamex; Santander con Santander Inclusión Financiera; CI Banco con Finanmadrid México; Banco del Bajío con Financiera Bajío; Banregio con Start Banregio; Inbursa con STM Financial, SOFOM Inbursa y CETELEM Inbursa; Afirme con Arrendadora Afirme; Banco Base con Arrendadora Base, Invex con Invex Consumo; Bancrea con Arrendadora Bancrea, así como Ve por Más con Arrendadora Ve por Más.
B5: Notas:
B7: 1/ Para la cartera total se considera la información de cartera de los bancos junto con la cartera de sus respectivas Sociedades Financieras de Objeto Múltiple Reguladas a las que consolidan. Hasta diciembre 2021: Cartera total = Cartera vigente + cartera vencida. A partir de enero 2022: Cartera total = Cartera de crédito con riesgo de crédito en etapa 1 + 2 + 3 + cartera de crédito valuada a valor razonable.
B9: 2/ Respecto al resultado neto se muestran saldos acumulados al cierre de mes.
B10: 3/ ROA = Resultado neto (flujo 12 meses) / Activos totales, promedio 12 meses.
B11: 4/ ROE = Resultado neto (flujo 12 meses) / Capital contable, promedio 12 meses.
B12: 5/ Hasta diciembre 2021: IMOR = Índice de Morosidad = cartera vencida / (Cartera vigente + cartera vencida). A partir de enero 2022: IMOR = Índice de Morosidad = cartera de crédito con riesgo de crédito en etapa 3 / (Cartera de crédito con riesgo de crédito en etapa 1 + 2 + 3).
B13: 6/ Hasta diciembre 2021: ICOR = Índice de cobertura= Estimaciones preventivas para riesgos crediticios del balance general / cartera de crédito vencida. A partir de enero 2022: ICOR = Índice de cobertura= Estimaciones preventivas para riesgos crediticios del estado de situación financiera / cartera de crédito con riesgo de crédito en etapa 3.
B14: 7/ Hasta diciembre 2021: Estimaciones preventivas para riesgo crediticio del balance general / (Cartera vigente + cartera vencida). A partir de enero 2022: Estimaciones preventivas para riesgo crediticio del estado de situación financiera / (Cartera de crédito con riesgo de crédito en etapa 1 + 2 + 3).
B16: */ En todos los casos se presentan las instituciones en orden descendente por tamaño de activo total en el mes de análisis más reciente.
B18: El símbolo ( - ) indica que la cifra es cero. Las cifras en cero indican una cantidad cercana a cero.
... B21: n.d.: No disponible

Sheet Pm2
B3: Principales rubros del estado de situación financiera y estado de resultado integral
B4: Millones de pesos y porcentajes
C5: Activo total | I5: Inversiones en instrumentos financieros | O5: Cartera total1/ | U5: Captación total | AA5: Capital contable | AG5: Resultado neto 2/
C6: 45505 | E6: 45839 | G6: 45870 | I6: =+$C$6 -> 45505 | K6: =+$E$6 -> 45839 | M6: =+$G$6 -> 45870 | O6: =+$C$6 -> 45505 | Q6: =+$E$6 -> 45839 | S6: =+$G$6 -> 45870 | U6: =+$C$6 -> 45505 | W6: =+$E$6 -> 45839 | Y6: =+$G$6 -> 45870 | AA6: =+$C$6 -> 45505 | AC6: =+$E$6 -> 45839 | AE6: =+$G$6 -> 45870 | AG6: =+$C$6 -> 45505 | AI6: =+$E$6 -> 45839 | AK6: =+$G$6 -> 45870
B7: Sistema */ | C7: 14453699 | D7: 100 | E7: 15389124 | F7: 100 | G7: 15431060 | H7: 100 | I7: 3799962.4 | J7: 100 | K7: 4053496.7 | L7: 100 | M7: 4023367.5 | N7: 100 | O7: 7351193.1 | P7: 100 | Q7: 7839661.6 | R7: 100 | S7: 7858406 | T7: 100 | U7: 8556208 | V7: 100 | W7: 9174885.7 | X7: 100 | Y7: 9233014.2 | Z7: 100 | AA7: 1620356.6 | AB7: 100 | AC7: 1775851.1 | AD7: 100 | AE7: 1804585.8 | AF7: 100 | AG7: 195972.35 | AH7: 100 | AI7: 178430.47 | AJ7: 100 | AK7: 203173.6 | AL7: 100
B8: BBVA México | C8: 3197252.1 | D8: 22.120649 | E8: 3340530.4 | F8: 21.707086 | G8: 3334146.9 | H8: 21.606726 | I8: 669721.11 | J8: 17.624414 | K8: 598949.41 | L8: 14.776117 | M8: 563805.88 | N8: 14.013283 | O8: 1848363 | P8: 25.143714 | Q8: 2015513.2 | R8: 25.709186 | S8: 2012068.9 | T8: 25.604033 | U8: 1854174.8 | V8: 21.67052 | W8: 2036733.9 | X8: 22.199012 | Y8: 2053500.3 | Z8: 22.240844 | AA8: 359852.84 | AB8: 22.208249 | AC8: 390680.59 | AD8: 21.999625 | AE8: 401144.42 | AF8: 22.229169 | AG8: 61691.6 | AH8: 31.479747 | AI8: 57711.877 | AJ8: 32.344182 | AK8: 66280.766 | AL8: 32.622726
B9: Santander | C9: 1910817.7 | D9: 13.220267 | E9: 1974060 | F9: 12.827631 | G9: 1991916.7 | H9: 12.908489 | I9: 593748.53 | J9: 15.625116 | K9: 593626.65 | L9: 14.644804 | M9: 599303.74 | N9: 14.895575 | O9: 897751.35 | P9: 12.212322 | Q9: 934236.43 | R9: 11.916795 | S9: 929316.63 | T9: 11.825765 | U9: 1042644.3 | V9: 12.185822 | W9: 1098918.5 | X9: 11.977463 | Y9: 1104934 | Z9: 11.967208 | AA9: 165286.29 | AB9: 10.200611 | AC9: 161669.97 | AD9: 9.103802 | AE9: 164899.95 | AF9: 9.1378281 | AG9: 19919.508 | AH9: 10.164448 | AI9: 18535.116 | AJ9: 10.387865 | AK9: 21432.466 | AL9: 10.548844
B10: Banorte | C10: 1779664.9 | D10: 12.312868 | E10: 1887469.4 | F10: 12.264957 | G10: 1862912 | H10: 12.072482 | I10: 406145.19 | J10: 10.688137 | K10: 451283.27 | L10: 11.133184 | M10: 443714.17 | N10: 11.028428 | O10: 1077778.1 | P10: 14.661268 | Q10: 1148959.6 | R10: 14.655729 | S10: 1158655.5 | T10: 14.744154 | U10: 1142322.8 | V10: 13.350807 | W10: 1186183.1 | X10: 12.928587 | Y10: 1193359.6 | Z10: 12.924919 | AA10: 152101.55 | AB10: 9.386918 | AC10: 166405.23 | AD10: 9.3704493 | AE10: 170852.09 | AF10: 9.4676621 | AG10: 30488.225 | AH10: 15.557412 | AI10: 27354.42 | AJ10: 15.330577 | AK10: 31389.194 | AL10: 15.449445
B11: Banamex | C11: 1557957.8 | D11: 10.778955 | E11: 1106121.1 | F11: 7.1876805 | G11: 1110881.5 | H11: 7.1989971 | I11: 579217.32 | J11: 15.242712 | K11: 416428.74 | L11: 10.273321 | M11: 402823.79 | N11: 10.012105 | O11: 615260.37 | P11: 8.3695307 | Q11: 486300.07 | R11: 6.2030748 | S11: 492087.34 | T11: 6.2619231 | U11: 975268.79 | V11: 11.398376 | W11: 763127.06 | X11: 8.3175647 | Y11: 773161.3 | Z11: 8.3738775 | AA11: 229099.8 | AB11: 14.13885 | AC11: 177913.35 | AD11: 10.018483 | AE11: 179568.57 | AF11: 9.9506808 | AG11: 16168.762 | AH11: 8.2505325 | AI11: 8553.0559 | AJ11: 4.7934951 | AK11: 9664.7347 | AL11: 4.7568852
B12: HSBC | C12: 892827.59 | D12: 6.1771563 | E12: 907745.99 | F12: 5.8986202 | G12: 890120.35 | H12: 5.7683682 | I12: 177627.01 | J12: 4.6744413 | K12: 210476.27 | L12: 5.1924617 | M12: 218382.91 | N12: 5.427864 | O12: 497798.4 | P12: 6.7716681 | Q12: 493741.75 | R12: 6.2979982 | S12: 490989.81 | T12: 6.2479568 | U12: 607280.22 | V12: 7.0975392 | W12: 574253.19 | X12: 6.2589683 | Y12: 560878.44 | Z12: 6.0747057 | AA12: 82274.003 | AB12: 5.0775243 | AC12: 86701.786 | AD12: 4.8822665 | AE12: 87796.547 | AF12: 4.865191 | AG12: 5963.8352 | AH12: 3.0432024 | AI12: 5108.3384 | AJ12: 2.8629294 | AK12: 5896.0556 | AL12: 2.9019792
B13: Scotiabank | C13: 844413.08 | D13: 5.8421935 | E13: 861735.43 | F13: 5.5996392 | G13: 871850.28 | H13: 5.6499702 | I13: 176691.74 | J13: 4.6498287 | K13: 166595.17 | L13: 4.1099125 | M13: 171111.93 | N13: 4.2529531 | O13: 526787.83 | P13: 7.1660181 | Q13: 527986.99 | R13: 6.7348186 | S13: 532170.63 | T13: 6.771992 | U13: 573306.69 | V13: 6.7004763 | W13: 589058.65 | X13: 6.4203378 | Y13: 591248.14 | Z13: 6.4036307 | AA13: 85858.881 | AB13: 5.2987644 | AC13: 91615.061 | AD13: 5.1589381 | AE13: 92317.678 | AF13: 5.1157267 | AG13: 7175.9957 | AH13: 3.6617389 | AI13: 5781.6631 | AJ13: 3.2402891 | AK13: 6651.1116 | AL13: 3.2736102
B14: Inbursa | C14: 633983.01 | D14: 4.3863028 | E14: 698989.33 | F14: 4.5420995 | G14: 704687.72 | H14: 4.5666839 | I14: 67406.516 | J14: 1.7738733 | K14: 70030.352 | L14: 1.7276529 | M14: 73588.344 | N14: 1.8290237 | O14: 444836.88 | P14: 6.0512202 | Q14: 461921.58 | R14: 5.8921112 | S14: 466601.03 | T14: 5.937604 | U14: 418068.73 | V14: 4.886145 | W14: 465217.13 | X14: 5.0705496 | Y14: 466616.41 | Z14: 5.053782 | AA14: 173603.2 | AB14: 10.713888 | AC14: 200527.29 | AD14: 11.291897 | AE14: 201509.51 | AF14: 11.166524 | AG14: 15998.562 | AH14: 8.1636832 | AI14: 13661.102 | AJ14: 7.6562607 | AK14: 15208.85 | AL14: 7.4856431
B15: Citi México | C15: 2041.4179 | D15: 0.014123843 | E15: 577231.71 | F15: 3.7509068 | G15: 583611.65 | H15: 3.7820581 | I15: 0.00101047 | J15: 2.6591579e-08 | K15: 235392.56 | L15: 5.8071482 | M15: 251623.63 | N15: 6.2540553 | O15: 0 | P15: 0 | Q15: 167718.59 | R15: 2.1393601 | S15: 162838.46 | T15: 2.0721564 | U15: 0.0010006 | V15: 1.1694433e-08 | W15: 339318.51 | X15: 3.6983405 | Y15: 334183.09 | Z15: 3.6194365 | AA15: 1483.9522 | AB15: 0.091581826 | AC15: 75077.878 | AD15: 4.2277123 | AE15: 76590.889 | AF15: 4.2442365 | AG15: 9.0233955 | AH15: 0.0046044228 | AI15: 6447.7772 | AJ15: 3.6136077 | AK15: 7578.955 | AL15: 3.7302854
B16: Banco del Bajío | C16: 345011.85 | D16: 2.3870142 | E16: 374884.01 | F16: 2.4360321 | G16: 382977.7 | H16: 2.4818626 | I16: 23829.615 | J16: 0.62710133 | K16: 28262.579 | L16: 0.69723947 | M16: 29641.297 | N16: 0.73672855 | O16: 250049.72 | P16: 3.4014848 | Q16: 264080.65 | R16: 3.368521 | S16: 266968.83 | T16: 3.397239 | U16: 283896.7 | V16: 3.31802 | W16: 310533.69 | X16: 3.3846056 | Y16: 316482.61 | Z16: 3.427728 | AA16: 42258.375 | AB16: 2.6079675 | AC16: 45523.253 | AD16: 2.5634611 | AE16: 46337.389 | AF16: 2.5677576 | AG16: 7348.528 | AH16: 3.749778 | AI16: 5367.0088 | AJ16: 3.0078992 | AK16: 6181.8116 | AL16: 3.0426255
B17: Banco Azteca | C17: 315426.51 | D17: 2.1823237 | E17: 358130.15 | F17: 2.3271639 | G17: 360844.95 | H17: 2.3384327 | I17: 80618.311 | J17: 2.1215555 | K17: 107881.59 | L17: 2.661445 | M17: 106765.34 | N17: 2.6536313 | O17: 182604.06 | P17: 2.4840057 | Q17: 201079.6 | R17: 2.5649015 | S17: 204657.34 | T17: 2.6043111 | U17: 223119.72 | V17: 2.607694 | W17: 242117.71 | X17: 2.638918 | Y17: 247637.47 | Z17: 2.682087 | AA17: 36912.903 | AB17: 2.2780728 | AC17: 44506.63 | AD17: 2.506214 | AE17: 44985.17 | AF17: 2.4928252 | AG17: 3439.6783 | AH17: 1.7551855 | AI17: 3379.8051 | AJ17: 1.8941861 | AK17: 3858.3457 | AL17: 1.8990389
B18: Afirme | C18: 306533.08 | D18: 2.1207933 | E18: 311426.66 | F18: 2.0236802 | G18: 314172.38 | H18: 2.0359741 | I18: 177564.6 | J18: 4.6727989 | K18: 177438.47 | L18: 4.3774172 | M18: 179170.06 | N18: 4.4532362 | O18: 64514.881 | P18: 0.87761102 | Q18: 68150.646 | R18: 0.86930597 | S18: 68901.897 | T18: 0.87679228 | U18: 92792.455 | V18: 1.0845044 | W18: 84558.258 | X18: 0.92162738 | Y18: 87043.479 | Z18: 0.94274175 | AA18: 8493.1311 | AB18: 0.52415196 | AC18: 9157.2074 | AD18: 0.51565174 | AE18: 9236.0385 | AF18: 0.51180933 | AG18: 358.79395 | AH18: 0.18308397 | AI18: 540.2653 | AJ18: 0.30278758 | AK18: 650.37462 | AL18: 0.32010785
... B59: Forjadores | C59: 843.66971 | D59: 0.0058370504 | E59: 913.07317 | F59: 0.0059332368 | G59: 928.82824 | H59: 0.0060192122 | I59: 0 | J59: 0 | K59: 0 | L59: 0 | M59: 0 | N59: 0 | O59: 500.24758 | P59: 0.0068049849 | Q59: 381.86235 | R59: 0.0048709034 | S59: 404.2503 | T59: 0.0051441769 | U59: 190.86092 | V59: 0.0022306718 | W59: 247.02857 | X59: 0.002692443 | Y59: 251.81786 | Z59: 0.0027273635 | AA59: 592.32135 | AB59: 0.036554999 | AC59: 618.63044 | AD59: 0.034835715 | AE59: 629.25154 | AF59: 0.034869583 | AG59: 2.386828 | AH59: 0.0012179412 | AI59: -22.003246 | AJ59: -0.012331552 | AK59: -28.382147 | AL59: -0.013969407

Sheet Indicadores
B2: Indicadores financieros
B3: Porcentajes | O3: 1.5853443
C5: ROA (Flujo 12 meses) 3/ | F5: ROE (Flujo 12 meses) 4/
C6: 45505 | D6: 45839 | E6: 45870 | F6: =+C6 -> 45505 | G6: =+D6 -> 45839 | H6: =+E6 -> 45870
B7: Sistema */ | C7: 2.0842601 | D7: 1.9686615 | E7: 1.9621093 | F7: 18.567215 | G7: 17.511634 | H7: 17.390149
B8: BBVA México | C8: 2.9999937 | D8: 2.9236001 | E8: 2.9566591 | F8: 26.412335 | G8: 25.7504 | H8: 25.893534
B9: Santander | C9: 1.5439158 | D9: 1.5078758 | E9: 1.5219715 | F9: 17.579834 | G9: 18.619496 | H9: 18.861805
B10: Banorte | C10: 2.5467199 | D10: 2.4773689 | E10: 2.4700136 | F10: 29.381563 | G10: 29.008945 | H10: 28.748222
B11: Banamex | C11: 1.5914304 | D11: 1.3808035 | E11: 1.3444569 | F11: 11.021205 | G11: 8.8335011 | H11: 8.5236798
B12: HSBC | C12: 1.057819 | D12: 0.70730798 | E12: 0.74108866 | F12: 11.116019 | G12: 7.7701024 | H12: 8.0945442
B13: Scotiabank | C13: 1.3050293 | D13: 1.1895722 | E13: 1.1707526 | F13: 13.5182 | G13: 11.752307 | H13: 11.527083
B14: Inbursa | C14: 4.1412355 | D14: 3.6215481 | E14: 3.5410859 | F14: 15.412832 | G14: 12.961588 | H14: 12.628435
B15: Citi México | C15: 3.3111676 | D15: 1.2665408 | E15: 1.3806368 | F15: 3.7313789 | G15: 10.327018 | H15: 11.192472
B16: Banco del Bajío | C16: 3.2649173 | D16: 2.6363784 | E16: 2.604197 | F16: 26.905679 | G16: 21.281448 | H16: 21.045841
B17: Banco Azteca | C17: 1.3773551 | D17: 1.7763661 | E17: 1.7760803 | F17: 11.520614 | G17: 14.45623 | H17: 14.381277
B18: Afirme | C18: 0.14805289 | D18: 0.24656215 | E18: 0.26444664 | F18: 5.0737462 | G18: 8.4441541 | H18: 9.012611
... B46: Banco Covalto | C46: 0.089192074 | D46: 1.518938 | E46: 1.5704968 | F46: 0.65705523 | G46: 12.329478 | H46: 12.76194
B47: Openbank | C47: n.a. | D47: -26.245312 | E47: -24.527727 | F47: n.a. | G47: -35.059007 | H47: -35.666321
B48: Volkswagen Bank | C48: 6.229125 | D48: 5.9361469 | E48: 6.0615049 | F48: 8.950684 | G48: 12.266385 | H48: 12.705889
B49: Bank of China | C49: 2.210429 | D49: 1.7082272 | E49: 1.9968873 | F49: 11.575147 | G49: 7.884571 | H49: 8.741238
B50: Shinhan | C50: 2.4433133 | D50: 1.7688039 | E50: 1.817915 | F50: 7.4935447 | G50: 6.1589319 | H50: 6.4123743
B51: Banco Ualá | C51: -25.945126 | D51: -18.776095 | E51: -18.580999 | F51: -140.85025 | G51: -154.2955 | H51: -149.41837
B52: Banco S3 | C52: 5.8032152 | D52: 5.5992688 | E52: 5.4365239 | F52: 13.433112 | G52: 13.23618 | H52: 13.00302
B53: KEB Hana México | C53: 0.95587014 | D53: 0.80838528 | E53: 0.76336247 | F53: 2.7798711 | G53: 2.6714134 | H53: 2.5198903
B54: Banco Bineo | C54: -28.123312 | D54: -30.346281 | E54: -30.148729 | F54: -30.750235 | G54: -32.608705 | H54: -32.213142
B55: Dondé Banco | C55: -10.778621 | D55: -5.0866478 | E55: -4.64868 | F55: -20.404659 | G55: -22.529182 | H55: -21.648423
B56: Credit Suisse | C56: -10.012602 | D56: -4.8495628 | E56: -5.3130418 | F56: -15.269295 | G56: -5.2370058 | H56: -5.6906418
B57: Hey Banco | C57: n.a. | D57: 5.6622236 | E57: 5.2069735 | F57: n.a. | G57: 5.6890569 | H57: 5.2308925
B58: Pagatodo | C58: -12.618275 | D58: -21.537666 | E58: -19.390734 | F58: -17.28854 | G58: -24.703061 | H58: -26.405367
B59: Forjadores | C59: 0.94138292 | D59: -1.8791918 | E59: -2.8065719 | F59: 1.346443 | G59: -2.7057418 | H59: -4.0533763

Sheet CCT
B2: Cartera de crédito total
B3: Millones de pesos y porcentajes
C5: Cartera total (MDP) 1/ | F5: IMOR (%) 5/ | I5: ICOR (%) 6/ | L5: Pérdida esperada (%) 7/
C6: 45505 | D6: 45839 | E6: 45870 | F6: =C6 -> 45505 | G6: =D6 -> 45839 | H6: =E6 -> 45870 | I6: =C6 -> 45505 | J6: =D6 -> 45839 | K6: =E6 -> 45870 | L6: =C6 -> 45505 | M6: =D6 -> 45839 | N6: =E6 -> 45870
B7: Sistema */ | C7: 7351193.1 | D7: 7839661.6 | E7: 7858406 | F7: 2.0339519 | G7: 2.1254588 | H7: 2.1597894 | I7: 156.07681 | J7: 151.25758 | K7: 150.15523 | L7: 3.1745273 | M7: 3.2149175 | N7: 3.2430367
B8: BBVA México | C8: 1848363 | D8: 2015513.2 | E8: 2012068.9 | F8: 1.677326 | G8: 1.6346425 | H8: 1.6507735 | I8: 192.18911 | J8: 189.1028 | K8: 189.94649 | L8: 3.223638 | M8: 3.0911547 | N8: 3.1355863
B9: Santander | C9: 897751.35 | D9: 934236.43 | E9: 929316.63 | F9: 2.230355 | G9: 2.3224121 | H9: 2.2979288 | I9: 136.39113 | J9: 134.65926 | K9: 135.87507 | L9: 3.0420065 | M9: 3.1273428 | N9: 3.1223123
B10: Banorte | C10: 1077778.1 | D10: 1148959.6 | E10: 1158655.5 | F10: 0.95385101 | G10: 1.1035814 | H10: 1.0782108 | I10: 171.96559 | J10: 152.29449 | K10: 156.92802 | L10: 1.6402955 | M10: 1.6806937 | N10: 1.6920148
B11: Banamex | C11: 615260.37 | D11: 486300.07 | E11: 492087.34 | F11: 2.1266056 | G11: 2.8293089 | H11: 2.8062853 | I11: 202.67029 | J11: 189.17816 | K11: 190.14216 | L11: 4.3099978 | M11: 5.3524345 | N11: 5.3359315
B12: HSBC | C12: 497798.4 | D12: 493741.75 | E12: 490989.81 | F12: 2.2185892 | G12: 2.7387882 | H12: 2.9594283 | I12: 152.51038 | J12: 139.95075 | K12: 129.70583 | L12: 3.3835789 | M12: 3.8329547 | N12: 3.8385512
B13: Scotiabank | C13: 526787.83 | D13: 527986.99 | E13: 532170.63 | F13: 3.7765415 | G13: 4.0517553 | H13: 4.042423 | I13: 73.903024 | J13: 68.652291 | K13: 69.024933 | L13: 2.7909784 | M13: 2.7816228 | N13: 2.7902798
B14: Inbursa | C14: 444836.88 | D14: 461921.58 | E14: 466601.03 | F14: 1.614095 | G14: 1.4786003 | H14: 1.5063476 | I14: 136.03706 | J14: 149.75024 | K14: 149.20137 | L14: 2.1957673 | M14: 2.2142075 | N14: 2.2474914
B15: Citi México | C15: 0 | D15: 167718.59 | E15: 162838.46 | F15: - | G15: 1.350366 | H15: 1.3908188 | I15: - | J15: 189.67717 | K15: 188.59079 | L15: - | M15: 2.561336 | N15: 2.6229561
B16: Banco del Bajío | C16: 250049.72 | D16: 264080.65 | E16: 266968.83 | F16: 1.499852 | G16: 1.8704086 | H16: 1.845093 | I16: 147.73168 | J16: 121.57592 | K16: 119.95995 | L16: 2.2157566 | M16: 2.2739665 | N16: 2.2133728
B17: Banco Azteca | C17: 182604.06 | D17: 201079.6 | E17: 204657.34 | F17: 3.2642665 | G17: 4.2294726 | H17: 4.6627621 | I17: 353.7681 | J17: 274.04411 | K17: 255.08493 | L17: 11.547933 | M17: 11.590621 | N17: 11.894004
B18: Afirme | C18: 64514.881 | D18: 68150.646 | E18: 68901.897 | F18: 5.5169331 | G18: 3.9543661 | H18: 3.9420726 | I18: 67.950399 | J18: 86.624197 | K18: 84.882725 | L18: 3.7487781 | M18: 3.4254379 | N18: 3.3461386
B19: Monex | C19: 45180.419 | D19: 55679.67 | E19: 55196.869 | F19: 1.3916776 | G19: 1.4838624 | H19: 1.4745026 | I19: 128.60088 | J19: 128.40821 | K19: 128.6824 | L19: 1.7897097 | M19: 1.9054012 | N19: 1.8974253
B20: Banregio | C20: 169812.35 | D20: 184818.19 | E20: 186462.78 | F20: 1.3026005 | G20: 1.4945681 | H20: 1.5762546 | I20: 162.54127 | J20: 143.5183 | K20: 134.43745 | L20: 2.1172634 | M20: 2.1449786 | N20: 2.1190765
B21: J.P. Morgan | C21: 19577.149 | D21: 25545.122 | E21: 24842.326 | F21: 0 | G21: 0 | H21: 0 | I21: - | J21: - | K21: - | L21: 0.728024 | M21: 0.61994842 | N21: 0.64205721
B22: Bank of America | C22: 35275.451 | D22: 41861.69 | E22: 43913.817 | F22: 0 | G22: 0 | H22: 0 | I22: - | J22: - | K22: - | L22: 0.82833874 | M22: 1.0426333 | N22: 0.98873116
B23: Invex | C23: 41051.764 | D23: 49386.651 | E23: 49339.463 | F23: 2.1943845 | G23: 2.1702776 | H23: 2.35529 | I23: 232.16863 | J23: 257.61508 | K23: 241.82046 | L23: 5.0946724 | M23: 5.5909625 | N23: 5.6955732
B24: BanCoppel | C24: 62557.798 | D24: 69846.329 | E24: 79132.111 | F24: 8.1417468 | G24: 5.881127 | H24: 5.4084956 | I24: 134.68384 | J24: 149.55988 | K24: 150.1693 | L24: 10.965618 | M24: 8.7958066 | N24: 8.1218998
B25: Multiva | C25: 70432.555 | D25: 80241.469 | E25: 81408.031 | F25: 3.3603167 | G25: 2.6201476 | H25: 2.568871 | I25: 96.547063 | J25: 112.41907 | K25: 114.35006 | L25: 3.244287 | M25: 2.9455456 | N25: 2.9375055
B26: Banca Mifel | C26: 77476.547 | D26: 83334.566 | E26: 84449.258 | F26: 2.4114249 | G26: 2.6526099 | H26: 2.8478877 | I26: 89.129097 | J26: 86.550689 | K26: 79.624047 | L26: 2.1492813 | M26: 2.2958521 | N26: 2.2676034
B27: Barclays | C27: 0 | D27: 0 | E27: 0 | F27: - | G27: - | H27: - | I27: - | J27: - | K27: - | L27: - | M27: - | N27: -
B28: Banco Base | C28: 11447.083 | D28: 10522.093 | E28: 10437.397 | F28: 2.259522 | G28: 3.1417019 | H28: 3.3503311 | I28: 134.46992 | J28: 104.19206 | K28: 101.09046 | L28: 3.0383774 | M28: 3.2734038 | N28: 3.386865
B29: Sabadell | C29: 95773.992 | D29: 100065.78 | E29: 100285.57 | F29: 1.8440014 | G29: 2.2519243 | H29: 2.0369979 | I29: 76.087214 | J29: 66.052912 | K29: 68.998084 | L29: 1.4030493 | M29: 1.4874616 | N29: 1.4054895
B30: Ve por Más | C30: 57537.13 | D30: 60019.8 | E30: 59826.379 | F30: 3.2737893 | G30: 2.8738416 | H30: 2.8954991 | I30: 92.663317 | J30: 107.71404 | K30: 111.15768 | L30: 3.0336018 | M30: 3.095531 | N30: 3.2185697
B31: Actinver | C31: 26881.578 | D31: 28375.644 | E31: 29803.299 | F31: 3.390111 | G31: 3.3318947 | H31: 3.1306968 | I31: 113.89842 | J31: 107.55651 | K31: 111.1205 | L31: 3.8612828 | M31: 3.5836697 | N31: 3.4788458
B32: Bansí | C32: 22066.521 | D32: 29730.699 | E32: 30139.47 | F32: 4.7666328 | G32: 3.6975682 | H32: 3.5418365 | I32: 148.19033 | J32: 166.68465 | K32: 173.29319 | L32: 7.0636888 | M32: 6.1632786 | N32: 6.1377615
B33: CIBanco | C33: 13393.746 | D33: 16743.919 | E33: 6940.8554 | F33: 3.4924121 | G33: 3.3272579 | H33: 8.1069954 | I33: 104.45486 | J33: 102.02887 | K33: 64.710529 | L33: 3.6479943 | M33: 3.3947636 | N33: 5.2460796
B34: Compartamos | C34: 48082.232 | D34: 58883.972 | E34: 59110.491 | F34: 3.0169088 | G34: 3.1850154 | H34: 3.2626805 | I34: 245.44252 | J34: 234.46744 | K34: 236.87828 | L34: 7.404777 | M34: 7.467824 | N34: 7.7285813
B35: BIAfirme | C35: 273.0448 | D35: 244.16608 | E35: 244.07477 | F35: 0 | G35: 0 | H35: 0 | I35: - | J35: - | K35: - | L35: 0.52293068 | M35: 0.44172885 | N35: 0.56619249
B36: Bancrea | C36: 35826.643 | D36: 43235.349 | E36: 43738.995 | F36: 0.86946747 | G36: 1.035172 | H36: 2.1351984 | I36: 118.58853 | J36: 149.35787 | K36: 72.374258 | L36: 1.0310887 | M36: 1.5461108 | N36: 1.545334
B37: MUFG Bank | C37: 14809.127 | D37: 6866.0949 | E37: 7477.1335 | F37: 0 | G37: 0 | H37: 0 | I37: - | J37: - | K37: - | L37: 0.52512656 | M37: 0.78265206 | N37: 0.77410859
B38: Consubanco | C38: 23248.393 | D38: 30750.111 | E38: 31460.825 | F38: 1.763396 | G38: 1.6180695 | H38: 1.5104281 | I38: 210.14353 | J38: 224.02722 | K38: 232.96449 | L38: 3.7056624 | M38: 3.6249161 | N38: 3.5187612
B39: Intercam Banco | C39: 20818.492 | D39: 18997.184 | E39: 13701.469 | F39: 3.0342007 | G39: 4.8650035 | H39: 7.0765523 | I39: 186.64977 | J39: 144.79065 | K39: 143.23318 | L39: 5.6633286 | M39: 7.0440702 | N39: 10.135971
B40: Autofin | C40: 4417.2963 | D40: 9513.4427 | E40: 10101.269 | F40: 3.1345408 | G40: 3.2162558 | H40: 2.7156992 | I40: 151.64069 | J40: 131.88122 | K40: 153.72453 | L40: 4.7532394 | M40: 4.2416374 | N40: 4.1746959
B41: Bankaool | C41: 7487.3347 | D41: 12586.946 | E41: 12973.417 | F41: 1.6258189 | G41: 0.88075599 | H41: 0.84564655 | I41: 187.93417 | J41: 209.12365 | K41: 216.91464 | L41: 3.0554693 | M41: 1.8418691 | N41: 1.8343311
B42: BNP Paribas México | C42: 0 | D42: 0 | E42: 0 | F42: - | G42: - | H42: - | I42: - | J42: - | K42: - | L42: - | M42: - | N42: -
...

Sheet CCE
B2: Cartera de crédito a empresas
B3: Millones de pesos y porcentajes
C5: Cartera total (MDP) 1/ | F5: IMOR (%) 5/ | I5: ICOR (%) 6/ | L5: Pérdida esperada (%) 7/
C6: 45505 | D6: 45839 | E6: 45870 | F6: =C6 -> 45505 | G6: =D6 -> 45839 | H6: =E6 -> 45870 | I6: =C6 -> 45505 | J6: =D6 -> 45839 | K6: =E6 -> 45870 | L6: =C6 -> 45505 | M6: =D6 -> 45839 | N6: =E6 -> 45870
B7: Sistema */ | C7: 3488266 | D7: 3727749.3 | E7: 3737376.9 | F7: 1.7436158 | G7: 1.7291745 | H7: 1.758917 | I7: 95.141328 | J7: 97.092335 | K7: 96.012094 | L7: 1.6588992 | M7: 1.6788959 | N7: 1.688773
B8: BBVA México | C8: 779484.92 | D8: 845064.71 | E8: 842552.82 | F8: 1.3250227 | G8: 1.0930512 | H8: 1.0776563 | I8: 93.870375 | J8: 107.45246 | K8: 108.17431 | L8: 1.2438038 | M8: 1.1745104 | N8: 1.1657472
B9: Santander | C9: 380240.3 | D9: 387976.99 | E9: 380939.14 | F9: 1.5380285 | G9: 1.5405653 | H9: 1.6108388 | I9: 91.163006 | J9: 97.156531 | K9: 97.016733 | L9: 1.402113 | M9: 1.4967598 | N9: 1.5627832
B10: Banorte | C10: 425261.94 | D10: 454619.9 | E10: 460160.81 | F10: 0.96568098 | G10: 1.1437797 | H10: 1.1429573 | I10: 85.204664 | J10: 68.126721 | K10: 70.824159 | L10: 0.82280523 | M10: 0.77921957 | N10: 0.8094899
B11: Banamex | C11: 248834.16 | D11: 130847.47 | E11: 132285.57 | F11: 1.1254841 | G11: 2.9437062 | H11: 2.754815 | I11: 160.23722 | J11: 96.591479 | K11: 98.840577 | L11: 1.8034445 | M11: 2.8433693 | N11: 2.722875
B12: HSBC | C12: 209691.57 | D12: 222562.97 | E12: 220723.03 | F12: 2.1024589 | G12: 2.8024905 | H12: 2.8889034 | I12: 89.779297 | J12: 86.598885 | K12: 85.842568 | L12: 1.8875729 | M12: 2.4269255 | N12: 2.4799089
B13: Scotiabank | C13: 199231.79 | D13: 192263.08 | E13: 194943.21 | F13: 3.8056645 | G13: 2.8542654 | H13: 2.7577768 | I13: 82.356963 | J13: 78.308601 | K13: 80.099535 | L13: 3.1342297 | M13: 2.2351353 | N13: 2.2089664
B14: Inbursa | C14: 310768.57 | D14: 321335.89 | E14: 326660.46 | F14: 1.7020299 | G14: 1.494835 | H14: 1.5115313 | I14: 108.95063 | J14: 120.13973 | K14: 119.96108 | L14: 1.8543723 | M14: 1.7958907 | N14: 1.8132494
B15: Citi México | C15: 0 | D15: 137893.37 | E15: 133585.88 | F15: - | G15: 0.0065067991 | H15: 0.0067496803 | I15: - | J15: 17977.824 | K15: 17006.207 | L15: - | M15: 1.1697809 | N15: 1.1478646
B16: Banco del Bajío | C16: 210343.7 | D16: 228199.91 | E16: 231432.33 | F16: 1.6023045 | G16: 1.969894 | H16: 1.9486717 | I16: 103.60407 | J16: 95.214421 | K16: 94.534993 | L16: 1.6600527 | M16: 1.8756232 | N16: 1.8421767
B17: Banco Azteca | C17: 42775.047 | D17: 44433.97 | E17: 45638.894 | F17: 0.99164085 | G17: 2.7649932 | H17: 4.1774129 | I17: 80.503202 | J17: 56.704017 | K17: 49.173183 | L17: 0.79830264 | M17: 1.5678622 | N17: 2.0541669
B18: Afirme | C18: 36895.075 | D18: 39323.978 | E18: 39898.806 | F18: 6.6393133 | G18: 4.5647443 | H18: 4.4209898 | I18: 45.016951 | J18: 54.302093 | K18: 51.792746 | L18: 2.9888164 | M18: 2.4787517 | N18: 2.289752
B19: Monex | C19: 34008.243 | D19: 41614.196 | E19: 41955.725 | F19: 1.6993332 | G19: 1.8939995 | H19: 1.8500347 | I19: 107.32172 | J19: 110.35244 | K19: 114.38409 | L19: 1.8237537 | M19: 2.0900747 | N19: 2.1161453
B20: Banregio | C20: 136816.5 | D20: 148361.92 | E20: 149692.77 | F20: 1.2174093 | G20: 1.5097903 | H20: 1.6140326 | I20: 131.71533 | J20: 114.66077 | K20: 105.58514 | L20: 1.6035147 | M20: 1.7311372 | N20: 1.7041785
B21: J.P. Morgan | C21: 19577.149 | D21: 24248.486 | E21: 23991.417 | F21: 0 | G21: 0 | H21: 0 | I21: - | J21: - | K21: - | L21: 0.71147067 | M21: 0.60987204 | N21: 0.62284812
B22: Bank of America | C22: 28708.577 | D22: 28411.346 | E22: 30806.887 | F22: 0 | G22: 0 | H22: 0 | I22: - | J22: - | K22: - | L22: 0.88412104 | M22: 1.1874196 | N22: 1.0791899
B23: Invex | C23: 14156.4 | D23: 14881.706 | E23: 14454.032 | F23: 2.5428001 | G23: 1.8285654 | H23: 1.8825516 | I23: 78.799881 | J23: 119.84949 | K23: 119.8119 | L23: 2.0037234 | M23: 2.1915263 | N23: 2.2555209
B24: BanCoppel | C24: 33232.416 | D24: 41303.117 | E24: 42102.249 | F24: 4.1793086 | G24: 3.7822899 | H24: 3.8361586 | I24: 78.553056 | J24: 86.626422 | K24: 85.584636 | L24: 3.2829746 | M24: 3.2764624 | N24: 3.2831624
B25: Multiva | C25: 34769.146 | D25: 42771.104 | E25: 44501.538 | F25: 5.3923204 | G25: 3.8824297 | H25: 3.666852 | I25: 82.944187 | J25: 97.585618 | K25: 101.04747 | L25: 4.4726163 | M25: 3.788693 | N25: 3.7052613
B26: Banca Mifel | C26: 52809.359 | D26: 59764.998 | E26: 61096.464 | F26: 1.3508007 | G26: 1.1732697 | H26: 1.3121854 | I26: 131.17396 | J26: 146.55307 | K26: 129.89843 | L26: 1.7718987 | M26: 1.7194627 | N26: 1.7045083
B27: Barclays | C27: 0 | D27: 0 | E27: 0 | F27: - | G27: - | H27: - | I27: - | J27: - | K27: - | L27: - | M27: - | N27: -
B28: Banco Base | C28: 11049.292 | D28: 10225.457 | E28: 10138.432 | F28: 2.3408681 | G28: 3.2328412 | H28: 3.4491267 | I28: 105.65935 | J28: 85.596186 | K28: 82.087936 | L28: 2.4733461 | M28: 2.7671888 | N28: 2.8313169
B29: Sabadell | C29: 93252.803 | D29: 97372.271 | E29: 97700.862 | F29: 1.7827664 | G29: 2.312779 | H29: 2.0907283 | I29: 75.041327 | J29: 65.431454 | K29: 68.298771 | L29: 1.3378115 | M29: 1.5132849 | N29: 1.4279417
