Workbook
Name \a: #REF!
Name \a: #REF!
Name \a: #REF!
Name \a: #REF!
Name \a: #REF!
Name \a: #REF!
Name \a: #REF!
Name \a: #REF!
Name \a: #REF!
Name \a: #REF!
Name \a: #REF!
Name \a: #REF!
Name \a: #REF!
Name \a: #REF!
Name \a: #REF!
Name \a: #REF!
Name \a: #REF!
Name \a: #REF!
Name \a: #REF!
Name \a: #REF!
Name \a: #REF!
Name \a: #REF!
Name \a: #REF!
Name \a: #REF!
Name \a: #REF!
Name \a: #REF!
Name \s: #REF!
Name \s: #REF!
Name \s: #REF!
Name \s: #REF!
Name \s: #REF!
Name \s: #REF!
Name \s: #REF!
Name \s: #REF!
Name \s: #REF!
Name \s: #REF!
Name \s: #REF!
Name \s: #REF!
Name \s: #REF!
Name \s: #REF!
Name \s: #REF!
Name \s: #REF!
Name \s: #REF!
Name \s: #REF!
Name \s: #REF!
Name \s: #REF!
Name \s: #REF!
Name a: #REF!
Name a: #REF!
Name a: #REF!
Name a: #REF!
Name a: #REF!
Name a: #REF!
Name a: #REF!
Name a: #REF!
Name a: #REF!
Name a: #REF!
Name a: #REF!
Name a: #REF!
Name a: #REF!

Sheet Portada
C33: ='Pm2'!G6 -> 45839
C34: =PROPER(TEXT(C33,"Mmmm"))& " de " & PROPER(TEXT(C33,"aaa")) -> Julio de 2025

Sheet Nota
B4: La presente información corresponde a la que, en cumplimiento a las Disposiciones aplicables a cada sector, entregan las entidades supervisadas a la CNBV a través de los reportes regulatorios debiéndose asegurar que la misma sea completa, correcta, precisa, integra, confiable y oportuna. Es importante mencionar, como lo indican las propias Disposiciones, que dicha información debe cumplir con las validaciones establecidas en el Sistema Interinstitucional de Transferencia de Información, así como los estándares de calidad que indique la Comisión a través de dicho sistema, además debe existir consistencia entre la información que las entidades incluyan en uno o más reportes regulatorios, aunque se encuentre con un nivel distinto de integración, por lo que puede ser modificada derivado de las revisiones internas que se hagan a la misma. Por lo anterior se informa que la presente publicación se genera con la información con la que se cuenta al momento de su elaboración, se recomienda su uso tomando en cuenta los aspectos anteriormente descritos.
B6: Consideraciones sobre los criterios para integrar los estados financieros del sector de Banca Múltiple a partir de enero de 2022. El 13 de marzo de 2020 se publicó en el Diario Oficial de la Federación la resolución que modificó las Disposiciones de carácter general aplicables a las instituciones de crédito (Disposiciones), la cual incorporó las nuevas normas de información emitidas por el Consejo Mexicano de Normas de Información Financiera A.C., mismas que serían exigibles a partir del 1 de enero de 2021; sin embargo, su entrada en vigor se aplazó hasta el 1 de enero de 2022, mediante la resolución modificatoria publicada en el Diario Oficial de la Federación el 4 de diciembre de 2020. En la resolución modificatoria del 4 de diciembre, se indica que los estados financieros básicos consolidados trimestrales y anuales requeridos a las instituciones de conformidad con las disposiciones señaladas correspondientes al periodo concluido el 31 de diciembre de 2022, no deberán presentarse comparativos con cada trimestre del ejercicio 2021 y por el periodo terminado el 31 de diciembre de 2021. La información del comunicado de prensa de Banca Múltiple se puede consultar en https://www.cnbv.gob.mx/PRENSA/Paginas/Boletines-de-Prensa.aspx Para la información financiera histórica se recomienda utilizar los reportes publicados en el Portafolio de Información. Para consultar las cifras bajo la norma internacional de información financiera 9 “Instrumentos Financieros” (IFRS 9), dirigirse a la sección de IFRS 9 del Portafolio Consultas.
B11: El presente Boletín Estadístico se elaboró por personal de la Comisión Nacional Bancaria y de Valores (CNBV) con la información correspondiente a julio de 2025 contenida en los reportes regulatorios que las entidades supervisadas envían a esta Comisión, la cual estuvo disponible a partir del 20 de agosto de 2025.
B13: Las cifras aquí contenidas no se actualizan en el tiempo, por lo que para consultar series históricas se recomienda utilizar los reportes publicados en el Portafolio de Información.
B15: Al cierre de julio de 2025, el sector de Banca Múltiple estuvo integrado por 52 instituciones en operación, dos más que el año anterior, considerando el inicio de operaciones de; Openbank México, S.A., Institución de Banca Múltiple, Grupo Financiero Santander México el 19 de noviembre de 2024 y de Hey Banco, S.A. Institución de Banca Múltiple, Banregio Grupo Financiero el 12 de febrero de 2025.
B17: Mediante oficio con fecha del 24 de septiembre de 2024 se aprobó el cambio de denominación de CBM Banco, S.A., Institución de Banca Múltiple, Integrante del Grupo Financiero Citibanamex a Banco Citi México, S.A., Institución de Banca Múltiple, Grupo Financiero Citi México, en el presente Boletin estadístico (Citi México). Mediante oficio con fecha del 24 de septiembre de 2024 se aprobó el cambio de denominación de ABC Capital, S.A., Institución de Banca Múltiple (ABC Capital) a Ualá, S.A., Institución de Banca Múltiple, en el presente Boletín estadístico (Banco Ualá).
B19: El 1 de diciembre de 2024 Citigroup (Citigroup Inc.) concretó la separación del negocio de banca corporativa y privada de los negocios de consumo y banca empresarial. A partir de esa fecha, Citi opera en México a través de dos grupos financieros separados e independientes: Grupo Financiero Banamex y Grupo Financiero Citi México; por lo anterior, Citi gestionará el negocio de banca corporativa y privada (cartera comercial) y Banamex llevará el negocio de consumo y la banca empresarial (cartera comercial, de consumo y a la vivienda).
B21: El 18 de diciembre de 2024 se le notifica a Banco Sabadell, S.A., Institución de Banca Múltiple, que podrá llevar a cabo la fusión con Sabcapital, S.A. de C.V., Sociedad Financiera de Objeto Múltiple, Entidad Regulada, como sociedad fusionada, a partir de enero de 2025.

Sheet Índice
B4: Índice
B5: Presentación
B7: I. Índice de Capitalización y Evaluación de la Calidad de la Información
B8: Artículo 121 Ley de Instituciones de Crédito
B9: Metodología de Evaluación Sistema Financiero
B10: Metodología Evaluación Cartera Comercial
B11: Metodología Evaluación Cartera a la Vivienda
B12: Evaluación de Calidad a la Información
B14: II. Estadísticas de la Banca Múltiple
B15: Principales Rubros del Estado de Situación Financiera y Estado de Resultado Integral
B16: Indicadores Financieros
B17: Cartera de Crédito Total
... B36: III. Estados Financieros

Sheet Presentación
A2: Presentación
A3: La Comisión Nacional Bancaria y de Valores (CNBV) emite el presente documento para cumplir con lo dispuesto por la fracción XXIII del Artículo 4º de la Ley de la Comisión Nacional Bancaria y de Valores. Mediante la difusión de este boletín estadístico se persigue promover la transparencia y autorregulación del sector de Banca Múltiple, así como proveer a los mercados y al público en general información suficiente y confiable, que permita el análisis y seguimiento de estas instituciones.
A4: El boletín estadístico se encuentra dividido en 3 secciones: En primer lugar se informa sobre el nivel del Índice de Capitalización de las instituciones y su correspondiente categoría de Alertas Tempranas. Además, se presenta la tabla de Evaluación de la Calidad y Oportunidad de la Información con el que se califica el envío de los reportes regulatorios que las entidades supervisadas entregan a este organismo.
A5: En segundo lugar se muestra la información estadística relevante y principales indicadores de rentabilidad de cada institución de banca múltiple que proviene o se calcula con sus estados financieros consolidados.
A6: Enseguida se presenta la información reportada por las 52 instituciones de banca múltiple en operación correspondiente a julio de 2025, consolidada con la de sus SOFOMER (Sociedades Financieras de Objeto Múltiple, Entidades Reguladas) en el caso de los siguientes bancos: Banamex con Tarjetas Banamex; Santander con Santander Inclusión Financiera; CI Banco con Finanmadrid México; Banco del Bajío con Financiera Bajío; Banregio con Start Banregio; Inbursa con STM Financial, SOFOM Inbursa y CETELEM Inbursa; Afirme con Arrendadora Afirme; Banco Base con Arrendadora Base, Invex con Invex Consumo; Bancrea con Arrendadora Bancrea, así como Ve por Más con Arrendadora Ve por Más.
A7: Se incluyen los indicadores financieros destacados, los saldos de cada tipo de crédito y de la captación de recursos.
A8: Por último, se hace un compendio de los estados financieros que las instituciones de banca múltiple reportaron a esta Comisión, al igual que en las secciones anteriores, se incluye información consolidada de las instituciones de banca múltiple con las SOFOMER de cada banco.

Sheet Art_121
B4: REGLAS DE CARÁCTER GENERAL A QUE SE REFIERE EL ARTÍCULO 121 DE LA LEY DE INSTITUCIONES DE CRÉDITO.
B5: Con el fin de mantener informado al público sobre el desempeño de las instituciones que conforman al sector de banca múltiple, la CNBV con fundamento en lo dispuesto en el artículo 121 de la Ley de Instituciones de Crédito, en relación con los artículos 220 y 221 de las Disposiciones de carácter general aplicables a las instituciones de crédito (las Disposiciones), da a conocer la clasificación de las instituciones de banca múltiple en categorías, con base en el índice de capitalización requerido conforme a las disposiciones aplicables a los requerimientos de capitalización, emitidas por esta Comisión en términos del artículo 50 de la Ley de Instituciones de Crédito
B6: CLASIFICACIÓN DE LAS INSTITUCIONES DE BANCA MÚLTIPLE DE ACUERDO CON EL ARTÍCULO 220 DE LAS DISPOSICIONES
B7: INDICADORES DE CAPITALIZACIÓN CIFRAS AL 30 DE JUNIO DE 20251/
B8: Institución | C8: CCB 2/ % | D8: CCF 3/ % | E8: ICAP 4/ % | F8: Categoría 5/
B9: Actinver | C9: 18.227443 | D9: 18.227443 | E9: 18.227443 | F9: I
B10: Afirme | C10: 11.278408 | D10: 10.256816 | E10: 15.174032 | F10: I
B11: Autofin | C11: 13.227801 | D11: 13.227801 | E11: 13.227801 | F11: I
B12: Banamex | C12: 21.043783 | D12: 17.878001 | E12: 21.043783 | F12: I
B13: Banca Mifel | C13: 16.491486 | D13: 16.491486 | E13: 16.608245 | F13: I
B14: Banco Azteca | C14: 14.179915 | D14: 14.179915 | E14: 14.708639 | F14: I
B15: Banco Base | C15: 21.307347 | D15: 21.307347 | E15: 21.307347 | F15: I
B16: Banco Bineo | C16: 277.54151 | D16: 277.54151 | E16: 277.54151 | F16: I
B17: Banco Covalto | C17: 13.11962 | D17: 13.11962 | E17: 13.11962 | F17: I
B18: Banco del Bajío | C18: 14.288591 | D18: 14.288591 | E18: 14.525604 | F18: I
B19: Banco S3 | C19: 186.31448 | D19: 186.31448 | E19: 186.31448 | F19: I
B20: Banco Ualá | C20: 44.784858 | D20: 44.784858 | E20: 44.784858 | F20: I
... B60: Volkswagen Bank | C60: 27.47016 | D60: 27.47016 | E60: 27.47016 | F60: I
B61: Total Banca Múltiple | C61: 17.9131 | D61: 16.5832 | E61: 20.0006
B62: 1/ Dado a conocer a esta Comisión por el Banco de México el 12 de agosto de 2025, con base en la información entregada por las Instituciones, conforme a lo dispuesto por el artículo 2 Bis y 2 Bis 4 de las Disposiciones.
B63: 2/ CCB (Coeficiente de Capital Básico) = (Capital Fundamental + Capital no Fundamental) / Activos Ponderados Sujetos a Riesgo Total.
B64: 3/ CCF (Coeficiente de Capital Fundamental) = Capital Fundamental / Activos Ponderados Sujetos a Riesgo Total.
B65: 4/ ICAP (Índice de Capitalización) = Capital Neto / Activos Ponderados Sujetos a Riesgo Total.
B66: 5/ Categorías de Alertas Tempranas determinadas con base en el artículo 220 de las Disposiciones.

Sheet Ficha Técnica
B11: Evaluación de la Calidad de la Información
B12: Banca Múltiple
B14: Derivado de la mejora continua en los procesos de verificación de la calidad en la información, esta comisión ha modificado los criterios de evaluación de la calidad y los hábitos de envío de los reportes regulatorios que son transmitidos por las Instituciones de Banca Múltiple, por lo cual, se ha optado por generar un indicador único de calidad que refleje el estado actual obtenido para los reportes regulatorios, clasificados en 5 tipos de información distintos:
B20: Clave | C20: Clasificación | E20: Reportes | F20: Descripción
B21: 1 | C21: Situación financiera | E21: 22 | F21: Reportes de las series R01, R04 A, R06, R07, R08, R10, R12 , R13, R14, R32, R34 y R36.
B22: 2 | C22: Cartera Comercial | E22: 11 | F22: Reportes de la serie R04 C.
B23: 3 | C23: Cartera a la Vivienda | E23: 4 | F23: Reportes de la serie R04 H.
B24: 4 | C24: Captación | E24: 1 | F24: Reporte R24 B-2421.
B25: 5 | C25: Operativos | E25: 23 | F25: Reportes de las series R15, R24 B-2422, R24 B-2423, R24 C, R24 D, R24 E, R26, R27, R28, R29 y R35.
B27: Tomando en consideración la anterior clasificación, se generan 2 métricas para el cálculo del indicador único, como a continuación se muestra:
B30: 1. Calidad
B32: Para la medición del porcentaje de calidad obtenido, se identifican las incidencias presentadas en la ventana de evaluación del periodo, estas incidencias tienen ponderadores específicos para cada IBM, los cuáles se calculan a través de la distribución de sus errores presentados de manera histórica y se omiten aquellos reportes que por la naturaleza de su negocio no le son aplicables a cada IBM.
B37: 2. Oportunidad 1/
B39: Para la evaluación de hábitos de envío se consideran 3 conductas que no son adecuadas, siendo estas, los reenvíos, entregas extemporáneas y reportes omisos a la fecha de corte y que se encuentren en la ventana de evaluación. De igual forma se ponderan en la ventana de evaluación en función del comportamiento histórico y se ponderan de diferente forma en función del porcentaje de calidad obtenido.
B43: 2. Calificación final
B45: Tomando en consideración las 2 calificaciones previas, se determina una calificación final, la cual servirá como indicador general de evaluación para las IBM, el cual se calcula multiplicando el porcentaje de calidad obtenido por el porcentaje de oportunidad.
B50: Determinación de semáforos
B52: La determinación de semáforos se realiza con base en los siguientes criterios:
B54: Rojo | D54: Se asigna para instituciones que tienen una calificación final inferior a 90 puntos.
B56: Amarillo | D56: Se asigna para las instituciones que tienen una calificación de 90 o más y menor de 95 puntos.
B58: Verde | D58: Se asigna para las instituciones con 95 puntos o más.
B60: 1/ Debido a las intermitencias en el aplicativo SITI WEB, que han ocasionado retrasos involuntarios en la recepción de los Reportes Regulatorios transmitidos a la CNBV, la calificación no penaliza los hábitos de envío desde diciembre de 2023 hasta la fecha.

Sheet Evaluación Calidad
B7: Evaluación de la Calidad de la Información
B8: Banca Múltiple
B9: julio 2025
J10: Fecha de corte: 20 de agosto de 2025
B11: RANKING | C11: INSTITUCIÓN | G11: CALIFICACIÓN | J11: CALIDAD | K11: OPORTUNIDAD
B12: 1 | C12: 040002 | D12: Banamex | G12: 100 | H12: 100 | J12: 100 | K12: 100
B13: 1 | C13: 040126 | D13: Credit Suisse | G13: 100 | H13: 100 | J13: 100 | K13: 100
B14: 1 | C14: 040139 | D14: BIAfirme | G14: 100 | H14: 100 | J14: 100 | K14: 100
B15: 1 | C15: 040162 | D15: KEB Hana México | G15: 100 | H15: 100 | J15: 100 | K15: 100
B16: 1 | C16: 040165 | D16: Banco Bineo | G16: 100 | H16: 100 | J16: 100 | K16: 100
B17: 6 | C17: 040030 | D17: Banco del Bajío | G17: 99.86 | H17: 99.86 | J17: 99.86 | K17: 100
B18: 7 | C18: 040169 | D18: Openbank | G18: 99.84 | H18: 99.84 | J18: 99.84 | K18: 100
B19: 8 | C19: 040108 | D19: MUFG Bank | G19: 99.71 | H19: 99.71 | J19: 99.71 | K19: 100
B20: 8 | C20: 040151 | D20: Dondé Banco | G20: 99.71 | H20: 99.71 | J20: 99.71 | K20: 100
B21: 10 | C21: 040129 | D21: Barclays | G21: 99.56 | H21: 99.56 | J21: 99.56 | K21: 100
B22: 11 | C22: 040147 | D22: Bankaool | G22: 99.43 | H22: 99.43 | J22: 99.43 | K22: 100
B23: 12 | C23: 040159 | D23: Bank of China | G23: 99.42 | H23: 99.42 | J23: 99.42 | K23: 100
... B63: 52 | C63: 040136 | D63: Intercam Banco | G63: 77.4 | H63: 77.4 | J63: 77.4 | K63: 100
B101: =_xlfn.XLOOKUP(C101,[1]Calificación!D:D,[1]Calificación!A:A,"",0,1) | C101: =IF([1]Calificación!D88=0,"",[1]Calificación!D88) | D101: =IFERROR(VLOOKUP(C101,[1]Calificación!$D$1:$X$53,2,0),"") | G101: =IFERROR(VLOOKUP(C101,[1]Calificación!$D$1:$X$53,5,0),"") | H101: =IFERROR(VLOOKUP(C101,[1]Calificación!$D$1:$X$53,6,0),"") | J101: =IFERROR(VLOOKUP(C101,[1]Calificación!$D$1:$X$53,3,0),"") | K101: =IFERROR(VLOOKUP(C101,[1]Calificación!$D$1:$X$53,4,0),"")
B102: =_xlfn.XLOOKUP(C102,[1]Calificación!D:D,[1]Calificación!A:A,"",0,1) | C102: =IF([1]Calificación!D89=0,"",[1]Calificación!D89) | D102: =IFERROR(VLOOKUP(C102,[1]Calificación!$D$1:$X$53,2,0),"") | G102: =IFERROR(VLOOKUP(C102,[1]Calificación!$D$1:$X$53,5,0),"") | H102: =IFERROR(VLOOKUP(C102,[1]Calificación!$D$1:$X$53,6,0),"") | J102: =IFERROR(VLOOKUP(C102,[1]Calificación!$D$1:$X$53,3,0),"") | K102: =IFERROR(VLOOKUP(C102,[1]Calificación!$D$1:$X$53,4,0),"")
B103: =_xlfn.XLOOKUP(C103,[1]Calificación!D:D,[1]Calificación!A:A,"",0,1) | C103: =IF([1]Calificación!D90=0,"",[1]Calificación!D90) | D103: =IFERROR(VLOOKUP(C103,[1]Calificación!$D$1:$X$53,2,0),"") | G103: =IFERROR(VLOOKUP(C103,[1]Calificación!$D$1:$X$53,5,0),"") | H103: =IFERROR(VLOOKUP(C103,[1]Calificación!$D$1:$X$53,6,0),"") | J103: =IFERROR(VLOOKUP(C103,[1]Calificación!$D$1:$X$53,3,0),"") | K103: =IFERROR(VLOOKUP(C103,[1]Calificación!$D$1:$X$53,4,0),"")
B104: =_xlfn.XLOOKUP(C104,[1]Calificación!D:D,[1]Calificación!A:A,"",0,1) | C104: =IF([1]Calificación!D91=0,"",[1]Calificación!D91) | D104: =IFERROR(VLOOKUP(C104,[1]Calificación!$D$1:$X$53,2,0),"") | G104: =IFERROR(VLOOKUP(C104,[1]Calificación!$D$1:$X$53,5,0),"") | H104: =IFERROR(VLOOKUP(C104,[1]Calificación!$D$1:$X$53,6,0),"") | J104: =IFERROR(VLOOKUP(C104,[1]Calificación!$D$1:$X$53,3,0),"") | K104: =IFERROR(VLOOKUP(C104,[1]Calificación!$D$1:$X$53,4,0),"")
B105: =_xlfn.XLOOKUP(C105,[1]Calificación!D:D,[1]Calificación!A:A,"",0,1) | C105: =IF([1]Calificación!D92=0,"",[1]Calificación!D92) | D105: =IFERROR(VLOOKUP(C105,[1]Calificación!$D$1:$X$53,2,0),"") | G105: =IFERROR(VLOOKUP(C105,[1]Calificación!$D$1:$X$53,5,0),"") | H105: =IFERROR(VLOOKUP(C105,[1]Calificación!$D$1:$X$53,6,0),"") | J105: =IFERROR(VLOOKUP(C105,[1]Calificación!$D$1:$X$53,3,0),"") | K105: =IFERROR(VLOOKUP(C105,[1]Calificación!$D$1:$X$53,4,0),"")
B106: =_xlfn.XLOOKUP(C106,[1]Calificación!D:D,[1]Calificación!A:A,"",0,1) | C106: =IF([1]Calificación!D93=0,"",[1]Calificación!D93) | D106: =IFERROR(VLOOKUP(C106,[1]Calificación!$D$1:$X$53,2,0),"") | G106: =IFERROR(VLOOKUP(C106,[1]Calificación!$D$1:$X$53,5,0),"") | H106: =IFERROR(VLOOKUP(C106,[1]Calificación!$D$1:$X$53,6,0),"") | J106: =IFERROR(VLOOKUP(C106,[1]Calificación!$D$1:$X$53,3,0),"") | K106: =IFERROR(VLOOKUP(C106,[1]Calificación!$D$1:$X$53,4,0),"")
B107: =_xlfn.XLOOKUP(C107,[1]Calificación!D:D,[1]Calificación!A:A,"",0,1) | C107: =IF([1]Calificación!D94=0,"",[1]Calificación!D94) | D107: =IFERROR(VLOOKUP(C107,[1]Calificación!$D$1:$X$53,2,0),"") | G107: =IFERROR(VLOOKUP(C107,[1]Calificación!$D$1:$X$53,5,0),"") | H107: =IFERROR(VLOOKUP(C107,[1]Calificación!$D$1:$X$53,6,0),"") | J107: =IFERROR(VLOOKUP(C107,[1]Calificación!$D$1:$X$53,3,0),"") | K107: =IFERROR(VLOOKUP(C107,[1]Calificación!$D$1:$X$53,4,0),"")
B108: =_xlfn.XLOOKUP(C108,[1]Calificación!D:D,[1]Calificación!A:A,"",0,1) | C108: =IF([1]Calificación!D95=0,"",[1]Calificación!D95) | D108: =IFERROR(VLOOKUP(C108,[1]Calificación!$D$1:$X$53,2,0),"") | G108: =IFERROR(VLOOKUP(C108,[1]Calificación!$D$1:$X$53,5,0),"") | H108: =IFERROR(VLOOKUP(C108,[1]Calificación!$D$1:$X$53,6,0),"") | J108: =IFERROR(VLOOKUP(C108,[1]Calificación!$D$1:$X$53,3,0),"") | K108: =IFERROR(VLOOKUP(C108,[1]Calificación!$D$1:$X$53,4,0),"")
B109: =_xlfn.XLOOKUP(C109,[1]Calificación!D:D,[1]Calificación!A:A,"",0,1) | C109: =IF([1]Calificación!D96=0,"",[1]Calificación!D96) | D109: =IFERROR(VLOOKUP(C109,[1]Calificación!$D$1:$X$53,2,0),"") | G109: =IFERROR(VLOOKUP(C109,[1]Calificación!$D$1:$X$53,5,0),"") | H109: =IFERROR(VLOOKUP(C109,[1]Calificación!$D$1:$X$53,6,0),"") | J109: =IFERROR(VLOOKUP(C109,[1]Calificación!$D$1:$X$53,3,0),"") | K109: =IFERROR(VLOOKUP(C109,[1]Calificación!$D$1:$X$53,4,0),"")
B110: =_xlfn.XLOOKUP(C110,[1]Calificación!D:D,[1]Calificación!A:A,"",0,1) | C110: =IF([1]Calificación!D97=0,"",[1]Calificación!D97) | D110: =IFERROR(VLOOKUP(C110,[1]Calificación!$D$1:$X$53,2,0),"") | G110: =IFERROR(VLOOKUP(C110,[1]Calificación!$D$1:$X$53,5,0),"") | H110: =IFERROR(VLOOKUP(C110,[1]Calificación!$D$1:$X$53,6,0),"") | J110: =IFERROR(VLOOKUP(C110,[1]Calificación!$D$1:$X$53,3,0),"") | K110: =IFERROR(VLOOKUP(C110,[1]Calificación!$D$1:$X$53,4,0),"")
B111: =_xlfn.XLOOKUP(C111,[1]Calificación!D:D,[1]Calificación!A:A,"",0,1) | C111: =IF([1]Calificación!D98=0,"",[1]Calificación!D98) | D111: =IFERROR(VLOOKUP(C111,[1]Calificación!$D$1:$X$53,2,0),"") | G111: =IFERROR(VLOOKUP(C111,[1]Calificación!$D$1:$X$53,5,0),"") | H111: =IFERROR(VLOOKUP(C111,[1]Calificación!$D$1:$X$53,6,0),"") | J111: =IFERROR(VLOOKUP(C111,[1]Calificación!$D$1:$X$53,3,0),"") | K111: =IFERROR(VLOOKUP(C111,[1]Calificación!$D$1:$X$53,4,0),"")
B112: =_xlfn.XLOOKUP(C112,[1]Calificación!D:D,[1]Calificación!A:A,"",0,1) | C112: =IF([1]Calificación!D99=0,"",[1]Calificación!D99) | D112: =IFERROR(VLOOKUP(C112,[1]Calificación!$D$1:$X$53,2,0),"") | G112: =IFERROR(VLOOKUP(C112,[1]Calificación!$D$1:$X$53,5,0),"") | H112: =IFERROR(VLOOKUP(C112,[1]Calificación!$D$1:$X$53,6,0),"") | J112: =IFERROR(VLOOKUP(C112,[1]Calificación!$D$1:$X$53,3,0),"") | K112: =IFERROR(VLOOKUP(C112,[1]Calificación!$D$1:$X$53,4,0),"")
... B133: =_xlfn.XLOOKUP(C133,[1]Calificación!D:D,[1]Calificación!A:A,"",0,1) | C133: =IF([1]Calificación!D120=0,"",[1]Calificación!D120) | D133: =IFERROR(VLOOKUP(C133,[1]Calificación!$D$1:$X$53,2,0),"") | G133: =IFERROR(VLOOKUP(C133,[1]Calificación!$D$1:$X$53,5,0),"") | H133: =IFERROR(VLOOKUP(C133,[1]Calificación!$D$1:$X$53,6,0),"") | J133: =IFERROR(VLOOKUP(C133,[1]Calificación!$D$1:$X$53,3,0),"") | K133: =IFERROR(VLOOKUP(C133,[1]Calificación!$D$1:$X$53,4,0),"")

Sheet Evaluación Calidad Grupos
B7: Evaluación de la Calidad de la Información
B8: Banca Múltiple
B9: julio 2025
K10: Fecha de corte: 20 de agosto de 2025
B11: RANKING | C11: INSTITUCIÓN | G11: CALIFICACIÓN | K11: CALIDAD | L11: OPORTUNIDAD
B12: G7
B13: 1 | C13: 040002 | D13: Banamex | G13: 100 | H13: 100 | K13: 100 | L13: 100 | O13: G-7
B14: 2 | C14: 040072 | D14: Banorte | G14: 98.46 | H14: 98.46 | K14: 98.46 | L14: 100 | O14: G-7
B15: 3 | C15: 040044 | D15: Scotiabank | G15: 97.27 | H15: 97.27 | K15: 97.27 | L15: 100 | O15: G-7
B16: 4 | C16: 040036 | D16: Inbursa | G16: 96.8 | H16: 96.8 | K16: 96.8 | L16: 100 | O16: G-7
B17: 5 | C17: 040021 | D17: HSBC | G17: 95.6 | H17: 95.6 | K17: 95.6 | L17: 100 | O17: G-7
B18: 6 | C18: 040012 | D18: BBVA México | G18: 95.08 | H18: 95.08 | K18: 95.08 | L18: 100 | O18: G-7
B19: 7 | C19: 040014 | D19: Santander | G19: 90.06 | H19: 90.06 | K19: 90.06 | L19: 100 | O19: G-7
B21: BANCOS CAMBIARIOS
B22: 1 | C22: 040112 | D22: Monex | G22: 96.53 | H22: 96.53 | K22: 96.53 | L22: 100 | O22: Bancos Cambiarios
B23: 2 | C23: 040143 | D23: CIBanco | G23: 93.9 | H23: 93.9 | K23: 93.9 | L23: 100 | O23: Bancos Cambiarios
B24: 3 | C24: 040145 | D24: Banco Base | G24: 90.46 | H24: 90.46 | K24: 90.46 | L24: 100 | O24: Bancos Cambiarios
B25: 4 | C25: 040136 | D25: Intercam Banco | G25: 77.4 | H25: 77.4 | K25: 77.4 | L25: 100 | O25: Bancos Cambiarios
B27: BANCA DE INVERSIÓN Y OTROS SERVICIOS
B28: 1 | C28: 040126 | D28: Credit Suisse | G28: 100 | H28: 100 | K28: 100 | L28: 100 | O28: Banca de Inversión y Otros Servicios
B29: 1 | C29: 040139 | D29: BIAfirme | G29: 100 | H29: 100 | K29: 100 | L29: 100 | O29: Banca de Inversión y Otros Servicios
B30: 3 | C30: 040108 | D30: MUFG Bank | G30: 99.71 | H30: 99.71 | K30: 99.71 | L30: 100 | O30: Banca de Inversión y Otros Servicios
B31: 4 | C31: 040129 | D31: Barclays | G31: 99.56 | H31: 99.56 | K31: 99.56 | L31: 100 | O31: Banca de Inversión y Otros Servicios
B32: 5 | C32: 040124 | D32: Citi México (Antes CBM Banco) | G32: 99.19 | H32: 99.19 | K32: 99.19 | L32: 100 | O32: Banca de Inversión y Otros Servicios
B33: 6 | C33: 040148 | D33: Pagatodo | G33: 98.41 | H33: 98.41 | K33: 98.41 | L33: 100 | O33: Banca de Inversión y Otros Servicios
B34: 7 | C34: 040164 | D34: BNP Paribas México | G34: 97.99 | H34: 97.99 | K34: 97.99 | L34: 100 | O34: Banca de Inversión y Otros Servicios
B35: 8 | C35: 040106 | D35: Bank of America | G35: 97.84 | H35: 97.84 | K35: 97.84 | L35: 100 | O35: Banca de Inversión y Otros Servicios
B36: 9 | C36: 040160 | D36: Banco S3 | G36: 96.48 | H36: 96.48 | K36: 96.48 | L36: 100 | O36: Banca de Inversión y Otros Servicios
B37: 10 | C37: 040110 | D37: J.P. Morgan | G37: 94.64 | H37: 94.64 | K37: 94.64 | L37: 100 | O37: Banca de Inversión y Otros Servicios
B38: 11 | C38: 040062 | D38: Afirme | G38: 92.93 | H38: 92.93 | K38: 92.93 | L38: 100 | O38: Banca de Inversión y Otros Servicios
B39: 12 | C39: 040059 | D39: Invex | G39: 89 | H39: 89 | K39: 89 | L39: 100 | O39: Banca de Inversión y Otros Servicios
B41: COMERCIAL MEDIANO
B42: 1 | C42: 040030 | D42: Banco del Bajío | G42: 99.86 | H42: 99.86 | K42: 99.86 | L42: 100 | O42: Comercial Mediano
B43: 2 | C43: 040113 | D43: Ve por Más | G43: 99.36 | H43: 99.36 | K43: 99.36 | L43: 100 | O43: Comercial Mediano
B44: 3 | C44: 040156 | D44: Sabadell | G44: 98.66 | H44: 98.66 | K44: 98.66 | L44: 100 | O44: Comercial Mediano
B45: 4 | C45: 040058 | D45: Banregio | G45: 96.87 | H45: 96.87 | K45: 96.87 | L45: 100 | O45: Comercial Mediano
B46: 5 | C46: 040132 | D46: Multiva | G46: 95.22 | H46: 95.22 | K46: 95.22 | L46: 100 | O46: Comercial Mediano
B47: 6 | C47: 040042 | D47: Banca Mifel | G47: 93.55 | H47: 93.55 | K47: 93.55 | L47: 100 | O47: Comercial Mediano
B49: COMERCIAL PEQUEÑO
B50: 1 | C50: 040162 | D50: KEB Hana México | G50: 100 | H50: 100 | K50: 100 | L50: 100 | O50: Comercial pequeño
...

Sheet Evaluación Calidad Detallada
B3: Evaluación de la Calidad de la Información
B4: Banca Múltiple
B5: julio 2025
M6: Fecha de corte: 20 de agosto de 2025
B8: RANKING | C8: INSTITUCIÓN | G8: SITUACIÓN FINANCIERA | J8: CARTERA COMERCIAL | M8: CARTERA A LA VIVIENDA | P8: PRODUCTOS DE CAPTACIÓN | S8: OPERATIVOS
G9: CALIDAD | H9: OPORTUNIDAD | J9: CALIDAD | K9: OPORTUNIDAD | M9: CALIDAD | N9: OPORTUNIDAD | P9: CALIDAD | Q9: OPORTUNIDAD | S9: CALIDAD | T9: OPORTUNIDAD
B10: 1 | C10: 040002 | D10: Banamex | G10: 100 | H10: 100 | J10: 100 | K10: 100 | M10: 100 | N10: 100 | P10: 100 | Q10: 100 | S10: 100 | T10: 100
B11: 1 | C11: 040126 | D11: Credit Suisse | G11: 100 | H11: 100 | J11: n.a | K11: 100 | M11: n.a | N11: 100 | P11: 100 | Q11: 100 | S11: 100 | T11: 100
B12: 1 | C12: 040139 | D12: BIAfirme | G12: 100 | H12: 100 | J12: 100 | K12: 100 | M12: n.a | N12: 100 | P12: 100 | Q12: 100 | S12: 100 | T12: 100
B13: 1 | C13: 040162 | D13: KEB Hana México | G13: 100 | H13: 100 | J13: 100 | K13: 100 | M13: n.a | N13: 100 | P13: 100 | Q13: 100 | S13: 100 | T13: 100
B14: 1 | C14: 040165 | D14: Banco Bineo | G14: 100 | H14: 100 | J14: n.a | K14: 100 | M14: n.a | N14: 100 | P14: 100 | Q14: 100 | S14: 100 | T14: 100
B15: 6 | C15: 040030 | D15: Banco del Bajío | G15: 100 | H15: 100 | J15: 99.52 | K15: 100 | M15: 100 | N15: 100 | P15: 100 | Q15: 100 | S15: 100 | T15: 100
B16: 7 | C16: 040169 | D16: Openbank | G16: 99.73 | H16: 100 | J16: n.a | K16: 100 | M16: n.a | N16: 100 | P16: 100 | Q16: 100 | S16: 100 | T16: 100
B17: 8 | C17: 040108 | D17: MUFG Bank | G17: 99.73 | H17: 100 | J17: 99.54 | K17: 100 | M17: n.a | N17: 100 | P17: 100 | Q17: 100 | S17: 100 | T17: 100
B18: 8 | C18: 040151 | D18: Dondé Banco | G18: 100 | H18: 100 | J18: 99.54 | K18: 100 | M18: n.a | N18: 100 | P18: 97.44 | Q18: 100 | S18: 100 | T18: 100
B19: 10 | C19: 040129 | D19: Barclays | G19: 99.1 | H19: 100 | J19: n.a | K19: 100 | M19: n.a | N19: 100 | P19: 100 | Q19: 100 | S19: 100 | T19: 100
B20: 11 | C20: 040147 | D20: Bankaool | G20: 99.47 | H20: 100 | J20: 99.54 | K20: 100 | M20: n.a | N20: 100 | P20: 100 | Q20: 100 | S20: 98.97 | T20: 100
B21: 12 | C21: 040159 | D21: Bank of China | G21: 99.43 | H21: 100 | J21: 100 | K21: 100 | M21: n.a | N21: 100 | P21: 89.74 | Q21: 100 | S21: 100 | T21: 100
B22: 13 | C22: 040113 | D22: Ve por Más | G22: 100 | H22: 100 | J22: 98.04 | K22: 100 | M22: 100 | N22: 100 | P22: 100 | Q22: 100 | S22: 99.49 | T22: 100
B23: 14 | C23: 040149 | D23: Forjadores | G23: 100 | H23: 100 | J23: 98.15 | K23: 100 | M23: n.a | N23: 100 | P23: 100 | Q23: 100 | S23: 100 | T23: 100
B24: 15 | C24: 040124 | D24: Citi México (Antes CBM Banco) | G24: 100 | H24: 100 | J24: 99 | K24: 100 | M24: n.a | N24: 100 | P24: n.a | Q24: 100 | S24: 97.95 | T24: 100
B25: 16 | C25: 040130 | D25: Compartamos | G25: 99.01 | H25: 100 | J25: 99.76 | K25: 100 | M25: n.a | N25: 100 | P25: 87.18 | Q25: 100 | S25: 100 | T25: 100
B26: 17 | C26: 040155 | D26: ICBC | G26: 97.25 | H26: 100 | J26: 100 | K26: 100 | M26: n.a | N26: 100 | P26: 94.87 | Q26: 100 | S26: 100 | T26: 100
B27: 18 | C27: 040141 | D27: Volkswagen Bank | G27: 99.49 | H27: 100 | J27: n.a | K27: 100 | M27: n.a | N27: 100 | P27: 100 | Q27: 100 | S27: 100 | T27: 100
B28: 19 | C28: 040156 | D28: Sabadell | G28: 100 | H28: 100 | J28: 95.9 | K28: 100 | M28: 99.73 | N28: 100 | P28: 100 | Q28: 100 | S28: 100 | T28: 100
B29: 20 | C29: 040072 | D29: Banorte | G29: 100 | H29: 100 | J29: 99.76 | K29: 100 | M29: 94.99 | N29: 100 | P29: 100 | Q29: 100 | S29: 100 | T29: 100
B30: 21 | C30: 040148 | D30: Pagatodo | G30: 100 | H30: 100 | J30: n.a | K30: 100 | M30: n.a | N30: 100 | P30: 82.05 | Q30: 100 | S30: 100 | T30: 100
B31: 22 | C31: 040060 | D31: Bansí | G31: 100 | H31: 100 | J31: 96.6 | K31: 100 | M31: 100 | N31: 100 | P31: 100 | Q31: 100 | S31: 94.36 | T31: 100
B32: 23 | C32: 040164 | D32: BNP Paribas México | G32: 96.1 | H32: 100 | J32: n.a | K32: 100 | M32: n.a | N32: 100 | P32: n.a | Q32: 100 | S32: 100 | T32: 100
B33: 24 | C33: 040106 | D33: Bank of America | G33: 98.87 | H33: 100 | J33: 98.14 | K33: 100 | M33: n.a | N33: 100 | P33: 97.44 | Q33: 100 | S33: 95.38 | T33: 100
B34: 25 | C34: 040158 | D34: Mizuho Bank | G34: 99.18 | H34: 100 | J34: 94.55 | K34: 100 | M34: n.a | N34: 100 | P34: 100 | Q34: 100 | S34: 100 | T34: 100
B35: 26 | C35: 040044 | D35: Scotiabank | G35: 100 | H35: 100 | J35: 100 | K35: 100 | M35: 90.81 | N35: 100 | P35: 100 | Q35: 100 | S35: 100 | T35: 100
B36: 27 | C36: 040157 | D36: Shinhan | G36: 100 | H36: 100 | J36: 93.51 | K36: 100 | M36: n.a | N36: 100 | P36: 100 | Q36: 100 | S36: 100 | T36: 100
B37: 28 | C37: 040137 | D37: Bancoppel | G37: 96.4 | H37: 100 | J37: 96.94 | K37: 100 | M37: 99.31 | N37: 100 | P37: 100 | Q37: 100 | S37: 93.85 | T37: 100
B38: 29 | C38: 040058 | D38: Banregio | G38: 100 | H38: 100 | J38: 96.43 | K38: 100 | M38: 92.77 | N38: 100 | P38: 100 | Q38: 100 | S38: 100 | T38: 100
B39: 30 | C39: 040036 | D39: Inbursa | G39: 99.47 | H39: 100 | J39: 95.99 | K39: 100 | M39: 98.68 | N39: 100 | P39: 66.67 | Q39: 100 | S39: 95.38 | T39: 100
B40: 31 | C40: 040112 | D40: Monex | G40: 100 | H40: 100 | J40: 91.32 | K40: 100 | M40: 100 | N40: 100 | P40: 100 | Q40: 100 | S40: 93.33 | T40: 100
B41: 32 | C41: 040160 | D41: Banco S3 | G41: 97.55 | H41: 100 | J41: 95.79 | K41: 100 | M41: n.a | N41: 100 | P41: 100 | Q41: 100 | S41: 95.38 | T41: 100
B42: 33 | C42: 040133 | D42: Actinver | G42: 99.73 | H42: 100 | J42: 92.19 | K42: 100 | M42: n.a | N42: 100 | P42: 97.44 | Q42: 100 | S42: 100 | T42: 100
B43: 34 | C43: 040150 | D43: Inmobiliario Mexicano | G43: 100 | H43: 100 | J43: 87.5 | K43: 100 | M43: 100 | N43: 100 | P43: 100 | Q43: 100 | S43: 100 | T43: 100
...

Sheet Portadilla I
A7: I. Índice de Capitalización y Evaluación de la Calidad de la Información.
A8: El objetivo de este apartado es proporcionar al público los indicadores de capitalización de los bancos, con las cifras disponibles en la fecha de elaboración del presente boletín, así como la clasificación de las instituciones de banca múltiple en distintas categorías, de acuerdo con las disposiciones de Alertas Tempranas.
A9: Por otra parte, se presenta la evaluación de la calidad y oportunidad de la información que entregan las instituciones a este Organismo, la cual considera la oportunidad con la que reportan y el número de reenvíos.

Sheet Portadilla II
B2: II. Estadísticas de la Banca Múltiple
B3: El objetivo de este apartado es proporcionar al público indicadores estadísticos que reflejen adecuadamente la evolución de la condición financiera de la Banca Múltiple, por lo que en esta sección, se presenta la información reportada por las 52 instituciones de banca múltiple en operación correspondiente a julio de 2025, consolidada con la de sus SOFOMER en el caso de las siguientes instituciones: Banamex con Tarjetas Banamex; Santander con Santander Inclusión Financiera; CI Banco con Finanmadrid México; Banco del Bajío con Financiera Bajío; Banregio con Start Banregio; Inbursa con STM Financial, SOFOM Inbursa y CETELEM Inbursa; Afirme con Arrendadora Afirme; Banco Base con Arrendadora Base, Invex con Invex Consumo; Bancrea con Arrendadora Bancrea, así como Ve por Más con Arrendadora Ve por Más.
B5: Notas:
B7: 1/ Para la cartera total se considera la información de cartera de los bancos junto con la cartera de sus respectivas Sociedades Financieras de Objeto Múltiple Reguladas a las que consolidan. Hasta diciembre 2021: Cartera total = Cartera vigente + cartera vencida. A partir de enero 2022: Cartera total = Cartera de crédito con riesgo de crédito en etapa 1 + 2 + 3 + cartera de crédito valuada a valor razonable.
B9: 2/ Respecto al resultado neto se muestran saldos acumulados al cierre de mes.
B10: 3/ ROA = Resultado neto (flujo 12 meses) / Activos totales, promedio 12 meses.
B11: 4/ ROE = Resultado neto (flujo 12 meses) / Capital contable, promedio 12 meses.
B12: 5/ Hasta diciembre 2021: IMOR = Índice de Morosidad = cartera vencida / (Cartera vigente + cartera vencida). A partir de enero 2022: IMOR = Índice de Morosidad = cartera de crédito con riesgo de crédito en etapa 3 / (Cartera de crédito con riesgo de crédito en etapa 1 + 2 + 3).
B13: 6/ Hasta diciembre 2021: ICOR = Índice de cobertura= Estimaciones preventivas para riesgos crediticios del balance general / cartera de crédito vencida. A partir de enero 2022: ICOR = Índice de cobertura= Estimaciones preventivas para riesgos crediticios del estado de situación financiera / cartera de crédito con riesgo de crédito en etapa 3.
B14: 7/ Hasta diciembre 2021: Estimaciones preventivas para riesgo crediticio del balance general / (Cartera vigente + cartera vencida). A partir de enero 2022: Estimaciones preventivas para riesgo crediticio del estado de situación financiera / (Cartera de crédito con riesgo de crédito en etapa 1 + 2 + 3).
B16: */ En todos los casos se presentan las instituciones en orden descendente por tamaño de activo total en el mes de análisis más reciente.
B18: El símbolo ( - ) indica que la cifra es cero. Las cifras en cero indican una cantidad cercana a cero.
... B21: n.d.: No disponible

Sheet Pm2
B3: Principales rubros del estado de situación financiera y estado de resultado integral
B4: Millones de pesos y porcentajes
C5: Activo total | I5: Inversiones en instrumentos financieros | O5: Cartera total1/ | U5: Captación total | AA5: Capital contable | AG5: Resultado neto 2/
C6: 45474 | E6: 45809 | G6: 45839 | I6: =+$C$6 -> 45474 | K6: =+$E$6 -> 45809 | M6: =+$G$6 -> 45839 | O6: =+$C$6 -> 45474 | Q6: =+$E$6 -> 45809 | S6: =+$G$6 -> 45839 | U6: =+$C$6 -> 45474 | W6: =+$E$6 -> 45809 | Y6: =+$G$6 -> 45839 | AA6: =+$C$6 -> 45474 | AC6: =+$E$6 -> 45809 | AE6: =+$G$6 -> 45839 | AG6: =+$C$6 -> 45474 | AI6: =+$E$6 -> 45809 | AK6: =+$G$6 -> 45839
B7: Sistema */ | C7: 14250900 | D7: 100 | E7: 15291765 | F7: 100 | G7: 15388038 | H7: 100 | I7: 3765691.1 | J7: 100 | K7: 4019339.3 | L7: 100 | M7: 4052410.9 | N7: 100 | O7: 7229546 | P7: 100 | Q7: 7797749.9 | R7: 100 | S7: 7839661.6 | T7: 100 | U7: 8419009.1 | V7: 100 | W7: 9112459.1 | X7: 100 | Y7: 9174885.7 | Z7: 100 | AA7: 1588509.5 | AB7: 100 | AC7: 1751973.7 | AD7: 100 | AE7: 1775851.1 | AF7: 100 | AG7: 171838.95 | AH7: 100 | AI7: 152476.18 | AJ7: 100 | AK7: 178430.47 | AL7: 100
B8: BBVA México | C8: 3114454.9 | D8: 21.854444 | E8: 3322036.1 | F8: 21.724346 | G8: 3340530.4 | H8: 21.708617 | I8: 665247.96 | J8: 17.666026 | K8: 610149.88 | L8: 15.180353 | M8: 598949.41 | N8: 14.780076 | O8: 1814429.7 | P8: 25.097422 | Q8: 1992989.5 | R8: 25.558521 | S8: 2015513.2 | T8: 25.709186 | U8: 1807909.4 | V8: 21.474135 | W8: 2083231.9 | X8: 22.861359 | Y8: 2036733.9 | Z8: 22.199012 | AA8: 351794.66 | AB8: 22.14621 | AC8: 382849.72 | AD8: 21.852481 | AE8: 390680.59 | AF8: 21.999625 | AG8: 54549.034 | AH8: 31.744277 | AI8: 49443.265 | AJ8: 32.426879 | AK8: 57711.877 | AL8: 32.344182
B9: Santander | C9: 1881689.9 | D9: 13.204008 | E9: 1950806.7 | F9: 12.757237 | G9: 1974060 | H9: 12.828536 | I9: 601078.02 | J9: 15.961958 | K9: 588439.42 | L9: 14.640203 | M9: 593626.65 | N9: 14.648728 | O9: 880156.9 | P9: 12.174442 | Q9: 932042.92 | R9: 11.952716 | S9: 934236.43 | T9: 11.916795 | U9: 1018558.3 | V9: 12.098316 | W9: 1077295.9 | X9: 11.822231 | Y9: 1098918.5 | Z9: 11.977463 | AA9: 162165.49 | AB9: 10.208657 | AC9: 158890.49 | AD9: 9.0692279 | AE9: 161669.97 | AF9: 9.103802 | AG9: 17402.803 | AH9: 10.127391 | AI9: 15658.709 | AJ9: 10.26961 | AK9: 18535.116 | AL9: 10.387865
B10: Banorte | C10: 1788025.2 | D10: 12.546754 | E10: 1886627.8 | F10: 12.337541 | G10: 1887469.4 | H10: 12.265822 | I10: 397587.24 | J10: 10.558148 | K10: 430204.83 | L10: 10.703372 | M10: 451283.27 | N10: 11.136168 | O10: 1061820.3 | P10: 14.687234 | Q10: 1141382.7 | R10: 14.637334 | S10: 1148959.6 | T10: 14.655729 | U10: 1128928.2 | V10: 13.409276 | W10: 1210098.5 | X10: 13.279605 | Y10: 1186183.1 | Z10: 12.928587 | AA10: 147009.54 | AB10: 9.2545584 | AC10: 163319.58 | AD10: 9.322034 | AE10: 166405.23 | AF10: 9.3704493 | AG10: 26487.739 | AH10: 15.414281 | AI10: 23154.875 | AJ10: 15.185897 | AK10: 27354.42 | AL10: 15.330577
B11: Banamex | C11: 1505565.7 | D11: 10.564707 | E11: 1091590.1 | F11: 7.1384178 | G11: 1106121.1 | H11: 7.1881877 | I11: 571164.98 | J11: 15.1676 | K11: 397583.61 | L11: 9.8917653 | M11: 416428.74 | N11: 10.276074 | O11: 612393.6 | P11: 8.4707061 | Q11: 484729.32 | R11: 6.2162717 | S11: 486300.07 | T11: 6.2030748 | U11: 957318.31 | V11: 11.370914 | W11: 746120.08 | X11: 8.1879114 | Y11: 763127.06 | Z11: 8.3175647 | AA11: 225708.06 | AB11: 14.208795 | AC11: 176197.18 | AD11: 10.057068 | AE11: 177913.35 | AF11: 10.018483 | AG11: 14107.768 | AH11: 8.2098775 | AI11: 6696.5835 | AJ11: 4.3918884 | AK11: 8553.0559 | AL11: 4.7934951
B12: HSBC | C12: 877324.73 | D12: 6.1562761 | E12: 930938.04 | F12: 6.0878389 | G12: 907745.99 | H12: 5.8990364 | I12: 170070.79 | J12: 4.5163236 | K12: 213179.62 | L12: 5.3038473 | M12: 210476.27 | N12: 5.193853 | O12: 498407.66 | P12: 6.8940381 | Q12: 497726.33 | R12: 6.3829481 | S12: 493741.75 | T12: 6.2979982 | U12: 594973.04 | V12: 7.0670198 | W12: 567634.81 | X12: 6.2292165 | Y12: 574253.19 | Z12: 6.2589683 | AA12: 81604.711 | AB12: 5.1371875 | AC12: 85841.897 | AD12: 4.8997253 | AE12: 86701.786 | AF12: 4.8822665 | AG12: 5484.0527 | AH12: 3.1913909 | AI12: 4210.4206 | AJ12: 2.7613629 | AK12: 5108.3384 | AL12: 2.8629294
B13: Scotiabank | C13: 887994.22 | D13: 6.231145 | E13: 873397.97 | F13: 5.7115574 | G13: 861735.43 | H13: 5.6000343 | I13: 185061.29 | J13: 4.9144043 | K13: 163538.32 | L13: 4.0687862 | M13: 166595.17 | N13: 4.1110138 | O13: 523954.07 | P13: 7.2473993 | Q13: 521395.83 | R13: 6.6864908 | S13: 527986.99 | T13: 6.7348186 | U13: 603698.01 | V13: 7.1706539 | W13: 574302.99 | X13: 6.3023931 | Y13: 589058.65 | Z13: 6.4203378 | AA13: 84899.566 | AB13: 5.3446055 | AC13: 90784.527 | AD13: 5.181843 | AE13: 91615.061 | AF13: 5.1589381 | AG13: 6166.4227 | AH13: 3.5884894 | AI13: 4949.2409 | AJ13: 3.245911 | AK13: 5781.6631 | AL13: 3.2402891
B14: Inbursa | C14: 617591.42 | D14: 4.3337013 | E14: 701151.91 | F14: 4.58516 | G14: 698989.33 | H14: 4.54242 | I14: 65740.009 | J14: 1.7457621 | K14: 77138.307 | L14: 1.9191788 | M14: 70030.352 | N14: 1.7281158 | O14: 430414.24 | P14: 5.9535445 | Q14: 462573.5 | R14: 5.9321407 | S14: 461921.58 | T14: 5.8921112 | U14: 419524.95 | V14: 4.983068 | W14: 460048.99 | X14: 5.0485713 | Y14: 465217.13 | Z14: 5.0705496 | AA14: 167612.82 | AB14: 10.551578 | AC14: 198560.63 | AD14: 11.333539 | AE14: 200527.29 | AF14: 11.291897 | AG14: 14117.417 | AH14: 8.2154927 | AI14: 11562.677 | AJ14: 7.5832682 | AK14: 13661.102 | AL14: 7.6562607
B15: Citi México | C15: 2069.4533 | D15: 0.014521563 | E15: 567213.88 | F15: 3.7092766 | G15: 577231.71 | H15: 3.7511715 | I15: 0.00098524 | J15: 2.616359e-08 | K15: 202299.19 | L15: 5.0331455 | M15: 235392.56 | N15: 5.8087043 | O15: 0 | P15: 0 | Q15: 182823.18 | R15: 2.3445633 | S15: 167718.59 | T15: 2.1393601 | U15: 0 | V15: 0 | W15: 337251.71 | X15: 3.7009956 | Y15: 339318.51 | Z15: 3.6983405 | AA15: 1533.653 | AB15: 0.096546669 | AC15: 74437.059 | AD15: 4.2487544 | AE15: 75077.878 | AF15: 4.2277123 | AG15: -2.4246254 | AH15: -0.0014109871 | AI15: 5761.7684 | AJ15: 3.7787991 | AK15: 6447.7772 | AL15: 3.6136077
B16: Banco del Bajío | C16: 339861.56 | D16: 2.3848428 | E16: 372552.28 | F16: 2.4362934 | G16: 374884.01 | H16: 2.436204 | I16: 23815.534 | J16: 0.63243461 | K16: 28005.059 | L16: 0.69675778 | M16: 28262.579 | N16: 0.6974263 | O16: 246819.31 | P16: 3.4140361 | Q16: 265190.05 | R16: 3.4008534 | S16: 264080.65 | T16: 3.368521 | U16: 277484.84 | V16: 3.2959323 | W16: 308786.25 | X16: 3.3886161 | Y16: 310533.69 | Z16: 3.3846056 | AA16: 41415.827 | AB16: 2.6072131 | AC16: 44836.97 | AD16: 2.5592262 | AE16: 45523.253 | AF16: 2.5634611 | AG16: 6499.4597 | AH16: 3.7822971 | AI16: 4656.6649 | AJ16: 3.0540279 | AK16: 5367.0088 | AL16: 3.0078992
B17: Banco Azteca | C17: 308305.92 | D17: 2.1634137 | E17: 348431.86 | F17: 2.2785588 | G17: 358130.15 | H17: 2.3273282 | I17: 84134.092 | J17: 2.2342271 | K17: 102744.81 | L17: 2.5562611 | M17: 107881.59 | N17: 2.6621582 | O17: 177632.42 | P17: 2.4570342 | Q17: 193792 | R17: 2.4852297 | S17: 201079.6 | T17: 2.5649015 | U17: 217320.54 | V17: 2.5813078 | W17: 241453.28 | X17: 2.649705 | Y17: 242117.71 | Z17: 2.638918 | AA17: 36500.64 | AB17: 2.2977917 | AC17: 44174.221 | AD17: 2.5213975 | AE17: 44506.63 | AF17: 2.506214 | AG17: 3027.4149 | AH17: 1.7617745 | AI17: 3047.396 | AJ17: 1.9986047 | AK17: 3379.8051 | AL17: 1.8941861
B18: Afirme | C18: 298548.61 | D18: 2.0949457 | E18: 307728.44 | F18: 2.0123801 | G18: 311426.66 | H18: 2.023823 | I18: 173782.67 | J18: 4.6148944 | K18: 173690.31 | L18: 4.3213647 | M18: 177438.47 | N18: 4.3785902 | O18: 64129.659 | P18: 0.8870496 | Q18: 68546.657 | R18: 0.87905687 | S18: 68150.646 | T18: 0.86930597 | U18: 93503.637 | V18: 1.1106252 | W18: 88530.454 | X18: 0.97153197 | Y18: 84558.258 | Z18: 0.92162738 | AA18: 8472.2736 | AB18: 0.53334737 | AC18: 9063.979 | AD18: 0.51735817 | AE18: 9157.2074 | AF18: 0.51565174 | AG18: 304.55061 | AH18: 0.17723025 | AI18: 458.35173 | AJ18: 0.30060547 | AK18: 540.2653 | AL18: 0.30278758
... B59: Pagatodo | C59: 395.43887 | D59: 0.0027748344 | E59: 342.51926 | F59: 0.0022398935 | G59: 353.01674 | H59: 0.0022940984 | I59: 0 | J59: 0 | K59: 0 | L59: 0 | M59: 0 | N59: 0 | O59: 0 | P59: 0 | Q59: 0 | R59: 0 | S59: 0 | T59: 0 | U59: 26.174597 | V59: 0.00031089878 | W59: 21.57985 | X59: 0.00023681698 | Y59: 27.968025 | Z59: 0.00030483241 | AA59: 353.59994 | AB59: 0.022259857 | AC59: 302.34515 | AD59: 0.017257402 | AE59: 311.01369 | AF59: 0.0175135 | AG59: -41.751171 | AH59: -0.024296686 | AI59: -41.171634 | AJ59: -0.027002011 | AK59: -47.503086 | AL59: -0.026622743

Sheet Indicadores
B2: Indicadores financieros
B3: Porcentajes | O3: 1.5853443
C5: ROA (Flujo 12 meses) 3/ | F5: ROE (Flujo 12 meses) 4/
C6: 45474 | D6: 45809 | E6: 45839 | F6: =+C6 -> 45474 | G6: =+D6 -> 45809 | H6: =+E6 -> 45839
B7: Sistema */ | C7: 2.1000991 | D7: 1.9872541 | E7: 1.9686734 | F7: 18.689216 | G7: 17.729083 | H7: 17.511634
B8: BBVA México | C8: 3.0337262 | D8: 2.9519933 | E8: 2.9236001 | F8: 26.634879 | G8: 26.077726 | H8: 25.7504
B9: Santander | C9: 1.518794 | D9: 1.501388 | E9: 1.5078758 | F9: 17.241766 | G9: 18.462192 | H9: 18.619496
B10: Banorte | C10: 2.5334255 | D10: 2.4864977 | E10: 2.4773689 | F10: 29.1176 | G10: 29.283778 | H10: 29.008945
B11: Banamex | C11: 1.6678524 | D11: 1.3417185 | E11: 1.3808035 | F11: 11.584077 | G11: 8.636677 | H11: 8.8335011
B12: HSBC | C12: 1.025533 | D12: 0.71001546 | E12: 0.70730798 | F12: 10.718761 | G12: 7.8180739 | H12: 7.7701024
B13: Scotiabank | C13: 1.3129002 | D13: 1.2275887 | E13: 1.1895722 | F13: 13.605504 | G13: 12.234088 | H13: 11.752307
B14: Inbursa | C14: 4.1965767 | D14: 3.6814906 | E14: 3.6215481 | F14: 15.653389 | G14: 13.236336 | H14: 12.961588
B15: Citi México | C15: 3.079141 | D15: 1.2497226 | E15: 1.2665408 | F15: 3.3864123 | G15: 10.250186 | H15: 10.327018
B16: Banco del Bajío | C16: 3.2971942 | D16: 2.7030851 | E16: 2.6363784 | F16: 27.176524 | G16: 21.810486 | H16: 21.281448
B17: Banco Azteca | C17: 1.3062664 | D17: 1.7919507 | E17: 1.7763661 | F17: 10.93443 | G17: 14.640319 | H17: 14.45623
B18: Afirme | C18: 0.14473994 | D18: 0.23656955 | E18: 0.24656215 | F18: 4.9271382 | G18: 8.1256616 | H18: 8.4441541
... B48: Volkswagen Bank | C48: 7.5986233 | D48: 5.8534165 | E48: 5.9361469 | F48: 10.508124 | G48: 11.821859 | H48: 12.266385
B49: Openbank | C49: n.a. | D49: -28.036862 | E49: -26.245312 | F49: n.a. | G49: -35.430955 | H49: -35.059007
B50: Shinhan | C50: 2.4855955 | D50: 1.9308331 | E50: 1.7688039 | F50: 7.5678009 | G50: 6.6582391 | H50: 6.1589319
B51: Banco Ualá | C51: -25.426725 | D51: -18.264549 | E51: -18.776095 | F51: -128.50115 | G51: -151.57141 | H51: -154.2955
B52: Banco S3 | C52: 5.8080374 | D52: 5.6348784 | E52: 5.5992688 | F52: 13.964316 | G52: 13.186146 | H52: 13.23618
B53: KEB Hana México | C53: 0.87764407 | D53: 0.86597337 | E53: 0.80838528 | F53: 2.546091 | G53: 2.8422865 | H53: 2.6714134
B54: Banco Bineo | C54: -27.397434 | D54: -30.520194 | E54: -30.346281 | F54: -29.910085 | G54: -32.953984 | H54: -32.608705
B55: Dondé Banco | C55: -10.909768 | D55: -5.3406472 | E55: -5.0866478 | F55: -19.174581 | G55: -22.466151 | H55: -22.529182
B56: Credit Suisse | C56: -12.590114 | D56: -5.1695375 | E56: -4.8495628 | F56: -19.991813 | G56: -5.7376741 | H56: -5.2370058
B57: Hey Banco | C57: n.a. | D57: 6.3969044 | E57: 5.6622236 | F57: n.a. | G57: 6.4296263 | H57: 5.6890569
B58: Forjadores | C58: 0.229957 | D58: -1.2013703 | E58: -1.8791918 | F58: 0.32953565 | G58: -1.7240703 | H58: -2.7057418
B59: Pagatodo | C59: -11.665991 | D59: -21.086738 | E59: -21.537666 | F59: -17.967557 | G59: -24.151553 | H59: -24.703061

Sheet CCT
B2: Cartera de crédito total
B3: Millones de pesos y porcentajes
C5: Cartera total (MDP) 1/ | F5: IMOR (%) 5/ | I5: ICOR (%) 6/ | L5: Pérdida esperada (%) 7/
C6: 45474 | D6: 45809 | E6: 45839 | F6: =C6 -> 45474 | G6: =D6 -> 45809 | H6: =E6 -> 45839 | I6: =C6 -> 45474 | J6: =D6 -> 45809 | K6: =E6 -> 45839 | L6: =C6 -> 45474 | M6: =D6 -> 45809 | N6: =E6 -> 45839
B7: Sistema */ | C7: 7229546 | D7: 7797749.9 | E7: 7839661.6 | F7: 2.0071312 | G7: 2.1016541 | H7: 2.1254588 | I7: 157.05016 | J7: 152.26446 | K7: 151.25758 | L7: 3.1522027 | M7: 3.2000723 | N7: 3.2149175
B8: BBVA México | C8: 1814429.7 | D8: 1992989.5 | E8: 2015513.2 | F8: 1.648246 | G8: 1.6626646 | H8: 1.6346425 | I8: 189.79508 | J8: 185.95197 | K8: 189.1028 | L8: 3.1282897 | M8: 3.0917575 | N8: 3.0911547
B9: Santander | C9: 880156.9 | D9: 932042.92 | E9: 934236.43 | F9: 2.1755974 | G9: 2.3068186 | H9: 2.3224121 | I9: 140.4523 | J9: 136.50075 | K9: 134.65926 | L9: 3.0556766 | M9: 3.1488246 | N9: 3.1273428
B10: Banorte | C10: 1061820.3 | D10: 1141382.7 | E10: 1148959.6 | F10: 0.95815611 | G10: 1.0977863 | H10: 1.1035814 | I10: 175.86451 | J10: 152.28908 | K10: 152.29449 | L10: 1.6850566 | M10: 1.6718086 | N10: 1.6806937
B11: Banamex | C11: 612393.6 | D11: 484729.32 | E11: 486300.07 | F11: 2.137527 | G11: 2.7870775 | H11: 2.8293089 | I11: 201.70285 | J11: 192.2565 | K11: 189.17816 | L11: 4.3114528 | M11: 5.3583378 | N11: 5.3524345
B12: HSBC | C12: 498407.66 | D12: 497726.33 | E12: 493741.75 | F12: 2.209556 | G12: 2.5020973 | H12: 2.7387882 | I12: 154.16456 | J12: 150.94051 | K12: 139.95075 | L12: 3.4063523 | M12: 3.7766783 | N12: 3.8329547
B13: Scotiabank | C13: 523954.07 | D13: 521395.83 | E13: 527986.99 | F13: 3.6628194 | G13: 4.0162303 | H13: 4.0517553 | I13: 75.725386 | J13: 69.283656 | K13: 68.652291 | L13: 2.7736841 | M13: 2.7825912 | N13: 2.7816228
B14: Inbursa | C14: 430414.24 | D14: 462573.5 | E14: 461921.58 | F14: 1.5474035 | G14: 1.4633674 | H14: 1.4786003 | I14: 141.91651 | J14: 150.92454 | K14: 149.75024 | L14: 2.1960211 | M14: 2.2085804 | N14: 2.2142075
B15: Citi México | C15: 0 | D15: 182823.18 | E15: 167718.59 | F15: - | G15: 1.2394049 | H15: 1.350366 | I15: - | J15: 185.60963 | K15: 189.67717 | L15: - | M15: 2.3004549 | N15: 2.561336
B16: Banco del Bajío | C16: 246819.31 | D16: 265190.05 | E16: 264080.65 | F16: 1.5594084 | G16: 1.8343591 | H16: 1.8704086 | I16: 145.43874 | J16: 119.09661 | K16: 121.57592 | L16: 2.2679838 | M16: 2.1846596 | N16: 2.2739665
B17: Banco Azteca | C17: 177632.42 | D17: 193792 | E17: 201079.6 | F17: 3.2442473 | G17: 4.065389 | H17: 4.2294726 | I17: 342.15309 | J17: 288.43673 | K17: 274.04411 | L17: 11.100293 | M17: 11.726075 | N17: 11.590621
B18: Afirme | C18: 64129.659 | D18: 68546.657 | E18: 68150.646 | F18: 5.5273862 | G18: 3.9902362 | H18: 3.9543661 | I18: 68.158152 | J18: 85.247519 | K18: 86.624197 | L18: 3.7673643 | M18: 3.4015774 | N18: 3.4254379
B19: Monex | C19: 42410.257 | D19: 55217.342 | E19: 55679.67 | F19: 1.4063107 | G19: 1.4519538 | H19: 1.4838624 | I19: 153.88106 | J19: 130.06922 | K19: 128.40821 | L19: 2.1640458 | M19: 1.8885449 | N19: 1.9054012
B20: Banregio | C20: 167647.78 | D20: 184117.85 | E20: 184818.19 | F20: 1.301245 | G20: 1.5028619 | H20: 1.4945681 | I20: 164.6593 | J20: 140.32033 | K20: 143.5183 | L20: 2.1426209 | M20: 2.1088207 | N20: 2.1449786
B21: J.P. Morgan | C21: 19096.845 | D21: 24623.542 | E21: 25545.122 | F21: 0 | G21: 0 | H21: 0 | I21: - | J21: - | K21: - | L21: 0.71633014 | M21: 0.65361509 | N21: 0.61994842
B22: Invex | C22: 40370.847 | D22: 47571.074 | E22: 49386.651 | F22: 2.1941927 | G22: 2.3495376 | H22: 2.1702776 | I22: 228.72152 | J22: 244.16324 | K22: 257.61508 | L22: 5.0185909 | M22: 5.7367071 | N22: 5.5909625
B23: Bank of America | C23: 32183.869 | D23: 40215.168 | E23: 41861.69 | F23: 0 | G23: 0 | H23: 0 | I23: - | J23: - | K23: - | L23: 0.81279813 | M23: 0.81053787 | N23: 1.0426333
B24: BanCoppel | C24: 60875.435 | D24: 70278.652 | E24: 69846.329 | F24: 8.0218693 | G24: 5.958428 | H24: 5.881127 | I24: 137.87664 | J24: 145.97489 | K24: 149.55988 | L24: 11.060284 | M24: 8.6978086 | N24: 8.7958066
B25: Banca Mifel | C25: 75813.117 | D25: 82455.168 | E25: 83334.566 | F25: 2.4526773 | G25: 2.561652 | H25: 2.6526099 | I25: 86.497934 | J25: 88.758729 | K25: 86.550689 | L25: 2.1215152 | M25: 2.2736897 | N25: 2.2958521
B26: Multiva | C26: 67072.414 | D26: 76473.215 | E26: 80241.469 | F26: 3.3096588 | G26: 2.8116236 | H26: 2.6201476 | I26: 99.368613 | J26: 108.13525 | K26: 112.41907 | L26: 3.2887621 | M26: 3.0403562 | N26: 2.9455456
B27: Banco Base | C27: 11389.211 | D27: 11001.653 | E27: 10522.093 | F27: 1.90157 | G27: 2.875475 | H27: 3.1417019 | I27: 140.72343 | J27: 104.71268 | K27: 104.19206 | L27: 2.6759546 | M27: 3.0109871 | N27: 3.2734038
B28: Barclays | C28: 0 | D28: 0 | E28: 0 | F28: - | G28: - | H28: - | I28: - | J28: - | K28: - | L28: - | M28: - | N28: -
B29: Sabadell | C29: 93792.06 | D29: 97906.152 | E29: 100065.78 | F29: 1.8691659 | G29: 2.3014467 | H29: 2.2519243 | I29: 75.26519 | J29: 65.037883 | K29: 66.052912 | L29: 1.4068313 | M29: 1.4968122 | N29: 1.4874616
B30: Ve por Más | C30: 57184.649 | D30: 59053.05 | E30: 60019.8 | F30: 3.0448065 | G30: 2.9198691 | H30: 2.8738416 | I30: 102.42263 | J30: 105.19546 | K30: 107.71404 | L30: 3.1185709 | M30: 3.0715698 | N30: 3.095531
B31: CIBanco | C31: 13301.435 | D31: 17706.215 | E31: 16743.919 | F31: 3.5038435 | G31: 2.9305622 | H31: 3.3272579 | I31: 102.51799 | J31: 103.63729 | K31: 102.02887 | L31: 3.5920698 | M31: 3.0371553 | N31: 3.3947636
B32: Bansí | C32: 22336.473 | D32: 27225.967 | E32: 29730.699 | F32: 4.473928 | G32: 4.0523093 | H32: 3.6975682 | I32: 153.94531 | J32: 163.16403 | K32: 166.68465 | L32: 6.8874021 | M32: 6.611911 | N32: 6.1632786
B33: Actinver | C33: 26631.983 | D33: 27833.813 | E33: 28375.644 | F33: 3.3676056 | G33: 3.3312494 | H33: 3.3318947 | I33: 111.48461 | J33: 118.54876 | K33: 107.55651 | L33: 3.754362 | M33: 3.9491548 | N33: 3.5836697
B34: Compartamos | C34: 45844.851 | D34: 54933.984 | E34: 58883.972 | F34: 2.9944215 | G34: 3.315018 | H34: 3.1850154 | I34: 250.62136 | J34: 237.5763 | K34: 234.46744 | L34: 7.5046599 | M34: 7.8756971 | N34: 7.467824
B35: BIAfirme | C35: 273.32896 | D35: 245.00795 | E35: 244.16608 | F35: 0 | G35: 0 | H35: 0 | I35: - | J35: - | K35: - | L35: 0.52316263 | M35: 0.44387457 | N35: 0.44172885
B36: Intercam Banco | C36: 20157.505 | D36: 25340.782 | E36: 18997.184 | F36: 2.5172953 | G36: 3.2699457 | H36: 4.8650035 | I36: 217.23129 | J36: 164.63899 | K36: 144.79065 | L36: 5.4683529 | M36: 5.3836055 | N36: 7.0440702
B37: Bancrea | C37: 35240.32 | D37: 42730.05 | E37: 43235.349 | F37: 0.82656864 | G37: 1.0398351 | H37: 1.035172 | I37: 124.16798 | J37: 151.16894 | K37: 149.35787 | L37: 1.0263336 | M37: 1.5719076 | N37: 1.5461108
B38: MUFG Bank | C38: 11647.884 | D38: 7306.8789 | E38: 6866.0949 | F38: 0 | G38: 0 | H38: 0 | I38: - | J38: - | K38: - | L38: 0.5364314 | M38: 0.81356373 | N38: 0.78265206
B39: Consubanco | C39: 22999.082 | D39: 30230.936 | E39: 30750.111 | F39: 1.7633557 | G39: 1.6858286 | H39: 1.6180695 | I39: 210.41225 | J39: 216.28173 | K39: 224.02722 | L39: 3.7103164 | M39: 3.6461391 | N39: 3.6249161
B40: BNP Paribas México | C40: 0 | D40: 0 | E40: 0 | F40: - | G40: - | H40: - | I40: - | J40: - | K40: - | L40: - | M40: - | N40: -
B41: Autofin | C41: 3639.7169 | D41: 9289.4392 | E41: 9513.4427 | F41: 3.1805317 | G41: 3.7459694 | H41: 3.2162558 | I41: 157.9498 | J41: 117.03858 | K41: 131.88122 | L41: 5.0236436 | M41: 4.3842293 | N41: 4.2416374
B42: Bankaool | C42: 7214.4852 | D42: 11775.756 | E42: 12586.946 | F42: 1.4363382 | G42: 0.94051365 | H42: 0.88075599 | I42: 197.18341 | J42: 215.234 | K42: 209.12365 | L42: 2.8322205 | M42: 2.0243052 | N42: 1.8418691
...

Sheet CCE
B2: Cartera de crédito a empresas
B3: Millones de pesos y porcentajes
C5: Cartera total (MDP) 1/ | F5: IMOR (%) 5/ | I5: ICOR (%) 6/ | L5: Pérdida esperada (%) 7/
C6: 45474 | D6: 45809 | E6: 45839 | F6: =C6 -> 45474 | G6: =D6 -> 45809 | H6: =E6 -> 45839 | I6: =C6 -> 45474 | J6: =D6 -> 45809 | K6: =E6 -> 45839 | L6: =C6 -> 45474 | M6: =D6 -> 45809 | N6: =E6 -> 45839
B7: Sistema */ | C7: 3415147.8 | D7: 3704272.8 | E7: 3727749.3 | F7: 1.6869629 | G7: 1.7032783 | H7: 1.7291745 | I7: 98.588435 | J7: 97.355877 | K7: 97.092335 | L7: 1.6631504 | M7: 1.6582415 | N7: 1.6788959
B8: BBVA México | C8: 758333.85 | D8: 829730.83 | E8: 845064.71 | F8: 1.298138 | G8: 1.1445644 | H8: 1.0930512 | I8: 94.680976 | J8: 101.99607 | K8: 107.45246 | L8: 1.2290897 | M8: 1.1674107 | N8: 1.1745104
B9: Santander | C9: 367828.5 | D9: 386570.24 | E9: 387976.99 | F9: 1.3535625 | G9: 1.5088915 | H9: 1.5405653 | I9: 98.845607 | J9: 98.467597 | K9: 97.156531 | L9: 1.337937 | M9: 1.4857692 | N9: 1.4967598
B10: Banorte | C10: 416460.27 | D10: 452770.24 | E10: 454619.9 | F10: 0.94395419 | G10: 1.1629068 | H10: 1.1437797 | I10: 96.632432 | J10: 66.291952 | K10: 68.126721 | L10: 0.9121659 | M10: 0.7709136 | N10: 0.77921957
B11: Banamex | C11: 243153.39 | D11: 132126.95 | E11: 130847.47 | F11: 1.1369857 | G11: 2.8298142 | H11: 2.9437062 | I11: 163.57328 | J11: 100.59623 | K11: 96.591479 | L11: 1.8598048 | M11: 2.8466865 | N11: 2.8433693
B12: HSBC | C12: 215072.55 | D12: 223079.65 | E12: 222562.97 | F12: 2.0672704 | G12: 2.2910929 | H12: 2.8024905 | I12: 90.444959 | J12: 106.09173 | K12: 86.598885 | L12: 1.8697419 | M12: 2.4306601 | N12: 2.4269255
B13: Scotiabank | C13: 199544.45 | D13: 187923.94 | E13: 192263.08 | F13: 3.5503582 | G13: 2.8123065 | H13: 2.8542654 | I13: 86.78343 | J13: 78.052043 | K13: 78.308601 | L13: 3.0811226 | M13: 2.1950627 | N13: 2.2351353
B14: Inbursa | C14: 298404.99 | D14: 320032.28 | E14: 321335.89 | F14: 1.5994125 | G14: 1.5159802 | H14: 1.494835 | I14: 115.05628 | J14: 118.90261 | K14: 120.13973 | L14: 1.8402244 | M14: 1.80254 | N14: 1.7958907
B15: Citi México | C15: 0 | D15: 142814.03 | E15: 137893.37 | F15: - | G15: 0.0071214279 | H15: 0.0065067991 | I15: - | J15: 15729.19 | K15: 17977.824 | L15: - | M15: 1.1201429 | N15: 1.1697809
B16: Banco del Bajío | C16: 207166.71 | D16: 229015.87 | E16: 228199.91 | F16: 1.6684895 | G16: 1.924131 | H16: 1.969894 | I16: 100.61682 | J16: 92.820771 | K16: 95.214421 | L16: 1.678781 | M16: 1.7859933 | N16: 1.8756232
B17: Banco Azteca | C17: 45138.057 | D17: 40345.131 | E17: 44433.97 | F17: 0.95833728 | G17: 3.0459159 | H17: 2.7649932 | I17: 81.159453 | J17: 49.958858 | K17: 56.704017 | L17: 0.7777813 | M17: 1.5217048 | N17: 1.5678622
B18: Afirme | C18: 36536.424 | D18: 39927.423 | E18: 39323.978 | F18: 6.6277771 | G18: 4.490468 | H18: 4.5647443 | I18: 44.469088 | J18: 53.277349 | K18: 54.302093 | L18: 2.947312 | M18: 2.3924023 | N18: 2.4787517
B19: Monex | C19: 32667.158 | D19: 41710.675 | E19: 41614.196 | F19: 1.6761537 | G19: 1.8160797 | H19: 1.8939995 | I19: 134.78391 | J19: 112.70552 | K19: 110.35244 | L19: 2.2591855 | M19: 2.046822 | N19: 2.0900747
B20: Banregio | C20: 134939.08 | D20: 147943.19 | E20: 148361.92 | F20: 1.2124152 | G20: 1.51766 | H20: 1.5097903 | I20: 133.99829 | J20: 110.42067 | K20: 114.66077 | L20: 1.6246156 | M20: 1.6758103 | N20: 1.7311372
B21: J.P. Morgan | C21: 19085.34 | D21: 23770.677 | E21: 24248.486 | F21: 0 | G21: 0 | H21: 0 | I21: - | J21: - | K21: - | L21: 0.70097689 | M21: 0.63402605 | N21: 0.60987204
B22: Invex | C22: 14172.766 | D22: 13834.513 | E22: 14881.706 | F22: 2.4631532 | G22: 1.996656 | H22: 1.8285654 | I22: 80.052622 | J22: 111.74424 | K22: 119.84949 | L22: 1.9718187 | M22: 2.2311481 | N22: 2.1915263
B23: Bank of America | C23: 27684.477 | D23: 27325.407 | E23: 28411.346 | F23: 0 | G23: 0 | H23: 0 | I23: - | J23: - | K23: - | L23: 0.88510385 | M23: 0.84781328 | N23: 1.1874196
B24: BanCoppel | C24: 32202.065 | D24: 41959.665 | E24: 41303.117 | F24: 3.9970273 | G24: 3.791287 | H24: 3.7822899 | I24: 78.692541 | J24: 81.059188 | K24: 86.626422 | L24: 3.1453623 | M24: 3.0731865 | N24: 3.2764624
B25: Banca Mifel | C25: 50746.735 | D25: 58930.895 | E25: 59764.998 | F25: 1.3874607 | G25: 1.2249575 | H25: 1.1732697 | I25: 123.28409 | J25: 145.07861 | K25: 146.55307 | L25: 1.7105182 | M25: 1.7771514 | N25: 1.7194627
B26: Multiva | C26: 32952.945 | D26: 40751.421 | E26: 42771.104 | F26: 5.2346614 | G26: 4.1869802 | H26: 3.8824297 | I26: 86.524648 | J26: 94.25058 | K26: 97.585618 | L26: 4.5292724 | M26: 3.9462532 | N26: 3.788693
B27: Banco Base | C27: 10994.78 | D27: 10694.104 | E27: 10225.457 | F27: 1.9697876 | G27: 2.9581703 | H27: 3.2328412 | I27: 107.53339 | J27: 84.896894 | K27: 85.596186 | L27: 2.1181794 | M27: 2.5113947 | N27: 2.7671888
B28: Barclays | C28: 0 | D28: 0 | E28: 0 | F28: - | G28: - | H28: - | I28: - | J28: - | K28: - | L28: - | M28: - | N28: -
B29: Sabadell | C29: 91103.874 | D29: 95521.632 | E29: 97372.271 | F29: 1.8163116 | G29: 2.3574069 | H29: 2.312779 | I29: 74.144055 | J29: 64.522403 | K29: 65.431454 | L29: 1.3466871 | M29: 1.5210556 | N29: 1.5132849
B30: Ve por Más | C30: 40081.371 | D30: 43602.428 | E30: 43982.27 | F30: 3.930021 | G30: 3.6638171 | H30: 3.670094 | I30: 77.022859 | J30: 81.341647 | K30: 83.36192 | L30: 3.0270145 | M30: 2.9802091 | N30: 3.0594608
