Workbook
Name \a: #REF!
Name \a: #REF!
Name \a: #REF!
Name \a: #REF!
Name \a: #REF!
Name \a: #REF!
Name \a: #REF!
Name \a: #REF!
Name \a: #REF!
Name \a: #REF!
Name \a: #REF!
Name \a: #REF!
Name \a: #REF!
Name \a: #REF!
Name \a: #REF!
Name \a: #REF!
Name \a: #REF!
Name \a: #REF!
Name \a: #REF!
Name \a: #REF!
Name \a: #REF!
Name \a: #REF!
Name \a: #REF!
Name \a: #REF!
Name \a: #REF!
Name \a: #REF!
Name \s: #REF!
Name \s: #REF!
Name \s: #REF!
Name \s: #REF!
Name \s: #REF!
Name \s: #REF!
Name \s: #REF!
Name \s: #REF!
Name \s: #REF!
Name \s: #REF!
Name \s: #REF!
Name \s: #REF!
Name \s: #REF!
Name \s: #REF!
Name \s: #REF!
Name \s: #REF!
Name \s: #REF!
Name \s: #REF!
Name \s: #REF!
Name \s: #REF!
Name \s: #REF!
Name a: #REF!
Name a: #REF!
Name a: #REF!
Name a: #REF!
Name a: #REF!
Name a: #REF!
Name a: #REF!
Name a: #REF!
Name a: #REF!
Name a: #REF!
Name a: #REF!
Name a: #REF!
Name a: #REF!

Sheet Portada
C33: ='Pm2'!G6 -> 45901
C34: =PROPER(TEXT(C33,"Mmmm"))& " de " & PROPER(TEXT(C33,"aaa")) -> Septiembre de 2025

Sheet Nota
B4: La presente información corresponde a la que, en cumplimiento a las Disposiciones aplicables a cada sector, entregan las entidades supervisadas a la CNBV a través de los reportes regulatorios debiéndose asegurar que la misma sea completa, correcta, precisa, integra, confiable y oportuna. Es importante mencionar, como lo indican las propias Disposiciones, que dicha información debe cumplir con las validaciones establecidas en el Sistema Interinstitucional de Transferencia de Información, así como los estándares de calidad que indique la Comisión a través de dicho sistema, además debe existir consistencia entre la información que las entidades incluyan en uno o más reportes regulatorios, aunque se encuentre con un nivel distinto de integración, por lo que puede ser modificada derivado de las revisiones internas que se hagan a la misma. Por lo anterior se informa que la presente publicación se genera con la información con la que se cuenta al momento de su elaboración, se recomienda su uso tomando en cuenta los aspectos anteriormente descritos.
B6: Consideraciones sobre los criterios para integrar los estados financieros del sector de Banca Múltiple a partir de enero de 2022. El 13 de marzo de 2020 se publicó en el Diario Oficial de la Federación la resolución que modificó las Disposiciones de carácter general aplicables a las instituciones de crédito (Disposiciones), la cual incorporó las nuevas normas de información emitidas por el Consejo Mexicano de Normas de Información Financiera A.C., mismas que serían exigibles a partir del 1 de enero de 2021; sin embargo, su entrada en vigor se aplazó hasta el 1 de enero de 2022, mediante la resolución modificatoria publicada en el Diario Oficial de la Federación el 4 de diciembre de 2020. En la resolución modificatoria del 4 de diciembre, se indica que los estados financieros básicos consolidados trimestrales y anuales requeridos a las instituciones de conformidad con las disposiciones señaladas correspondientes al periodo concluido el 31 de diciembre de 2022, no deberán presentarse comparativos con cada trimestre del ejercicio 2021 y por el periodo terminado el 31 de diciembre de 2021. La información del comunicado de prensa de Banca Múltiple se puede consultar en https://www.cnbv.gob.mx/PRENSA/Paginas/Boletines-de-Prensa.aspx Para la información financiera histórica se recomienda utilizar los reportes publicados en el Portafolio de Información. Para consultar las cifras bajo la norma internacional de información financiera 9 “Instrumentos Financieros” (IFRS 9), dirigirse a la sección de IFRS 9 del Portafolio Consultas.
B11: El presente Boletín Estadístico se elaboró por personal de la Comisión Nacional Bancaria y de Valores (CNBV) con la información correspondiente a septiembre de 2025 contenida en los reportes regulatorios que las entidades supervisadas envían a esta Comisión, la cual estuvo disponible a partir del 21 de octubre de 2025.
B13: Las cifras aquí contenidas no se actualizan en el tiempo, por lo que para consultar series históricas se recomienda utilizar los reportes publicados en el Portafolio de Información.
B15: Al cierre de septiembre de 2025, el sector de Banca Múltiple estuvo integrado por 52 instituciones en operación, dos más que el año anterior, considerando el inicio de operaciones de; Openbank México, S.A., Institución de Banca Múltiple, Grupo Financiero Santander México el 19 de noviembre de 2024 y de Hey Banco, S.A. Institución de Banca Múltiple, Banregio Grupo Financiero el 12 de febrero de 2025.
B17: Mediante oficio con fecha del 24 de septiembre de 2024 se aprobó el cambio de denominación de CBM Banco, S.A., Institución de Banca Múltiple, Integrante del Grupo Financiero Citibanamex a Banco Citi México, S.A., Institución de Banca Múltiple, Grupo Financiero Citi México, en el presente Boletin estadístico (Citi México). Mediante oficio con fecha del 24 de septiembre de 2024 se aprobó el cambio de denominación de ABC Capital, S.A., Institución de Banca Múltiple (ABC Capital) a Ualá, S.A., Institución de Banca Múltiple, en el presente Boletín estadístico (Banco Ualá).
B19: El 1 de diciembre de 2024 Citigroup (Citigroup Inc.) concretó la separación del negocio de banca corporativa y privada de los negocios de consumo y banca empresarial. A partir de esa fecha, Citi opera en México a través de dos grupos financieros separados e independientes: Grupo Financiero Banamex y Grupo Financiero Citi México; por lo anterior, Citi gestionará el negocio de banca corporativa y privada (cartera comercial) y Banamex llevará el negocio de consumo y la banca empresarial (cartera comercial, de consumo y a la vivienda).
B21: El 18 de diciembre de 2024 se le notifica a Banco Sabadell, S.A., Institución de Banca Múltiple, que podrá llevar a cabo la fusión con Sabcapital, S.A. de C.V., Sociedad Financiera de Objeto Múltiple, Entidad Regulada, como sociedad fusionada, a partir de enero de 2025.

Sheet Índice
B4: Índice
B5: Presentación
B7: I. Índice de Capitalización y Evaluación de la Calidad de la Información
B8: Artículo 121 Ley de Instituciones de Crédito
B9: Metodología de Evaluación Sistema Financiero
B10: Metodología Evaluación Cartera Comercial
B11: Metodología Evaluación Cartera a la Vivienda
B12: Evaluación de Calidad a la Información
B14: II. Estadísticas de la Banca Múltiple
B15: Principales Rubros del Estado de Situación Financiera y Estado de Resultado Integral
B16: Indicadores Financieros
B17: Cartera de Crédito Total
... B36: III. Estados Financieros

Sheet Presentación
A2: Presentación
A3: La Comisión Nacional Bancaria y de Valores (CNBV) emite el presente documento para cumplir con lo dispuesto por la fracción XXIII del Artículo 4º de la Ley de la Comisión Nacional Bancaria y de Valores. Mediante la difusión de este boletín estadístico se persigue promover la transparencia y autorregulación del sector de Banca Múltiple, así como proveer a los mercados y al público en general información suficiente y confiable, que permita el análisis y seguimiento de estas instituciones.
A4: El boletín estadístico se encuentra dividido en 3 secciones: En primer lugar se informa sobre el nivel del Índice de Capitalización de las instituciones y su correspondiente categoría de Alertas Tempranas. Además, se presenta la tabla de Evaluación de la Calidad y Oportunidad de la Información con el que se califica el envío de los reportes regulatorios que las entidades supervisadas entregan a este organismo.
A5: En segundo lugar se muestra la información estadística relevante y principales indicadores de rentabilidad de cada institución de banca múltiple que proviene o se calcula con sus estados financieros consolidados.
A6: Enseguida se presenta la información reportada por las 52 instituciones de banca múltiple en operación correspondiente a septiembre de 2025, consolidada con la de sus SOFOMER (Sociedades Financieras de Objeto Múltiple, Entidades Reguladas) en el caso de los siguientes bancos: Banamex con Tarjetas Banamex; Santander con Santander Inclusión Financiera; CI Banco con Finanmadrid México; Banco del Bajío con Financiera Bajío; Banregio con Start Banregio; Inbursa con STM Financial, SOFOM Inbursa y CETELEM Inbursa; Afirme con Arrendadora Afirme; Banco Base con Arrendadora Base, Invex con Invex Consumo; Bancrea con Arrendadora Bancrea, así como Ve por Más con Arrendadora Ve por Más.
A7: Se incluyen los indicadores financieros destacados, los saldos de cada tipo de crédito y de la captación de recursos.
A8: Por último, se hace un compendio de los estados financieros que las instituciones de banca múltiple reportaron a esta Comisión, al igual que en las secciones anteriores, se incluye información consolidada de las instituciones de banca múltiple con las SOFOMER de cada banco.

Sheet Portadilla I
A7: I. Índice de Capitalización y Evaluación de la Calidad de la Información.
A8: El objetivo de este apartado es proporcionar al público los indicadores de capitalización de los bancos, con las cifras disponibles en la fecha de elaboración del presente boletín, así como la clasificación de las instituciones de banca múltiple en distintas categorías, de acuerdo con las disposiciones de Alertas Tempranas.
A9: Por otra parte, se presenta la evaluación de la calidad y oportunidad de la información que entregan las instituciones a este Organismo, la cual considera la oportunidad con la que reportan y el número de reenvíos.

Sheet Art_121
B4: REGLAS DE CARÁCTER GENERAL A QUE SE REFIERE EL ARTÍCULO 121 DE LA LEY DE INSTITUCIONES DE CRÉDITO.
B5: Con el fin de mantener informado al público sobre el desempeño de las instituciones que conforman al sector de banca múltiple, la CNBV con fundamento en lo dispuesto en el artículo 121 de la Ley de Instituciones de Crédito, en relación con los artículos 220 y 221 de las Disposiciones de carácter general aplicables a las instituciones de crédito (las Disposiciones), da a conocer la clasificación de las instituciones de banca múltiple en categorías, con base en el índice de capitalización requerido conforme a las disposiciones aplicables a los requerimientos de capitalización, emitidas por esta Comisión en términos del artículo 50 de la Ley de Instituciones de Crédito
B6: CLASIFICACIÓN DE LAS INSTITUCIONES DE BANCA MÚLTIPLE DE ACUERDO CON EL ARTÍCULO 220 DE LAS DISPOSICIONES
B7: INDICADORES DE CAPITALIZACIÓN CIFRAS AL 31 DE AGOSTO DE 20251/
B8: Institución | C8: CCB 2/ % | D8: CCF 3/ % | E8: ICAP 4/ % | F8: Categoría 5/
B9: Actinver | C9: 17.464176 | D9: 17.464176 | E9: 17.464176 | F9: I
B10: Afirme | C10: 11.433743 | D10: 10.412407 | E10: 15.314787 | F10: I
B11: Banamex | C11: 21.082687 | D11: 17.958478 | E11: 21.082687 | F11: I
B12: Banca Mifel | C12: 16.077282 | D12: 16.077282 | E12: 16.190525 | F12: I
B13: Banco Azteca | C13: 13.550355 | D13: 13.550355 | E13: 14.011343 | F13: I
B14: Banco Base | C14: 22.5006 | D14: 22.5006 | E14: 22.5006 | F14: I
B15: Banco Bineo | C15: 235.95282 | D15: 235.95282 | E15: 235.95282 | F15: I
B16: Banco Covalto | C16: 13.189118 | D16: 13.189118 | E16: 13.189118 | F16: I
B17: Banco del Bajío | C17: 15.532215 | D17: 15.532215 | E17: 15.532215 | F17: I
B18: Banco S3 | C18: 175.3321 | D18: 175.3321 | E18: 175.3321 | F18: I
B19: Banco Ualá | C19: 46.199143 | D19: 46.199143 | E19: 46.199143 | F19: I
B20: BanCoppel | C20: 15.806196 | D20: 15.806196 | E20: 15.806196 | F20: I
... B60: Volkswagen Bank | C60: 27.35858 | D60: 27.35858 | E60: 27.35858 | F60: I
B61: Total Banca Múltiple | C61: 18.2732 | D61: 16.9631 | E61: 20.3149
B62: 1/ Dado a conocer a esta Comisión por el Banco de México el 10 de octubre de 2025, con base en la información entregada por las Instituciones, conforme a lo dispuesto por el artículo 2 Bis y 2 Bis 4 de las Disposiciones.
B63: 2/ CCB (Coeficiente de Capital Básico) = (Capital Fundamental + Capital no Fundamental) / Activos Ponderados Sujetos a Riesgo Total.
B64: 3/ CCF (Coeficiente de Capital Fundamental) = Capital Fundamental / Activos Ponderados Sujetos a Riesgo Total.
B65: 4/ ICAP (Índice de Capitalización) = Capital Neto / Activos Ponderados Sujetos a Riesgo Total.
B66: 5/ Categorías de Alertas Tempranas determinadas con base en el artículo 220 de las Disposiciones.

Sheet Ficha Técnica
B11: Evaluación de la Calidad de la Información
B12: Banca Múltiple
B14: Derivado de la mejora continua en los procesos de verificación de la calidad en la información, esta comisión ha modificado los criterios de evaluación de la calidad y los hábitos de envío de los reportes regulatorios que son transmitidos por las Instituciones de Banca Múltiple, por lo cual, se ha optado por generar un indicador único de calidad que refleje el estado actual obtenido para los reportes regulatorios, clasificados en 5 tipos de información distintos:
B20: Clave | C20: Clasificación | E20: Reportes | F20: Descripción
B21: 1 | C21: Situación financiera | E21: 22 | F21: Reportes de las series R01, R04 A, R06, R07, R08, R10, R12 , R13, R14, R32, R34 y R36.
B22: 2 | C22: Cartera Comercial | E22: 11 | F22: Reportes de la serie R04 C.
B23: 3 | C23: Cartera a la Vivienda | E23: 4 | F23: Reportes de la serie R04 H.
B24: 4 | C24: Captación | E24: 1 | F24: Reporte R24 B-2421.
B25: 5 | C25: Operativos | E25: 23 | F25: Reportes de las series R15, R24 B-2422, R24 B-2423, R24 C, R24 D, R24 E, R26, R27, R28, R29 y R35.
B27: Tomando en consideración la anterior clasificación, se generan 2 métricas para el cálculo del indicador único, como a continuación se muestra:
B30: 1. Calidad
B32: Para la medición del porcentaje de calidad obtenido, se identifican las incidencias presentadas en la ventana de evaluación del periodo, estas incidencias tienen ponderadores específicos para cada IBM, los cuáles se calculan a través de la distribución de sus errores presentados de manera histórica y se omiten aquellos reportes que por la naturaleza de su negocio no le son aplicables a cada IBM.
B37: 2. Oportunidad 1/
B39: Para la evaluación de hábitos de envío se consideran 3 conductas que no son adecuadas, siendo estas, los reenvíos, entregas extemporáneas y reportes omisos a la fecha de corte y que se encuentren en la ventana de evaluación. De igual forma se ponderan en la ventana de evaluación en función del comportamiento histórico y se ponderan de diferente forma en función del porcentaje de calidad obtenido.
B43: 2. Calificación final
B45: Tomando en consideración las 2 calificaciones previas, se determina una calificación final, la cual servirá como indicador general de evaluación para las IBM, el cual se calcula multiplicando el porcentaje de calidad obtenido por el porcentaje de oportunidad.
B50: Determinación de semáforos
B52: La determinación de semáforos se realiza con base en los siguientes criterios:
B54: Rojo | D54: Se asigna para instituciones que tienen una calificación final inferior a 90 puntos.
B56: Amarillo | D56: Se asigna para las instituciones que tienen una calificación de 90 o más y menor de 95 puntos.
B58: Verde | D58: Se asigna para las instituciones con 95 puntos o más.
B60: 1/ Debido a las intermitencias en el aplicativo SITI WEB, que han ocasionado retrasos involuntarios en la recepción de los Reportes Regulatorios transmitidos a la CNBV, la calificación no penaliza los hábitos de envío desde diciembre de 2023 hasta la fecha.

Sheet Evaluación Calidad
B6: Evaluación de la Calidad de la Información
B7: Banca Múltiple
B8: septiembre 2025
J9: Fecha de corte: 21 de octubre de 2025
B10: RANKING | C10: INSTITUCIÓN | G10: CALIFICACIÓN | J10: CALIDAD | K10: OPORTUNIDAD
B11: 1 | C11: 040126 | D11: Credit Suisse | G11: 100 | H11: 100 | J11: 100 | K11: 100
B12: 1 | C12: 040139 | D12: BIAfirme | G12: 100 | H12: 100 | J12: 100 | K12: 100
B13: 1 | C13: 040162 | D13: KEB Hana México | G13: 100 | H13: 100 | J13: 100 | K13: 100
B14: 1 | C14: 040165 | D14: Banco Bineo | G14: 100 | H14: 100 | J14: 100 | K14: 100
B15: 1 | C15: 040167 | D15: Hey Banco | G15: 100 | H15: 100 | J15: 100 | K15: 100
B16: 1 | C16: 040169 | D16: Openbank | G16: 100 | H16: 100 | J16: 100 | K16: 100
B17: 7 | C17: 040002 | D17: Banamex | G17: 99.93 | H17: 99.93 | J17: 99.93 | K17: 100
B18: 8 | C18: 040151 | D18: Dondé Banco | G18: 99.62 | H18: 99.62 | J18: 99.62 | K18: 100
B19: 9 | C19: 040129 | D19: Barclays | G19: 99.56 | H19: 99.56 | J19: 99.56 | K19: 100
B20: 10 | C20: 040149 | D20: Forjadores | G20: 99.32 | H20: 99.32 | J20: 99.32 | K20: 100
B21: 11 | C21: 040147 | D21: Bankaool | G21: 99.23 | H21: 99.23 | J21: 99.23 | K21: 100
B22: 12 | C22: 040130 | D22: Compartamos | G22: 98.97 | H22: 98.97 | J22: 98.97 | K22: 100
... B61: 51 | C61: 040136 | D61: Intercam Banco | G61: 76.38 | H61: 76.38 | J61: 76.38 | K61: 100
B101: =_xlfn.XLOOKUP(C101,[1]Calificación!D:D,[1]Calificación!A:A,"",0,1) | C101: =IF([1]Calificación!D89=0,"",[1]Calificación!D89) | D101: =IFERROR(VLOOKUP(C101,[1]Calificación!$D$1:$X$52,2,0),"") | G101: =IFERROR(VLOOKUP(C101,[1]Calificación!$D$1:$X$52,5,0),"") | H101: =IFERROR(VLOOKUP(C101,[1]Calificación!$D$1:$X$52,6,0),"") | J101: =IFERROR(VLOOKUP(C101,[1]Calificación!$D$1:$X$52,3,0),"") | K101: =IFERROR(VLOOKUP(C101,[1]Calificación!$D$1:$X$52,4,0),"")
B102: =_xlfn.XLOOKUP(C102,[1]Calificación!D:D,[1]Calificación!A:A,"",0,1) | C102: =IF([1]Calificación!D90=0,"",[1]Calificación!D90) | D102: =IFERROR(VLOOKUP(C102,[1]Calificación!$D$1:$X$52,2,0),"") | G102: =IFERROR(VLOOKUP(C102,[1]Calificación!$D$1:$X$52,5,0),"") | H102: =IFERROR(VLOOKUP(C102,[1]Calificación!$D$1:$X$52,6,0),"") | J102: =IFERROR(VLOOKUP(C102,[1]Calificación!$D$1:$X$52,3,0),"") | K102: =IFERROR(VLOOKUP(C102,[1]Calificación!$D$1:$X$52,4,0),"")
B103: =_xlfn.XLOOKUP(C103,[1]Calificación!D:D,[1]Calificación!A:A,"",0,1) | C103: =IF([1]Calificación!D91=0,"",[1]Calificación!D91) | D103: =IFERROR(VLOOKUP(C103,[1]Calificación!$D$1:$X$52,2,0),"") | G103: =IFERROR(VLOOKUP(C103,[1]Calificación!$D$1:$X$52,5,0),"") | H103: =IFERROR(VLOOKUP(C103,[1]Calificación!$D$1:$X$52,6,0),"") | J103: =IFERROR(VLOOKUP(C103,[1]Calificación!$D$1:$X$52,3,0),"") | K103: =IFERROR(VLOOKUP(C103,[1]Calificación!$D$1:$X$52,4,0),"")
B104: =_xlfn.XLOOKUP(C104,[1]Calificación!D:D,[1]Calificación!A:A,"",0,1) | C104: =IF([1]Calificación!D92=0,"",[1]Calificación!D92) | D104: =IFERROR(VLOOKUP(C104,[1]Calificación!$D$1:$X$52,2,0),"") | G104: =IFERROR(VLOOKUP(C104,[1]Calificación!$D$1:$X$52,5,0),"") | H104: =IFERROR(VLOOKUP(C104,[1]Calificación!$D$1:$X$52,6,0),"") | J104: =IFERROR(VLOOKUP(C104,[1]Calificación!$D$1:$X$52,3,0),"") | K104: =IFERROR(VLOOKUP(C104,[1]Calificación!$D$1:$X$52,4,0),"")
B105: =_xlfn.XLOOKUP(C105,[1]Calificación!D:D,[1]Calificación!A:A,"",0,1) | C105: =IF([1]Calificación!D93=0,"",[1]Calificación!D93) | D105: =IFERROR(VLOOKUP(C105,[1]Calificación!$D$1:$X$52,2,0),"") | G105: =IFERROR(VLOOKUP(C105,[1]Calificación!$D$1:$X$52,5,0),"") | H105: =IFERROR(VLOOKUP(C105,[1]Calificación!$D$1:$X$52,6,0),"") | J105: =IFERROR(VLOOKUP(C105,[1]Calificación!$D$1:$X$52,3,0),"") | K105: =IFERROR(VLOOKUP(C105,[1]Calificación!$D$1:$X$52,4,0),"")
B106: =_xlfn.XLOOKUP(C106,[1]Calificación!D:D,[1]Calificación!A:A,"",0,1) | C106: =IF([1]Calificación!D94=0,"",[1]Calificación!D94) | D106: =IFERROR(VLOOKUP(C106,[1]Calificación!$D$1:$X$52,2,0),"") | G106: =IFERROR(VLOOKUP(C106,[1]Calificación!$D$1:$X$52,5,0),"") | H106: =IFERROR(VLOOKUP(C106,[1]Calificación!$D$1:$X$52,6,0),"") | J106: =IFERROR(VLOOKUP(C106,[1]Calificación!$D$1:$X$52,3,0),"") | K106: =IFERROR(VLOOKUP(C106,[1]Calificación!$D$1:$X$52,4,0),"")
B107: =_xlfn.XLOOKUP(C107,[1]Calificación!D:D,[1]Calificación!A:A,"",0,1) | C107: =IF([1]Calificación!D95=0,"",[1]Calificación!D95) | D107: =IFERROR(VLOOKUP(C107,[1]Calificación!$D$1:$X$52,2,0),"") | G107: =IFERROR(VLOOKUP(C107,[1]Calificación!$D$1:$X$52,5,0),"") | H107: =IFERROR(VLOOKUP(C107,[1]Calificación!$D$1:$X$52,6,0),"") | J107: =IFERROR(VLOOKUP(C107,[1]Calificación!$D$1:$X$52,3,0),"") | K107: =IFERROR(VLOOKUP(C107,[1]Calificación!$D$1:$X$52,4,0),"")
B108: =_xlfn.XLOOKUP(C108,[1]Calificación!D:D,[1]Calificación!A:A,"",0,1) | C108: =IF([1]Calificación!D96=0,"",[1]Calificación!D96) | D108: =IFERROR(VLOOKUP(C108,[1]Calificación!$D$1:$X$52,2,0),"") | G108: =IFERROR(VLOOKUP(C108,[1]Calificación!$D$1:$X$52,5,0),"") | H108: =IFERROR(VLOOKUP(C108,[1]Calificación!$D$1:$X$52,6,0),"") | J108: =IFERROR(VLOOKUP(C108,[1]Calificación!$D$1:$X$52,3,0),"") | K108: =IFERROR(VLOOKUP(C108,[1]Calificación!$D$1:$X$52,4,0),"")
B109: =_xlfn.XLOOKUP(C109,[1]Calificación!D:D,[1]Calificación!A:A,"",0,1) | C109: =IF([1]Calificación!D97=0,"",[1]Calificación!D97) | D109: =IFERROR(VLOOKUP(C109,[1]Calificación!$D$1:$X$52,2,0),"") | G109: =IFERROR(VLOOKUP(C109,[1]Calificación!$D$1:$X$52,5,0),"") | H109: =IFERROR(VLOOKUP(C109,[1]Calificación!$D$1:$X$52,6,0),"") | J109: =IFERROR(VLOOKUP(C109,[1]Calificación!$D$1:$X$52,3,0),"") | K109: =IFERROR(VLOOKUP(C109,[1]Calificación!$D$1:$X$52,4,0),"")
B110: =_xlfn.XLOOKUP(C110,[1]Calificación!D:D,[1]Calificación!A:A,"",0,1) | C110: =IF([1]Calificación!D98=0,"",[1]Calificación!D98) | D110: =IFERROR(VLOOKUP(C110,[1]Calificación!$D$1:$X$52,2,0),"") | G110: =IFERROR(VLOOKUP(C110,[1]Calificación!$D$1:$X$52,5,0),"") | H110: =IFERROR(VLOOKUP(C110,[1]Calificación!$D$1:$X$52,6,0),"") | J110: =IFERROR(VLOOKUP(C110,[1]Calificación!$D$1:$X$52,3,0),"") | K110: =IFERROR(VLOOKUP(C110,[1]Calificación!$D$1:$X$52,4,0),"")
B111: =_xlfn.XLOOKUP(C111,[1]Calificación!D:D,[1]Calificación!A:A,"",0,1) | C111: =IF([1]Calificación!D99=0,"",[1]Calificación!D99) | D111: =IFERROR(VLOOKUP(C111,[1]Calificación!$D$1:$X$52,2,0),"") | G111: =IFERROR(VLOOKUP(C111,[1]Calificación!$D$1:$X$52,5,0),"") | H111: =IFERROR(VLOOKUP(C111,[1]Calificación!$D$1:$X$52,6,0),"") | J111: =IFERROR(VLOOKUP(C111,[1]Calificación!$D$1:$X$52,3,0),"") | K111: =IFERROR(VLOOKUP(C111,[1]Calificación!$D$1:$X$52,4,0),"")
B112: =_xlfn.XLOOKUP(C112,[1]Calificación!D:D,[1]Calificación!A:A,"",0,1) | C112: =IF([1]Calificación!D100=0,"",[1]Calificación!D100) | D112: =IFERROR(VLOOKUP(C112,[1]Calificación!$D$1:$X$52,2,0),"") | G112: =IFERROR(VLOOKUP(C112,[1]Calificación!$D$1:$X$52,5,0),"") | H112: =IFERROR(VLOOKUP(C112,[1]Calificación!$D$1:$X$52,6,0),"") | J112: =IFERROR(VLOOKUP(C112,[1]Calificación!$D$1:$X$52,3,0),"") | K112: =IFERROR(VLOOKUP(C112,[1]Calificación!$D$1:$X$52,4,0),"")
... B131: =_xlfn.XLOOKUP(C131,[1]Calificación!D:D,[1]Calificación!A:A,"",0,1) | C131: =IF([1]Calificación!D119=0,"",[1]Calificación!D119) | D131: =IFERROR(VLOOKUP(C131,[1]Calificación!$D$1:$X$52,2,0),"") | G131: =IFERROR(VLOOKUP(C131,[1]Calificación!$D$1:$X$52,5,0),"") | H131: =IFERROR(VLOOKUP(C131,[1]Calificación!$D$1:$X$52,6,0),"") | J131: =IFERROR(VLOOKUP(C131,[1]Calificación!$D$1:$X$52,3,0),"") | K131: =IFERROR(VLOOKUP(C131,[1]Calificación!$D$1:$X$52,4,0),"")

Sheet Evaluación Calidad Grupos 
B7: Evaluación de la Calidad de la Información
B8: Banca Múltiple
B9: septiembre 2025
K10: Fecha de corte: 21 de octubre de 2025
B11: RANKING | C11: INSTITUCIÓN | G11: CALIFICACIÓN | K11: CALIDAD | L11: OPORTUNIDAD
B12: G7
B13: 1 | C13: 040002 | D13: Banamex | G13: 99.93 | H13: 99.93 | K13: 99.93 | L13: 100 | O13: G-7
B14: 2 | C14: 040072 | D14: Banorte | G14: 97.93 | H14: 97.93 | K14: 97.93 | L14: 100 | O14: G-7
B15: 3 | C15: 040044 | D15: Scotiabank | G15: 96.67 | H15: 96.67 | K15: 96.67 | L15: 100 | O15: G-7
B16: 4 | C16: 040021 | D16: HSBC | G16: 94.42 | H16: 94.42 | K16: 94.42 | L16: 100 | O16: G-7
B17: 5 | C17: 040012 | D17: BBVA México | G17: 91.84 | H17: 91.84 | K17: 91.84 | L17: 100 | O17: G-7
B18: 6 | C18: 040036 | D18: Inbursa | G18: 90.76 | H18: 90.76 | K18: 90.76 | L18: 100 | O18: G-7
B19: 7 | C19: 040014 | D19: Santander | G19: 85.83 | H19: 85.83 | K19: 85.83 | L19: 100 | O19: G-7
B21: BANCOS CAMBIARIOS
B22: 1 | C22: 040112 | D22: Monex | G22: 97.42 | H22: 97.42 | K22: 97.42 | L22: 100 | O22: Bancos Cambiarios
B23: 2 | C23: 040145 | D23: Banco Base | G23: 90.56 | H23: 90.56 | K23: 90.56 | L23: 100 | O23: Bancos Cambiarios
B24: 3 | C24: 040136 | D24: Intercam Banco | G24: 76.38 | H24: 76.38 | K24: 76.38 | L24: 100 | O24: Bancos Cambiarios
B26: BANCA DE INVERSIÓN Y OTROS SERVICIOS
B27: 1 | C27: 040126 | D27: Credit Suisse | G27: 100 | H27: 100 | K27: 100 | L27: 100 | O27: Banca de Inversión y Otros Servicios
B28: 1 | C28: 040139 | D28: BIAfirme | G28: 100 | H28: 100 | K28: 100 | L28: 100 | O28: Banca de Inversión y Otros Servicios
B29: 3 | C29: 040129 | D29: Barclays | G29: 99.56 | H29: 99.56 | K29: 99.56 | L29: 100 | O29: Banca de Inversión y Otros Servicios
B30: 4 | C30: 040106 | D30: Bank of America | G30: 98.04 | H30: 98.04 | K30: 98.04 | L30: 100 | O30: Banca de Inversión y Otros Servicios
B31: 5 | C31: 040164 | D31: BNP Paribas México | G31: 97.99 | H31: 97.99 | K31: 97.99 | L31: 100 | O31: Banca de Inversión y Otros Servicios
B32: 6 | C32: 040148 | D32: Pagatodo | G32: 97.96 | H32: 97.96 | K32: 97.96 | L32: 100 | O32: Banca de Inversión y Otros Servicios
B33: 7 | C33: 040160 | D33: Banco S3 | G33: 97.07 | H33: 97.07 | K33: 97.07 | L33: 100 | O33: Banca de Inversión y Otros Servicios
B34: 8 | C34: 040124 | D34: Citi México (Antes CBM Banco) | G34: 95.72 | H34: 95.72 | K34: 95.72 | L34: 100 | O34: Banca de Inversión y Otros Servicios
B35: 9 | C35: 040110 | D35: J.P. Morgan | G35: 95.45 | H35: 95.45 | K35: 95.45 | L35: 100 | O35: Banca de Inversión y Otros Servicios
B36: 10 | C36: 040108 | D36: MUFG Bank | G36: 94.42 | H36: 94.42 | K36: 94.42 | L36: 100 | O36: Banca de Inversión y Otros Servicios
B37: 11 | C37: 040062 | D37: Afirme | G37: 93.36 | H37: 93.36 | K37: 93.36 | L37: 100 | O37: Banca de Inversión y Otros Servicios
B38: 12 | C38: 040059 | D38: Invex | G38: 87.47 | H38: 87.47 | K38: 87.47 | L38: 100 | O38: Banca de Inversión y Otros Servicios
B40: COMERCIAL MEDIANO
B41: 1 | C41: 040030 | D41: Banco del Bajío | G41: 98.87 | H41: 98.87 | K41: 98.87 | L41: 100 | O41: Comercial Mediano
B42: 2 | C42: 040113 | D42: Ve por Más | G42: 98.7 | H42: 98.7 | K42: 98.7 | L42: 100 | O42: Comercial Mediano
B43: 3 | C43: 040156 | D43: Sabadell | G43: 97.89 | H43: 97.89 | K43: 97.89 | L43: 100 | O43: Comercial Mediano
B44: 4 | C44: 040058 | D44: Banregio | G44: 97.87 | H44: 97.87 | K44: 97.87 | L44: 100 | O44: Comercial Mediano
B45: 5 | C45: 040042 | D45: Banca Mifel | G45: 95.12 | H45: 95.12 | K45: 95.12 | L45: 100 | O45: Comercial Mediano
B46: 6 | C46: 040132 | D46: Multiva | G46: 94.12 | H46: 94.12 | K46: 94.12 | L46: 100 | O46: Comercial Mediano
B48: COMERCIAL PEQUEÑO
B49: 1 | C49: 040162 | D49: KEB Hana México | G49: 100 | H49: 100 | K49: 100 | L49: 100 | O49: Comercial pequeño
B50: 2 | C50: 040151 | D50: Dondé Banco | G50: 99.62 | H50: 99.62 | K50: 99.62 | L50: 100 | O50: Comercial pequeño
...

Sheet Evaluación Calidad Detallada
B3: Evaluación de la Calidad de la Información
B4: Banca Múltiple
B5: septiembre 2025
M6: Fecha de corte: 21 de octubre de 2025
B8: RANKING | C8: INSTITUCIÓN | G8: SITUACIÓN FINANCIERA | J8: CARTERA COMERCIAL | M8: CARTERA A LA VIVIENDA | P8: PRODUCTOS DE CAPTACIÓN | S8: OPERATIVOS
G9: CALIDAD | H9: OPORTUNIDAD | J9: CALIDAD | K9: OPORTUNIDAD | M9: CALIDAD | N9: OPORTUNIDAD | P9: CALIDAD | Q9: OPORTUNIDAD | S9: CALIDAD | T9: OPORTUNIDAD
B10: 1 | C10: 040126 | D10: Credit Suisse | G10: 100 | H10: 100 | J10: n.a | K10: 100 | M10: n.a | N10: 100 | P10: 100 | Q10: 100 | S10: 100 | T10: 100
B11: 1 | C11: 040139 | D11: BIAfirme | G11: 100 | H11: 100 | J11: 100 | K11: 100 | M11: n.a | N11: 100 | P11: 100 | Q11: 100 | S11: 100 | T11: 100
B12: 1 | C12: 040162 | D12: KEB Hana México | G12: 100 | H12: 100 | J12: 100 | K12: 100 | M12: n.a | N12: 100 | P12: 100 | Q12: 100 | S12: 100 | T12: 100
B13: 1 | C13: 040165 | D13: Banco Bineo | G13: 100 | H13: 100 | J13: n.a | K13: 100 | M13: n.a | N13: 100 | P13: 100 | Q13: 100 | S13: 100 | T13: 100
B14: 1 | C14: 040167 | D14: Hey Banco | G14: 100 | H14: 100 | J14: n.a | K14: 100 | M14: n.a | N14: 100 | P14: 100 | Q14: 100 | S14: 100 | T14: 100
B15: 1 | C15: 040169 | D15: Openbank | G15: 100 | H15: 100 | J15: n.a | K15: 100 | M15: n.a | N15: 100 | P15: 100 | Q15: 100 | S15: 100 | T15: 100
B16: 7 | C16: 040002 | D16: Banamex | G16: 100 | H16: 100 | J16: 99.77 | K16: 100 | M16: 100 | N16: 100 | P16: 100 | Q16: 100 | S16: 100 | T16: 100
B17: 8 | C17: 040151 | D17: Dondé Banco | G17: 100 | H17: 100 | J17: 99.54 | K17: 100 | M17: n.a | N17: 100 | P17: 94.87 | Q17: 100 | S17: 100 | T17: 100
B18: 9 | C18: 040129 | D18: Barclays | G18: 99.1 | H18: 100 | J18: n.a | K18: 100 | M18: n.a | N18: 100 | P18: 100 | Q18: 100 | S18: 100 | T18: 100
B19: 10 | C19: 040149 | D19: Forjadores | G19: 100 | H19: 100 | J19: 98.38 | K19: 100 | M19: n.a | N19: 100 | P19: 100 | Q19: 100 | S19: 100 | T19: 100
B20: 11 | C20: 040147 | D20: Bankaool | G20: 99.47 | H20: 100 | J20: 98.85 | K20: 100 | M20: n.a | N20: 100 | P20: 100 | Q20: 100 | S20: 99.49 | T20: 100
B21: 12 | C21: 040130 | D21: Compartamos | G21: 99.01 | H21: 100 | J21: 99.76 | K21: 100 | M21: n.a | N21: 100 | P21: 84.62 | Q21: 100 | S21: 100 | T21: 100
B22: 13 | C22: 040030 | D22: Banco del Bajío | G22: 100 | H22: 100 | J22: 96.39 | K22: 100 | M22: 99.76 | N22: 100 | P22: 100 | Q22: 100 | S22: 100 | T22: 100
B23: 14 | C23: 040141 | D23: Volkswagen Bank | G23: 99.49 | H23: 100 | J23: n.a | K23: 100 | M23: n.a | N23: 100 | P23: 100 | Q23: 100 | S23: 100 | T23: 100
B24: 15 | C24: 040113 | D24: Ve por Más | G24: 100 | H24: 100 | J24: 95.74 | K24: 100 | M24: 100 | N24: 100 | P24: 100 | Q24: 100 | S24: 99.49 | T24: 100
B25: 16 | C25: 040159 | D25: Bank of China | G25: 99.72 | H25: 100 | J25: 97.1 | K25: 100 | M25: n.a | N25: 100 | P25: 92.31 | Q25: 100 | S25: 100 | T25: 100
B26: 17 | C26: 040060 | D26: Bansí | G26: 100 | H26: 100 | J26: 95.93 | K26: 100 | M26: 100 | N26: 100 | P26: 100 | Q26: 100 | S26: 95.38 | T26: 100
B27: 18 | C27: 040106 | D27: Bank of America | G27: 98.87 | H27: 100 | J27: 98.6 | K27: 100 | M27: n.a | N27: 100 | P27: 97.44 | Q27: 100 | S27: 95.38 | T27: 100
B28: 19 | C28: 040164 | D28: BNP Paribas México | G28: 96.1 | H28: 100 | J28: n.a | K28: 100 | M28: n.a | N28: 100 | P28: n.a | Q28: 100 | S28: 100 | T28: 100
B29: 20 | C29: 040148 | D29: Pagatodo | G29: 100 | H29: 100 | J29: n.a | K29: 100 | M29: n.a | N29: 100 | P29: 76.92 | Q29: 100 | S29: 100 | T29: 100
B30: 21 | C30: 040072 | D30: Banorte | G30: 100 | H30: 100 | J30: 96.48 | K30: 100 | M30: 96.42 | N30: 100 | P30: 100 | Q30: 100 | S30: 100 | T30: 100
B31: 22 | C31: 040156 | D31: Sabadell | G31: 100 | H31: 100 | J31: 93.13 | K31: 100 | M31: 100 | N31: 100 | P31: 100 | Q31: 100 | S31: 100 | T31: 100
B32: 23 | C32: 040058 | D32: Banregio | G32: 100 | H32: 100 | J32: 98.49 | K32: 100 | M32: 94.11 | N32: 100 | P32: 100 | Q32: 100 | S32: 100 | T32: 100
B33: 24 | C33: 040155 | D33: ICBC | G33: 97.8 | H33: 100 | J33: 96.89 | K33: 100 | M33: n.a | N33: 100 | P33: 94.87 | Q33: 100 | S33: 100 | T33: 100
B34: 25 | C34: 040157 | D34: Shinhan | G34: 100 | H34: 100 | J34: 94.59 | K34: 100 | M34: n.a | N34: 100 | P34: 100 | Q34: 100 | S34: 100 | T34: 100
B35: 26 | C35: 040112 | D35: Monex | G35: 100 | H35: 100 | J35: 91.25 | K35: 100 | M35: 100 | N35: 100 | P35: 100 | Q35: 100 | S35: 100 | T35: 100
B36: 27 | C36: 040133 | D36: Actinver | G36: 100 | H36: 100 | J36: 93.44 | K36: 100 | M36: n.a | N36: 100 | P36: 100 | Q36: 100 | S36: 100 | T36: 100
B37: 28 | C37: 040160 | D37: Banco S3 | G37: 97.28 | H37: 100 | J37: 97.85 | K37: 100 | M37: n.a | N37: 100 | P37: 100 | Q37: 100 | S37: 94.36 | T37: 100
B38: 29 | C38: 040154 | D38: Covalto | G38: 98.9 | H38: 100 | J38: 93.87 | K38: 100 | M38: n.a | N38: 100 | P38: 100 | Q38: 100 | S38: 100 | T38: 100
B39: 30 | C39: 040044 | D39: Scotiabank | G39: 100 | H39: 100 | J39: 97.93 | K39: 100 | M39: 90.81 | N39: 100 | P39: 100 | Q39: 100 | S39: 100 | T39: 100
B40: 31 | C40: 040137 | D40: Bancoppel | G40: 96.4 | H40: 100 | J40: 94.39 | K40: 100 | M40: 99.05 | N40: 100 | P40: 100 | Q40: 100 | S40: 94.87 | T40: 100
B41: 32 | C41: 040158 | D41: Mizuho Bank | G41: 98.9 | H41: 100 | J41: 92.09 | K41: 100 | M41: n.a | N41: 100 | P41: 100 | Q41: 100 | S41: 100 | T41: 100
B42: 33 | C42: 040127 | D42: Banco Azteca | G42: 98.94 | H42: 100 | J42: 94.67 | K42: 100 | M42: 92.71 | N42: 100 | P42: 100 | Q42: 100 | S42: 99.49 | T42: 100
B43: 34 | C43: 040124 | D43: Citi México (Antes CBM Banco) | G43: 100 | H43: 100 | J43: 96.15 | K43: 100 | M43: n.a | N43: 100 | P43: 38.46 | Q43: 100 | S43: 97.95 | T43: 100
...

Sheet Portadilla II
B2: II. Estadísticas de la Banca Múltiple
B3: El objetivo de este apartado es proporcionar al público indicadores estadísticos que reflejen adecuadamente la evolución de la condición financiera de la Banca Múltiple, por lo que en esta sección, se presenta la información reportada por las 52 instituciones de banca múltiple en operación correspondiente a septiembre de 2025, consolidada con la de sus SOFOMER en el caso de las siguientes instituciones: Banamex con Tarjetas Banamex; Santander con Santander Inclusión Financiera; CI Banco con Finanmadrid México; Banco del Bajío con Financiera Bajío; Banregio con Start Banregio; Inbursa con STM Financial, SOFOM Inbursa y CETELEM Inbursa; Afirme con Arrendadora Afirme; Banco Base con Arrendadora Base, Invex con Invex Consumo; Bancrea con Arrendadora Bancrea, así como Ve por Más con Arrendadora Ve por Más.
B5: Notas:
B7: 1/ Para la cartera total se considera la información de cartera de los bancos junto con la cartera de sus respectivas Sociedades Financieras de Objeto Múltiple Reguladas a las que consolidan. Hasta diciembre 2021: Cartera total = Cartera vigente + cartera vencida. A partir de enero 2022: Cartera total = Cartera de crédito con riesgo de crédito en etapa 1 + 2 + 3 + cartera de crédito valuada a valor razonable.
B9: 2/ Respecto al resultado neto se muestran saldos acumulados al cierre de mes.
B10: 3/ ROA = Resultado neto (flujo 12 meses) / Activos totales, promedio 12 meses.
B11: 4/ ROE = Resultado neto (flujo 12 meses) / Capital contable, promedio 12 meses.
B12: 5/ Hasta diciembre 2021: IMOR = Índice de Morosidad = cartera vencida / (Cartera vigente + cartera vencida). A partir de enero 2022: IMOR = Índice de Morosidad = cartera de crédito con riesgo de crédito en etapa 3 / (Cartera de crédito con riesgo de crédito en etapa 1 + 2 + 3).
B13: 6/ Hasta diciembre 2021: ICOR = Índice de cobertura = Estimaciones preventivas para riesgos crediticios del balance general / cartera de crédito vencida. A partir de enero 2022: ICOR = Índice de cobertura = Estimaciones preventivas para riesgos crediticios del estado de situación financiera / cartera de crédito con riesgo de crédito en etapa 3.
B14: 7/ Hasta diciembre 2021: Estimaciones preventivas para riesgo crediticio del balance general / (Cartera vigente + cartera vencida). A partir de enero 2022: Estimaciones preventivas para riesgo crediticio del estado de situación financiera / (Cartera de crédito con riesgo de crédito en etapa 1 + 2 + 3).
B16: */ En todos los casos se presentan las instituciones en orden descendente por tamaño de activo total en el mes de análisis más reciente.
B18: El símbolo ( - ) indica que la cifra es cero. Las cifras en cero indican una cantidad cercana a cero.
... B21: n.d.: No disponible

Sheet Pm2
B3: Principales rubros del estado de situación financiera y estado de resultado integral
B4: Millones de pesos y porcentajes
C5: Activo total | I5: Inversiones en instrumentos financieros | O5: Cartera total1/ | U5: Captación total | AA5: Capital contable | AG5: Resultado neto 2/
C6: 45536 | E6: 45870 | G6: 45901 | I6: =+$C$6 -> 45536 | K6: =+$E$6 -> 45870 | M6: =+$G$6 -> 45901 | O6: =+$C$6 -> 45536 | Q6: =+$E$6 -> 45870 | S6: =+$G$6 -> 45901 | U6: =+$C$6 -> 45536 | W6: =+$E$6 -> 45870 | Y6: =+$G$6 -> 45901 | AA6: =+$C$6 -> 45536 | AC6: =+$E$6 -> 45870 | AE6: =+$G$6 -> 45901 | AG6: =+$C$6 -> 45536 | AI6: =+$E$6 -> 45870 | AK6: =+$G$6 -> 45901
B7: Sistema */ | C7: 14248896 | D7: 100 | E7: 15431060 | F7: 100 | G7: 15362544 | H7: 100 | I7: 3679985.9 | J7: 100 | K7: 4023367.5 | L7: 100 | M7: 3991475.6 | N7: 100 | O7: 7341346.6 | P7: 100 | Q7: 7858406 | R7: 100 | S7: 7863444.3 | T7: 100 | U7: 8520586.9 | V7: 100 | W7: 9233014.2 | X7: 100 | Y7: 9133939.5 | Z7: 100 | AA7: 1637105 | AB7: 100 | AC7: 1804585.8 | AD7: 100 | AE7: 1799422.5 | AF7: 100 | AG7: 222612.65 | AH7: 100 | AI7: 203173.6 | AJ7: 100 | AK7: 226075.46 | AL7: 100
B8: BBVA México | C8: 3112767.3 | D8: 21.845674 | E8: 3334146.9 | F8: 21.606726 | G8: 3371171.8 | H8: 21.944099 | I8: 659425.83 | J8: 17.919249 | K8: 563805.88 | L8: 14.013283 | M8: 578436.15 | N8: 14.491787 | O8: 1839030.8 | P8: 25.05032 | Q8: 2012068.9 | R8: 25.604033 | S8: 2016789.4 | T8: 25.647659 | U8: 1887722.9 | V8: 22.154846 | W8: 2053500.3 | X8: 22.240844 | Y8: 2096776.8 | Z8: 22.955887 | AA8: 355829.94 | AB8: 21.735316 | AC8: 401144.42 | AD8: 22.229169 | AE8: 394994.22 | AF8: 21.951166 | AG8: 70519.174 | AH8: 31.677973 | AI8: 66280.766 | AJ8: 32.622726 | AK8: 74212.541 | AL8: 32.826447
B9: Santander | C9: 1886565.6 | D9: 13.240083 | E9: 1991916.7 | F9: 12.908489 | G9: 2019417.3 | H9: 13.145071 | I9: 551674.18 | J9: 14.991204 | K9: 599303.74 | L9: 14.895575 | M9: 618043.38 | N9: 15.484083 | O9: 874142.25 | P9: 11.90711 | Q9: 929316.63 | R9: 11.825765 | S9: 926658.93 | T9: 11.78439 | U9: 1033043.4 | V9: 12.124088 | W9: 1104934 | X9: 11.967208 | Y9: 1066511.5 | Z9: 11.676358 | AA9: 168566.7 | AB9: 10.296634 | AC9: 164899.95 | AD9: 9.1378281 | AE9: 167381.66 | AF9: 9.3019657 | AG9: 22275.616 | AH9: 10.006447 | AI9: 21432.466 | AJ9: 10.548844 | AK9: 23805.167 | AL9: 10.529744
B10: Banorte | C10: 1779459.6 | D10: 12.488404 | E10: 1862912 | F10: 12.072482 | G10: 1868293.1 | H10: 12.161353 | I10: 419573.34 | J10: 11.401493 | K10: 443714.17 | L10: 11.028428 | M10: 442150.64 | N10: 11.077373 | O10: 1079814.2 | P10: 14.708666 | Q10: 1158655.5 | R10: 14.744154 | S10: 1164148.4 | T10: 14.80456 | U10: 1154816.9 | V10: 13.553256 | W10: 1193359.6 | X10: 12.924919 | Y10: 1180061.8 | Z10: 12.919528 | AA10: 156968.88 | AB10: 9.588199 | AC10: 170852.09 | AD10: 9.4676621 | AE10: 174062.43 | AF10: 9.6732385 | AG10: 34253.852 | AH10: 15.3872 | AI10: 31389.194 | AJ10: 15.449445 | AK10: 34506.709 | AL10: 15.263359
B11: Banamex | C11: 1520032.6 | D11: 10.667722 | E11: 1110881.5 | F11: 7.1989971 | G11: 1117474.4 | H11: 7.2740194 | I11: 526442.09 | J11: 14.305546 | K11: 402823.79 | L11: 10.012105 | M11: 406459.66 | N11: 10.183193 | O11: 620251.84 | P11: 8.4487475 | Q11: 492087.34 | R11: 6.2619231 | S11: 503424.35 | T11: 6.4020845 | U11: 965592.75 | V11: 11.332468 | W11: 773161.3 | X11: 8.3738775 | Y11: 764231.24 | Z11: 8.36694 | AA11: 232322.09 | AB11: 14.191032 | AC11: 179568.57 | AD11: 9.9506808 | AE11: 180328.72 | AF11: 10.021478 | AG11: 18107.129 | AH11: 8.1339175 | AI11: 9664.7347 | AJ11: 4.7568852 | AK11: 10157.826 | AL11: 4.493113
B12: HSBC | C12: 883735.82 | D12: 6.2021356 | E12: 890120.35 | F12: 5.7683682 | G12: 897782.35 | H12: 5.8439695 | I12: 174294.64 | J12: 4.7362857 | K12: 218382.91 | L12: 5.427864 | M12: 224058.65 | N12: 5.6134291 | O12: 503555.8 | P12: 6.8591748 | Q12: 490989.81 | R12: 6.2479568 | S12: 483659.84 | T12: 6.1507378 | U12: 579365.66 | V12: 6.799598 | W12: 560878.44 | X12: 6.0747057 | Y12: 541428.01 | Z12: 5.9276505 | AA12: 83399.378 | AB12: 5.0943207 | AC12: 87796.547 | AD12: 4.865191 | AE12: 88567.923 | AF12: 4.9220194 | AG12: 6806.6679 | AH12: 3.0576286 | AI12: 5896.0556 | AJ12: 2.9019792 | AK12: 6730.1865 | AL12: 2.9769646
B13: Scotiabank | C13: 877814.05 | D13: 6.160576 | E13: 871850.28 | F13: 5.6499702 | G13: 893048.68 | H13: 5.8131564 | I13: 180770.89 | J13: 4.9122712 | K13: 171111.93 | L13: 4.2529531 | M13: 177633.86 | N13: 4.4503306 | O13: 527608.54 | P13: 7.1868087 | Q13: 532170.63 | R13: 6.771992 | S13: 529339.29 | T13: 6.7316468 | U13: 594724.43 | V13: 6.9798529 | W13: 591248.14 | X13: 6.4036307 | Y13: 589538.92 | Z13: 6.4543774 | AA13: 86404.183 | AB13: 5.2778646 | AC13: 92317.678 | AD13: 5.1157267 | AE13: 93061.955 | AF13: 5.171768 | AG13: 7917.2742 | AH13: 3.5565249 | AI13: 6651.1116 | AJ13: 3.2736102 | AK13: 7479.6545 | AL13: 3.308477
B14: Inbursa | C14: 638270.81 | D14: 4.4794406 | E14: 704687.72 | F14: 4.5666839 | G14: 706596.95 | H14: 4.5994789 | I14: 61005.344 | J14: 1.6577603 | K14: 73588.344 | L14: 1.8290237 | M14: 72118.81 | N14: 1.8068208 | O14: 444506.49 | P14: 6.0548359 | Q14: 466601.03 | R14: 5.937604 | S14: 467303.13 | T14: 5.9427283 | U14: 421058.22 | V14: 4.9416575 | W14: 466616.41 | X14: 5.053782 | Y14: 466402.17 | Z14: 5.1062542 | AA14: 175402.39 | AB14: 10.714181 | AC14: 201509.51 | AD14: 11.166524 | AE14: 202541.75 | AF14: 11.255931 | AG14: 18698.47 | AH14: 8.3995541 | AI14: 15208.85 | AJ14: 7.4856431 | AK14: 16938.198 | AL14: 7.4922762
B15: Citi México | C15: 2219.0303 | D15: 0.015573349 | E15: 583611.65 | F15: 3.7820581 | G15: 556350.64 | H15: 3.6214748 | I15: 206.25123 | J15: 0.0056046745 | K15: 251623.63 | L15: 6.2540553 | M15: 223945.36 | N15: 5.6105908 | O15: 0 | P15: 0 | Q15: 162838.46 | R15: 2.0721564 | S15: 157921.08 | T15: 2.008294 | U15: 109.53043 | V15: 0.0012854799 | W15: 334183.09 | X15: 3.6194365 | Y15: 338381.49 | Z15: 3.7046609 | AA15: 1459.1467 | AB15: 0.089129696 | AC15: 76590.889 | AD15: 4.2442365 | AE15: 77440.191 | AF15: 4.3036137 | AG15: -15.961482 | AH15: -0.00717007 | AI15: 7578.955 | AJ15: 3.7302854 | AK15: 8270.3131 | AL15: 3.6582091
B16: Banco del Bajío | C16: 347044.17 | D16: 2.4355864 | E16: 382977.7 | F16: 2.4818626 | G16: 383294.55 | H16: 2.494994 | I16: 23912.925 | J16: 0.64981024 | K16: 29641.297 | L16: 0.73672855 | M16: 31836.004 | N16: 0.79759987 | O16: 254571.14 | P16: 3.4676355 | Q16: 266968.83 | R16: 3.397239 | S16: 268199.21 | T16: 3.4107091 | U16: 287440.56 | V16: 3.3734832 | W16: 316482.61 | X16: 3.427728 | Y16: 318804.45 | Z16: 3.490328 | AA16: 43057.343 | AB16: 2.6300905 | AC16: 46337.389 | AD16: 2.5677576 | AE16: 47108.401 | AF16: 2.6179734 | AG16: 8150.551 | AH16: 3.6613154 | AI16: 6181.8116 | AJ16: 3.0426255 | AK16: 6924.0481 | AL16: 3.0627155
B17: Banco Azteca | C17: 311661.36 | D17: 2.1872667 | E17: 360844.95 | F17: 2.3384327 | G17: 353123.75 | H17: 2.2986021 | I17: 75412.965 | J17: 2.0492732 | K17: 106765.34 | L17: 2.6536313 | M17: 104454.19 | N17: 2.6169317 | O17: 183525.6 | P17: 2.4998902 | Q17: 204657.34 | R17: 2.6043111 | S17: 203994.87 | T17: 2.5942178 | U17: 222874.58 | V17: 2.6157187 | W17: 247637.47 | X17: 2.682087 | Y17: 240763.79 | Z17: 2.6359249 | AA17: 37306.978 | AB17: 2.2788385 | AC17: 44985.17 | AD17: 2.4928252 | AE17: 47426.02 | AF17: 2.6356245 | AG17: 3833.7532 | AH17: 1.7221633 | AI17: 3858.3457 | AJ17: 1.8990389 | AK17: 4259.1952 | AL17: 1.8839706
B18: Afirme | C18: 295135.44 | D18: 2.0712864 | E18: 314172.38 | F18: 2.0359741 | G18: 317026.41 | H18: 2.0636323 | I18: 162775.96 | J18: 4.4232767 | K18: 179170.06 | L18: 4.4532362 | M18: 178452.96 | N18: 4.4708518 | O18: 64414.765 | P18: 0.87742438 | Q18: 68901.897 | R18: 0.87679228 | S18: 69893.806 | T18: 0.88884468 | U18: 91651.153 | V18: 1.0756437 | W18: 87043.479 | X18: 0.94274175 | Y18: 89448.351 | Z18: 0.97929651 | AA18: 8720.0585 | AB18: 0.53265115 | AC18: 9236.0385 | AD18: 0.51180933 | AE18: 9276.1041 | AF18: 0.51550452 | AG18: 403.28073 | AH18: 0.18115805 | AI18: 650.37462 | AJ18: 0.32010785 | AK18: 743.91518 | AL18: 0.32905614
... B58: CIBanco | C58: 148514.04 | D58: 1.0422846 | E58: 68658.224 | F58: 0.44493525 | G58: 0 | H58: 0 | I58: 60853.073 | J58: 1.6536224 | K58: 46196.814 | L58: 1.1482126 | M58: 0 | N58: 0 | O58: 13484.912 | P58: 0.18368445 | Q58: 6940.8554 | R58: 0.08832396 | S58: 0 | T58: 0 | U58: 55509.599 | V58: 0.65147624 | W58: 11931.171 | X58: 0.12922293 | Y58: 0 | Z58: 0 | AA58: 5319.636 | AB58: 0.32494166 | AC58: 5176.285 | AD58: 0.28684061 | AE58: 0 | AF58: 0 | AG58: 270.63046 | AH58: 0.12157012 | AI58: -533.02978 | AJ58: -0.2623519 | AK58: 0 | AL58: 0
B59: Intercam Banco | C59: 80292.703 | D59: 0.56350124 | E59: 32202.599 | F59: 0.20868689 | G59: n.d. | H59: 0 | I59: 33834.627 | J59: 0.91942275 | K59: 10838.548 | L59: 0.26938996 | M59: n.d. | N59: 0 | O59: 21764.329 | P59: 0.29646235 | Q59: 13701.469 | R59: 0.1743543 | S59: n.d. | T59: 0 | U59: 38295.385 | V59: 0.44944539 | W59: 18720.004 | X59: 0.20275073 | Y59: n.d. | Z59: 0 | AA59: 10091.506 | AB59: 0.61642388 | AC59: 11335.532 | AD59: 0.62815143 | AE59: n.d. | AF59: 0 | AG59: 1966.4093 | AH59: 0.88333227 | AI59: 952.45441 | AJ59: 0.46878848 | AK59: n.d. | AL59: 0
B61: n.d. No disponible

Sheet Indicadores
B2: Indicadores financieros
B3: Porcentajes | O3: 1.5853443
C5: ROA (Flujo 12 meses) 3/ | F5: ROE (Flujo 12 meses) 4/
C6: 45536 | D6: 45870 | E6: 45901 | F6: =+C6 -> 45536 | G6: =+D6 -> 45870 | H6: =+E6 -> 45901
B7: Sistema */ | C7: 2.0903083 | D7: 1.9621093 | E7: 1.9256743 | F7: 18.589893 | G7: 17.390141 | H7: 17.036981
B8: BBVA México | C8: 3.0018527 | D8: 2.9566591 | E8: 2.9105992 | F8: 26.386441 | G8: 25.893534 | H8: 25.436267
B9: Santander | C9: 1.5453166 | D9: 1.5219715 | E9: 1.5143325 | F9: 17.608706 | G9: 18.861805 | H9: 18.88389
B10: Banorte | C10: 2.5373499 | D10: 2.4700136 | E10: 2.425762 | F10: 29.33587 | G10: 28.748222 | H10: 28.095885
B11: Banamex | C11: 1.6243797 | D11: 1.3444569 | E11: 1.2589613 | F11: 11.173534 | G11: 8.5236798 | H11: 7.9401549
B12: HSBC | C12: 0.98113871 | D12: 0.74108866 | E12: 0.7391947 | F12: 10.33091 | G12: 8.0945442 | H12: 8.0428776
B13: Scotiabank | C13: 1.2673771 | D13: 1.1707526 | E13: 1.1788842 | F13: 13.148883 | G13: 11.527083 | H13: 11.55274
B14: Inbursa | C14: 4.2169987 | D14: 3.5410859 | E14: 3.370025 | F14: 15.661865 | G14: 12.628435 | H14: 11.976934
B15: Citi México | C15: 2.0102569 | D15: 1.3806368 | E15: 1.3967315 | F15: 2.3397587 | G15: 11.192472 | H15: 11.205029
B16: Banco del Bajío | C16: 3.2030177 | D16: 2.604197 | E16: 2.566643 | F16: 26.3858 | G16: 21.045841 | H16: 20.758826
B17: Banco Azteca | C17: 1.4243603 | D17: 1.7760803 | E17: 1.7599291 | F17: 11.914921 | G17: 14.381277 | H17: 14.109705
B18: Afirme | C18: 0.15944578 | D18: 0.26444664 | E18: 0.27892826 | F18: 5.4810049 | G18: 9.012611 | H18: 9.5137922
... B43: ICBC | C43: 3.3525343 | D43: 2.2783634 | E43: 2.3146084 | F43: 27.067063 | G43: 20.428629 | H43: 20.938262
B44: Openbank | C44: n.a. | D44: -24.527727 | E44: -22.851442 | F44: n.a. | G44: -35.666321 | H44: -36.766528
B45: Banco Covalto | C45: 0.046420338 | D45: 1.5704968 | E45: 1.5036116 | F45: 0.34590188 | G45: 12.76194 | H45: 12.143935
B46: Volkswagen Bank | C46: 6.08663 | D46: 6.0615049 | E46: 6.2143517 | F46: 9.0370614 | G46: 12.705889 | H46: 13.379389
B47: Banco S3 | C47: 5.6160398 | D47: 5.4365239 | E47: 5.331649 | F47: 12.9828 | G47: 13.00302 | H47: 13.038216
B48: Bank of China | C48: 1.9859903 | D48: 1.9968873 | E48: 1.995916 | F48: 10.4272 | G48: 8.741238 | H48: 8.2352083
B49: Shinhan | C49: 2.3819426 | D49: 1.817915 | E49: 1.7668573 | F49: 7.3517564 | G49: 6.4123743 | H49: 6.2762287
B50: Banco Ualá | C50: -26.207697 | D50: -18.580999 | E50: -18.169057 | F50: -154.13849 | G50: -149.41837 | H50: -142.56008
B51: KEB Hana México | C51: 0.92507228 | D51: 0.76336247 | E51: 0.76038282 | F51: 2.6902856 | G51: 2.5198903 | H51: 2.5057716
B52: Banco Bineo | C52: -27.077141 | D52: -30.148729 | E52: -30.456123 | F52: -29.565611 | G52: -32.213142 | H52: -32.401331
B53: Dondé Banco | C53: -11.140061 | D53: -4.64868 | E53: -4.3926222 | F53: -22.828445 | G53: -21.648423 | H53: -21.362706
B54: Credit Suisse | C54: -10.696884 | D54: -5.3130418 | E54: -4.9125421 | F54: -15.447928 | G54: -5.6906418 | H54: -5.2132177
B55: Hey Banco | C55: n.a. | D55: 5.2069735 | E55: 4.852482 | F55: n.a. | G55: 5.2308925 | H55: 4.874223
B56: Forjadores | C56: 1.4067658 | D56: -2.8065719 | E56: -2.9400751 | F56: 2.0096612 | G56: -4.0533763 | H56: -4.263933
B57: Pagatodo | C57: -13.028624 | D57: -19.390734 | E57: -18.020991 | F57: -17.500247 | G57: -26.405367 | H57: -26.893868
B58: CIBanco | C58: 0.44782896 | D58: -0.11224776 | E58: 0.28000228 | F58: 10.050151 | G58: -2.7877843 | H58: 6.8809651
B59: Intercam Banco | C59: 3.9026326 | D59: 2.6412978 | E59: n.d. | F59: 28.497161 | G59: 18.488138 | H59: n.d.
B62: n.d. No disponible

Sheet CCT
B2: Cartera de crédito total
B3: Millones de pesos y porcentajes
C5: Cartera total (MDP) 1/ | F5: IMOR (%) 5/ | I5: ICOR (%) 6/ | L5: Pérdida esperada (%) 7/
C6: 45536 | D6: 45870 | E6: 45901 | F6: =C6 -> 45536 | G6: =D6 -> 45870 | H6: =E6 -> 45901 | I6: =C6 -> 45536 | J6: =D6 -> 45870 | K6: =E6 -> 45901 | L6: =C6 -> 45536 | M6: =D6 -> 45870 | N6: =E6 -> 45901
B7: Sistema */ | C7: 7341346.6 | D7: 7858406 | E7: 7863444.3 | F7: 2.0590376 | G7: 2.1597894 | H7: 2.235963 | I7: 155.97289 | J7: 150.15523 | K7: 147.33948 | L7: 3.2115406 | M7: 3.2430367 | N7: 3.2944562
B8: BBVA México | C8: 1839030.8 | D8: 2012068.9 | E8: 2016789.4 | F8: 1.6785616 | G8: 1.6507735 | H8: 1.7240306 | I8: 191.71125 | J8: 189.94649 | K8: 182.54423 | L8: 3.2179913 | M8: 3.1355863 | N8: 3.1471184
B9: Santander | C9: 874142.25 | D9: 929316.63 | E9: 926658.93 | F9: 2.3390753 | G9: 2.2979288 | H9: 2.406478 | I9: 135.64018 | J9: 135.87507 | K9: 134.08072 | L9: 3.1727261 | M9: 3.1223123 | N9: 3.226623
B10: Banorte | C10: 1079814.2 | D10: 1158655.5 | E10: 1164148.4 | F10: 0.93695034 | G10: 1.0782108 | H10: 1.3713432 | I10: 173.73259 | J10: 156.92802 | K10: 134.94421 | L10: 1.6277881 | M10: 1.6920148 | N10: 1.8505484
B11: Banamex | C11: 620251.84 | D11: 492087.34 | E11: 503424.35 | F11: 2.1226197 | G11: 2.8062853 | H11: 2.7992908 | I11: 205.79469 | J11: 190.14216 | K11: 190.55203 | L11: 4.3682386 | M11: 5.3359315 | N11: 5.3341055
B12: HSBC | C12: 503555.8 | D12: 490989.81 | E12: 483659.84 | F12: 2.2124578 | G12: 2.9594283 | H12: 2.9904825 | I12: 154.26755 | J12: 129.70583 | K12: 129.23467 | L12: 3.4131044 | M12: 3.8385512 | N12: 3.8647402
B13: Scotiabank | C13: 527608.54 | D13: 532170.63 | E13: 529339.29 | F13: 3.8660942 | G13: 4.042423 | H13: 4.1159353 | I13: 72.368682 | J13: 69.024933 | K13: 69.459426 | L13: 2.7978414 | M13: 2.7902798 | N13: 2.858905
B14: Inbursa | C14: 444506.49 | D14: 466601.03 | E14: 467303.13 | F14: 1.5876496 | G14: 1.5063476 | H14: 1.4700399 | I14: 140.31655 | J14: 149.20137 | K14: 154.16425 | L14: 2.2277352 | M14: 2.2474914 | N14: 2.266276
B15: Citi México | C15: 0 | D15: 162838.46 | E15: 157921.08 | F15: - | G15: 1.3908188 | H15: 1.4345793 | I15: - | J15: 188.59079 | K15: 184.3 | L15: - | M15: 2.6229561 | N15: 2.6439296
B16: Banco del Bajío | C16: 254571.14 | D16: 266968.83 | E16: 268199.21 | F16: 1.4891518 | G16: 1.845093 | H16: 1.9736294 | I16: 141.09045 | J16: 119.95995 | K16: 115.74629 | L16: 2.101051 | M16: 2.2133728 | N16: 2.2844029
B17: Banco Azteca | C17: 183525.6 | D17: 204657.34 | E17: 203994.87 | F17: 3.4627228 | G17: 4.6627621 | H17: 4.8727849 | I17: 344.94667 | J17: 255.08493 | K17: 254.11316 | L17: 11.944547 | M17: 11.894004 | N17: 12.382388
B18: Afirme | C18: 64414.765 | D18: 68901.897 | E18: 69893.806 | F18: 5.5170309 | G18: 3.9420726 | H18: 3.9085741 | I18: 69.017311 | J18: 84.882725 | K18: 86.241004 | L18: 3.8077063 | M18: 3.3461386 | N18: 3.3707935
B19: Monex | C19: 45979.93 | D19: 55196.869 | E19: 54595.986 | F19: 1.4262459 | G19: 1.4745026 | H19: 1.4693963 | I19: 129.42789 | J19: 128.6824 | K19: 129.99268 | L19: 1.8459599 | M19: 1.8974253 | N19: 1.9101075
B20: Banregio | C20: 171638.25 | D20: 186462.78 | E20: 188494.8 | F20: 1.2336374 | G20: 1.5762546 | H20: 1.6140056 | I20: 168.53411 | J20: 134.43745 | K20: 130.42363 | L20: 2.0790998 | M20: 2.1190765 | N20: 2.1050447
B21: J.P. Morgan | C21: 23030.498 | D21: 24842.326 | E21: 23631.979 | F21: 0 | G21: 0 | H21: 0 | I21: - | J21: - | K21: - | L21: 0.72483536 | M21: 0.64205721 | N21: 0.61792183
B22: Invex | C22: 41546.324 | D22: 49339.463 | E22: 49754.432 | F22: 2.186528 | G22: 2.35529 | H22: 2.2510827 | I22: 238.43119 | J22: 241.82046 | K22: 255.65101 | L22: 5.2133648 | M22: 5.6955732 | N22: 5.7549158
B23: Multiva | C23: 70690.182 | D23: 81408.031 | E23: 86876.488 | F23: 3.4114477 | G23: 2.568871 | H23: 2.6903645 | I23: 94.875868 | J23: 114.35006 | K23: 109.92655 | L23: 3.2366406 | M23: 2.9375055 | N23: 2.957425
B24: BanCoppel | C24: 61055.263 | D24: 79132.111 | E24: 78285.569 | F24: 8.4392693 | G24: 5.4084956 | H24: 5.4978305 | I24: 134.19706 | J24: 150.1693 | K24: 150.34336 | L24: 11.325251 | M24: 8.1218998 | N24: 8.2656231
B25: Banca Mifel | C25: 77836.741 | D25: 84449.258 | E25: 83911.035 | F25: 2.4529447 | G25: 2.8478877 | H25: 3.1923916 | I25: 88.655054 | J25: 79.624047 | K25: 71.33299 | L25: 2.1746594 | M25: 2.2676034 | N25: 2.2772283
B26: Barclays | C26: 0 | D26: 0 | E26: 0 | F26: - | G26: - | H26: - | I26: - | J26: - | K26: - | L26: - | M26: - | N26: -
B27: Banco Base | C27: 11442.382 | D27: 10437.397 | E27: 10461.586 | F27: 2.4630544 | G27: 3.3503311 | H27: 3.2162987 | I27: 119.02222 | J27: 101.09046 | K27: 103.56998 | L27: 2.9315821 | M27: 3.386865 | N27: 3.33112
B28: Sabadell | C28: 94054.735 | D28: 100285.57 | E28: 101304.32 | F28: 2.1751498 | G28: 2.0369979 | H28: 1.8835613 | I28: 71.725947 | J28: 68.998084 | K28: 69.585855 | L28: 1.5601468 | M28: 1.4054895 | N28: 1.3106922
B29: Bank of America | C29: 33087.576 | D29: 43913.817 | E29: 45436.847 | F29: 0 | G29: 0 | H29: 0 | I29: - | J29: - | K29: - | L29: 0.8713084 | M29: 0.98873116 | N29: 1.1721605
B30: Ve por Más | C30: 56671.8 | D30: 59826.379 | E30: 62000.729 | F30: 3.0933377 | G30: 2.8954991 | H30: 2.7592538 | I30: 96.811116 | J30: 111.15768 | K30: 115.20369 | L30: 2.9946947 | M30: 3.2185697 | N30: 3.1787623
B31: Actinver | C31: 27303.77 | D31: 29803.299 | E31: 29502.671 | F31: 3.3415707 | G31: 3.1306968 | H31: 2.9741051 | I31: 115.99847 | J31: 111.1205 | K31: 113.46367 | L31: 3.8761707 | M31: 3.4788458 | N31: 3.374529
B32: Bansí | C32: 22101.042 | D32: 30139.47 | E32: 29578.353 | F32: 4.4923449 | G32: 3.5418365 | H32: 3.6772336 | I32: 158.18191 | J32: 173.29319 | K32: 171.68334 | L32: 7.1060768 | M32: 6.1377615 | N32: 6.3131976
B33: Compartamos | C33: 48565.199 | D33: 59110.491 | E33: 58108.319 | F33: 3.3606933 | G33: 3.2626805 | H33: 3.5065949 | I33: 234.72744 | J33: 236.87828 | K33: 236.61154 | L33: 7.8884695 | M33: 7.7285813 | N33: 8.2970081
B34: BIAfirme | C34: 272.76063 | D34: 244.07477 | E34: 241.49468 | F34: 0 | G34: 0 | H34: 0 | I34: - | J34: - | K34: - | L34: 0.44300675 | M34: 0.56619249 | N34: 0.58409361
B35: Bancrea | C35: 36194.128 | D35: 43738.995 | E35: 44154.664 | F35: 0.92127341 | G35: 2.1351984 | H35: 2.1386388 | I35: 139.17427 | J35: 72.374258 | K35: 87.411205 | L35: 1.2821756 | M35: 1.545334 | N35: 1.86941
B36: Kapital Bank | C36: 4640.7704 | D36: 10101.269 | E36: 22058.982 | F36: 3.3784599 | G36: 2.7156992 | H36: 1.4502096 | I36: 130.17619 | J36: 153.72453 | K36: 178.95398 | L36: 4.3979504 | M36: 4.1746959 | N36: 2.5952079
B37: MUFG Bank | C37: 13684.455 | D37: 7477.1335 | E37: 5841.3814 | F37: 0 | G37: 0 | H37: 0 | I37: - | J37: - | K37: - | L37: 0.53910977 | M37: 0.77410859 | N37: 0.85501766
B38: Consubanco | C38: 23743.328 | D38: 31460.825 | E38: 31736.663 | F38: 1.6870264 | G38: 1.5104281 | H38: 1.4718667 | I38: 215.28379 | J38: 232.96449 | K38: 237.15309 | L38: 3.6318944 | M38: 3.5187612 | N38: 3.4905772
B39: Bankaool | C39: 7855.3757 | D39: 12973.417 | E39: 13865.611 | F39: 1.8752992 | G39: 0.84564655 | H39: 0.78218156 | I39: 156.38954 | J39: 216.91464 | K39: 202.21036 | L39: 2.9327718 | M39: 1.8343311 | N39: 1.5816521
B40: BNP Paribas México | C40: 0 | D40: 0 | E40: 0 | F40: - | G40: - | H40: - | I40: - | J40: - | K40: - | L40: - | M40: - | N40: -
B41: Inmobiliario Mexicano | C41: 11686.081 | D41: 12581.466 | E41: 12639.05 | F41: 3.5654478 | G41: 2.825377 | H41: 2.7589361 | I41: 61.604084 | J41: 64.458994 | K41: 64.1077 | L41: 2.1964614 | M41: 1.8212096 | N41: 1.7686905
B42: Mizuho Bank | C42: 4730.6043 | D42: 6064.05 | E42: 6089.6534 | F42: 0 | G42: 0 | H42: 0 | I42: - | J42: - | K42: - | L42: 0.46249331 | M42: 0.46360062 | N42: 0.46501875
...

Sheet CCE
B2: Cartera de crédito a empresas
B3: Millones de pesos y porcentajes
C5: Cartera total (MDP) 1/ | F5: IMOR (%) 5/ | I5: ICOR (%) 6/ | L5: Pérdida esperada (%) 7/
C6: 45536 | D6: 45870 | E6: 45901 | F6: =C6 -> 45536 | G6: =D6 -> 45870 | H6: =E6 -> 45901 | I6: =C6 -> 45536 | J6: =D6 -> 45870 | K6: =E6 -> 45901 | L6: =C6 -> 45536 | M6: =D6 -> 45870 | N6: =E6 -> 45901
B7: Sistema */ | C7: 3469495.1 | D7: 3737376.9 | E7: 3724672.5 | F7: 1.7257781 | G7: 1.758917 | H7: 1.8690689 | I7: 95.843779 | J7: 96.012094 | K7: 93.681861 | L7: 1.6540509 | M7: 1.688773 | N7: 1.7509785
B8: BBVA México | C8: 766552.02 | D8: 842552.82 | E8: 839268.06 | F8: 1.234799 | G8: 1.0776563 | H8: 1.1965507 | I8: 96.330757 | J8: 108.17431 | K8: 102.15988 | L8: 1.1894912 | M8: 1.1657472 | N8: 1.2223948
B9: Santander | C9: 372849.84 | D9: 380939.14 | E9: 377258.9 | F9: 1.5604648 | G9: 1.6108388 | H9: 1.7976544 | I9: 91.885848 | J9: 97.016733 | K9: 90.423326 | L9: 1.4338463 | M9: 1.5627832 | N9: 1.6254989
B10: Banorte | C10: 422335.38 | D10: 460160.81 | E10: 457808.28 | F10: 0.87344447 | G10: 1.1429573 | H10: 1.8753544 | I10: 84.177485 | J10: 70.824159 | K10: 62.924932 | L10: 0.73524359 | M10: 0.8094899 | N10: 1.1800655
B11: Banamex | C11: 252774.75 | D11: 132285.57 | E11: 138105.89 | F11: 1.0932264 | G11: 2.754815 | H11: 2.7103877 | I11: 164.1774 | J11: 98.840577 | K11: 98.461742 | L11: 1.7948307 | M11: 2.722875 | N11: 2.668695
B12: HSBC | C12: 212841.1 | D12: 220723.03 | E12: 219529.06 | F12: 2.0628019 | G12: 2.8889034 | H12: 2.8732029 | I12: 91.65809 | J12: 85.842568 | K12: 86.907278 | L12: 1.8907248 | M12: 2.4799089 | N12: 2.4970224
B13: Scotiabank | C13: 192926.81 | D13: 194943.21 | E13: 190991.52 | F13: 4.0624433 | G13: 2.7577768 | H13: 2.8979997 | I13: 78.975587 | J13: 80.099535 | K13: 80.945595 | L13: 3.2083384 | M13: 2.2089664 | N13: 2.3458031
B14: Inbursa | C14: 310558.81 | D14: 326660.46 | E14: 329200.03 | F14: 1.6517417 | G14: 1.5115313 | H14: 1.4172109 | I14: 113.49098 | J14: 119.96108 | K14: 127.35284 | L14: 1.8745779 | M14: 1.8132494 | N14: 1.8048582
B15: Citi México | C15: 0 | D15: 133585.88 | E15: 130764.29 | F15: - | G15: 0.0067496803 | H15: 0.0073875108 | I15: - | J15: 17006.207 | K15: 15957.841 | L15: - | M15: 1.1478646 | N15: 1.1788872
B16: Banco del Bajío | C16: 215258.26 | D16: 231432.33 | E16: 231747.9 | F16: 1.5820078 | G16: 1.9486717 | H16: 2.0765553 | I16: 104.1926 | J16: 94.534993 | K16: 91.532564 | L16: 1.648335 | M16: 1.8421767 | N16: 1.9007243
B17: Banco Azteca | C17: 42600.465 | D17: 45638.894 | E17: 43479.286 | F17: 0.99514157 | G17: 4.1774129 | H17: 3.7861506 | I17: 81.847243 | J17: 49.173183 | K17: 46.450138 | L17: 0.81449594 | M17: 2.0541669 | N17: 1.7586722
B18: Afirme | C18: 36944.826 | D18: 39898.806 | E18: 40246.774 | F18: 6.6808087 | G18: 4.4209898 | H18: 4.2830678 | I18: 45.103807 | J18: 51.792746 | K18: 54.94461 | L18: 3.0132991 | M18: 2.289752 | N18: 2.3533149
B19: Monex | C19: 34072.287 | D19: 41955.725 | E19: 42329.099 | F19: 1.7755753 | G19: 1.8500347 | H19: 1.8076002 | I19: 108.91589 | J19: 114.38409 | K19: 118.58764 | L19: 1.9338837 | M19: 2.1161453 | N19: 2.1435903
B20: Banregio | C20: 138704.14 | D20: 149692.77 | E20: 151663.63 | F20: 1.2018854 | G20: 1.6140326 | H20: 1.6581853 | I20: 134.99208 | J20: 105.58514 | K20: 103.18945 | L20: 1.6224501 | M20: 1.7041785 | N20: 1.7110723
B21: J.P. Morgan | C21: 22505.88 | D21: 23991.417 | E21: 22689.95 | F21: 0 | G21: 0 | H21: 0 | I21: - | J21: - | K21: - | L21: 0.55979871 | M21: 0.62284812 | N21: 0.59459943
B22: Invex | C22: 14082.513 | D22: 14454.032 | E22: 14284.716 | F22: 2.4419374 | G22: 1.8825516 | H22: 1.8799254 | I22: 83.954736 | J22: 119.8119 | K22: 113.3549 | L22: 2.0501221 | M22: 2.2555209 | N22: 2.1309876
B23: Multiva | C23: 32814.668 | D23: 44501.538 | E23: 46069.086 | F23: 5.7618841 | G23: 3.666852 | H23: 4.065764 | I23: 81.606787 | J23: 101.04747 | K23: 96.061725 | L23: 4.7020884 | M23: 3.7052613 | N23: 3.905643
B24: BanCoppel | C24: 31669.944 | D24: 42102.249 | E24: 41391.458 | F24: 4.2233946 | G24: 3.8361586 | H24: 3.7796711 | I24: 80.152697 | J24: 85.584636 | K24: 88.453299 | L24: 3.3851647 | M24: 3.2831624 | N24: 3.3432438
